Workbook
Name 범위: '[2]1-1. 개인별 급여분석'!$B$5:$R$43
Name 성명: '[2]1-1. 개인별 급여분석'!$B$5:$B$39
Name 포함단어시작셀: #REF!

Sheet 인사기본정보
B1: 1 | C1: 2 | L1: 11 | M1: 12 | N1: 13 | O1: 14 | P1: 15 | Q1: 16 | R1: 17 | S1: 18 | T1: 19 | U1: 20 | V1: 21 | W1: 22 | X1: 23 | Y1: 24 | Z1: 25 | AA1: 26 | AB1: 27 | AC1: 28 | AD1: 29 | AE1: 30 | AF1: 31 | AG1: 32 | AH1: 33 | AI1: 34 | AJ1: 35 | AK1: 36 | AL1: 37 | AM1: 38 | AN1: 39 | AO1: 40 | AP1: 41 | AQ1: 42 | AR1: 43 | AS1: 44 | AT1: 45 | AU1: 46 | AV1: 47 | AW1: 48 | AX1: 49 | AY1: 50 | AZ1: 51 | BA1: 52 | BB1: 53 | BC1: 54 | BD1: 55 | BE1: 56 | BF1: 57 | BG1: 58 | BH1: 59 | BI1: 60 | BJ1: 61 | BK1: 62 | BL1: 63 | BM1: 64 | BN1: 65 | BO1: 66 | BP1: 67 | BQ1: 68 | BR1: 69 | BS1: 70 | BT1: 71 | BU1: 72 | BV1: 73 | BW1: 63 | BX1: 64 | BY1: 65 | BZ1: 66 | CA1: 67 | CB1: 68 | CC1: 69 | CD1: 70 | CE1: 71 | CF1: 72 | CG1: 73 | CH1: 74 | CI1: 75 | CJ1: 76 | CK1: 77 | CL1: 78 | CM1: 79 | CN1: 80 | CO1: 81 | CP1: 82 | CQ1: 83 | CR1: 84 | CS1: 85 | CT1: 86 | CU1: 87 | CV1: 88 | CW1: 89 | CX1: 90 | CY1: 91 | CZ1: 92 | DA1: 93 | DB1: 94 | DC1: 95 | DD1: 96 | DE1: 97 | DF1: 98 | DG1: 99 | DH1: 100 | DI1: 101 | DJ1: 102 | DK1: 103 | DL1: 104
A2: 순번 | B2: 사번 | C2: 성명 | D2: 직책 | E2: 직급 | F2: 고용형태 | G2: 직무 | H2: 실 | I2: 팀 | J2: 팀 위치 | K2: 팀 권역 | L2: 최초입사일 | M2: 정규전환일 | N2: 적치적용일 | O2: 퇴직일자 | P2: 영문명 | Q2: 주민번호 | R2: 생년월일 | S2: 생일월 | T2: 성별 | U2: 나이 | V2: 양력/음력 | W2: 국적 | X2: 전화번호 | Y2: 재직구분 | Z2: 결혼유무 | AA2: 결혼기념일 | AB2: 법인 | AC2: 한자명 | AD2: 총업무경력 | AE2: 전SW경력 | AF2: 재직기간 | AG2: 최종학교 | AH2: 전공 | AI2: 최종학력 | AJ2: 졸업일 | AK2: 지우면안돼 | AL2: 등급(경력+학력) | AM2: 등급(자격증) | AN2: CSTS | AO2: 취득일 | AP2: ISTQB | AQ2: 취득일2 | AR2: 정보처리기사 | AS2: 취득일3 | AT2: 정보처리산업기사 | AU2: 취득일4 | AV2: 기타 | AW2: 발행기관 | AX2: 취득년월 | AY2: 분야 | AZ2: 직무2 | BA2: 은행 | BB2: 계좌번호 | BC2: 본인과의 관계 | BD2: 비상연락처 | BE2: 그룹웨어 이메일 | BF2: 주요시도 | BG2: 자치시구 | BH2: 상세주소 | BI2: 상세주소3 | BJ2: 거주지역 | BK2: 상세주소4 | BL2: 기준일 | BM2: 실근무일 | BN2: 2026연봉 | BO2: 실수령연봉 | BP2: 월 급여액 | BQ2: 기본급 | BR2: 연장근로수당 | BS2: 식대 | BT2: 법정근로시간 | BU2: 연장시간 | BV2: 25최저임금 | BW2: 기준일 | BX2: 실근무일 | BY2: 2025연봉 | BZ2: 실수령연봉 | CA2: 월 급여액 | CB2: 기본급 | CC2: 연장근로수당 | CD2: 식대 | CE2: 법정근로시간 | CF2: 연장시간 | CG2: 25최저임금 | CH2: 기준일 | CI2: 실근무일 | CJ2: 2024연봉 | CK2: 실수령연봉 | CL2: 월 급여액 | CM2: 기본급 | CN2: 연장근로수당 | CO2: 식대 | CP2: 법정근로시간 | CQ2: 연장시간 | CR2: 최저임금 | CS2: 2023연봉 | CT2: 월 급여액2 | CU2: 기본급3 | CV2: 연장근로수당4 | CW2: 식대2 | CX2: 법정근로시간2 | CY2: 연장근로시간 | CZ2: 총 근로시간 | DA2: 최저시급(9,620) | DB2: 통상임금 | DC2: 기준연도 | DD2: 비고 | DE2: 퇴직사유 | DF2: 내채공가입일 | DG2: 내채공만기일 | DH2: 인재추천자 | DI2: 지원시기 1차 | DJ2: 지원금 1차 | DK2: 지원시기 2차 | DL2: 지원금 2차
A3: =ROW()-2 -> 1 | B3: 150501 | C3: 김종균 | D3: 대표이사 | E3: 임원 | F3: 정규직 | G3: 대표 | H3: 경영전략실 | I3: 임원 | J3: =+VLOOKUP($I3,[1]프로젝트현황!$I:$N,5,0) -> 서울시 | K3: =+VLOOKUP($I3,[1]프로젝트현황!$I:$N,6,0) -> 강남구 | L3: 42142 | M3: 42142 | Q3: 831124-1113419 | R3: =LEFT(Q3,6) -> 831124 | S3: =MID($Q3,3,2) -> 11 | T3: =IF(OR(MID($Q3,8,1)="1",MID($Q3,8,1)="3"),"남자",IF(OR(MID($Q3,8,1)="2",MID($Q3,8,1)="4"),"여자","")) -> 남자 | U3: =YEAR(TODAY())-IF(OR(MID($Q3,8,1)="1",MID($Q3,8,1)="2"),19&LEFT($Q3,2),IF(OR(MID($Q3,8,1)="3",MID($Q3,8,1)="4"),20&LEFT($Q3,2),""))+1 -> 44 | V3: 양력 | W3: 한국 | X3: 010-5749-8009 | AB3: TBELL | AD3: {=QUOTIENT(SUMPRODUCT(LEFT($AE3:$AF3,FIND("년",$AE3:$AF3)-1)*12+MID($AE3:$AF3,FIND("년",$AE3:$AF3)+1,FIND("개월",$AE3:$AF3)-FIND("년",$AE3:$AF3)-1)),12)&"년"&MOD(SUMPRODUCT(LEFT($AE3:$AF3,FIND("년",$AE3:$AF3)-1)*12+MID($AE3:$AF3,FIND("년",$AE3:$AF3)+1,FIND("개월",$AE3:$AF3)-FIND("년",$AE3:$AF3)-1)),12)&"개월"} -> 10년8개월 | AE3: 0년0개월 | AF3: =DATEDIF($L3,TODAY(),"y")&"년"&DATEDIF($L3,TODAY(),"ym")&"개월" -> 10년8개월 | AI3: 전문학사 | AK3: =VALUE(LEFT($AD3,FIND("년",$AD3)-1)) -> 10 | AL3: 특급 | AM3: =IF(ISNUMBER(SEARCH("산업기사",$AT3)),IF($AK3>=13,"특급",IF($AK3>=10,"고급",IF($AK3>=7,"중급","초급"))),IF(ISNUMBER(SEARCH("기사",$AR3)),IF($AK3>=10,"특급",IF($AK3>=7,"고급",IF($AK3>=4,"중급","초급"))),"미해당")) -> 미해당 | AY3: 정보기술컨설팅 | BC3: 처 | BD3: 010-5749-8009 | BE3: jg.kim@tbell.co.kr | BF3: 서울시 | BG3: 서대문구 | BI3: 세무서8길 30 홍제역 효성해링턴플레이스 113동 1802호 | BJ3: =IFERROR(VLOOKUP($BG3,[1]프로젝트현황!Y:Z,2,0),"기타") -> 서북권 | BK3: =(IF(BF3="","",BF3&" "))&(IF(BG3="","",BG3&" "))&(IF(BH3="","",BH3&" "))&BI3 -> 서울시 서대문구 세무서8길 30 홍제역 효성해링턴플레이스 113동 1802호 | BL3: 30 | BM3: 30 | BN3: 2758053.7 | BO3: =BP3*12 -> 2758080 | BP3: =SUM(BQ3:BS3) -> 229840 | BQ3: =ROUNDUP(BN3/12*209/(209+BU3*1.5)/BL3*BM3,-1)-BS3 -> 29840 | BR3: =ROUNDUP(BN3/12*(BU3*1.5)/(209+BU3*1.5)/BL3*BM3,1) -> 0 | BS3: 200000 | BT3: 209 | BU3: =IF($BN3="","", IFERROR( IF($BN3<'[1]시간외시간 기준표'!$B$2,0, IF($BN3>LOOKUP(9.9E+307,'[1]시간외시간 기준표'!$B$2:$B$999), LOOKUP(9.9E+307,'[1]시간외시간 기준표'!$C$2:$C$999), LOOKUP($BN3,'[1]시간외시간 기준표'!$B$2:$B$999,'[1]시간외시간 기준표'!$C$2:$C$999) ) ),0) ) -> 0 | BV3: =(BQ3+BS3)/209 -> 1099.7129 | BW3: 30 | BX3: 30 | BY3: 2758053.7 | BZ3: =CA3*12 -> 2758080 | CA3: =SUM(CB3:CD3) -> 229840 | CB3: =ROUNDUP(BY3/12*209/(209+CF3*1.5)/BW3*BX3,-1)-CD3 -> 29840 | CC3: =ROUNDUP(BY3/12*(CF3*1.5)/(209+CF3*1.5)/BW3*BX3,1) -> 0 | CD3: 200000 | CE3: 209 | CF3: =IF(BY3<26000000,0,IF(BY3<26500000,4,IF(BY3<27000000,7,IF(BY3<27500000,9,IF(BY3<28000000,11,IF(BY3<28500000,15,IF(BY3<29000000,17,IF(BY3<29500000,20,IF(BY3<30000000,23,IF(BY3<30500000,25,IF(BY3<31000000,27,IF(BY3<31500000,29,IF(BY3<32000000,33,IF(BY3<32500000,37,IF(BY3<33000000,39,IF(BY3<33500000,42,IF(BY3<34000000,45,IF(BY3<34500000,48,IF(BY3<35000000,52,52))))))))))))))))))) -> 0 | CG3: =(CB3+CD3)/209 -> 1099.7129 | CH3: 30 | CI3: 30 | CJ3: 2712913.4 | CK3: =CL3*12 -> 2712960 | CL3: =SUM(CM3:CO3) -> 226080 | CM3: =ROUNDUP(CJ3/12*209/(209+CQ3*1.5)/CH3*CI3,-1)-CO3 -> 26080 | CN3: =ROUNDUP(CJ3/12*(CQ3*1.5)/(209+CQ3*1.5)/CH3*CI3,1) -> 0 | CO3: 200000 | CP3: 209 | CQ3: =IF(CJ3<26000000,0,IF(CJ3<26500000,4,IF(CJ3<27000000,7,IF(CJ3<27500000,9,IF(CJ3<28000000,11,IF(CJ3<28500000,15,IF(CJ3<29000000,17,IF(CJ3<29500000,20,IF(CJ3<30000000,23,IF(CJ3<30500000,25,IF(CJ3<31000000,27,IF(CJ3<31500000,29,IF(CJ3<32000000,33,IF(CJ3<32500000,37,IF(CJ3<33000000,39,IF(CJ3<33500000,42,IF(CJ3<34000000,45,IF(CJ3<34500000,48,IF(CJ3<35000000,52,52))))))))))))))))))) -> 0 | CR3: =(CM3+CO3)/209 -> 1081.7225 | CS3: =AVERAGE(CU4:CU312) -> 1933891.7 | CT3: =AVERAGE(CV4:CV312) -> 537038.66 | CU3: =AVERAGE(CW4:CW312) -> 197872.34 | CV3: =AVERAGE(CX4:CX312) -> 207.89362 | CW3: 200000 | DG3: =B3 -> 150501
A4: =ROW()-2 -> 2 | B4: 151201 | C4: 강현규 | D4: 실장 | E4: 임원 | F4: 정규직 | G4: 지원관리 | H4: 1실 | I4: 1실장 | J4: =+VLOOKUP($I4,[1]프로젝트현황!$I:$N,5,0) -> 서울시 | K4: =+VLOOKUP($I4,[1]프로젝트현황!$I:$N,6,0) -> 강남구 | L4: 42345 | M4: 42345 | N4: 43220 | P4: KANG, HyeonKyu | Q4: 821030-1012027 | R4: =LEFT(Q4,6) -> 821030 | S4: =MID($Q4,3,2) -> 10 | T4: =IF(OR(MID($Q4,8,1)="1",MID($Q4,8,1)="3"),"남자",IF(OR(MID($Q4,8,1)="2",MID($Q4,8,1)="4"),"여자","")) -> 남자 | U4: =YEAR(TODAY())-IF(OR(MID($Q4,8,1)="1",MID($Q4,8,1)="2"),19&LEFT($Q4,2),IF(OR(MID($Q4,8,1)="3",MID($Q4,8,1)="4"),20&LEFT($Q4,2),""))+1 -> 45 | V4: 양력 | W4: 한국 | X4: 010-6388-7664 | Z4: 유 | AA4: 45267 | AB4: TBELL | AD4: =QUOTIENT(SUMPRODUCT(LEFT($AE4:$AF4,FIND("년",$AE4:$AF4)-1)*12+MID($AE4:$AF4,FIND("년",$AE4:$AF4)+1,FIND("개월",$AE4:$AF4)-FIND("년",$AE4:$AF4)-1)),12)&"년"&MOD(SUMPRODUCT(LEFT($AE4:$AF4,FIND("년",$AE4:$AF4)-1)*12+MID($AE4:$AF4,FIND("년",$AE4:$AF4)+1,FIND("개월",$AE4:$AF4)-FIND("년",$AE4:$AF4)-1)),12)&"개월" -> 21년0개월 | AE4: 10년 10개월 | AF4: =DATEDIF($L4,TODAY(),"y")&"년"&DATEDIF($L4,TODAY(),"ym")&"개월" -> 10년2개월 | AG4: 동국대학교전산원 | AH4: 멀티미디어 | AI4: 전문학사 | AJ4: 37672 | AK4: =VALUE(LEFT($AD4,FIND("년",$AD4)-1)) -> 21 | AL4: =IF($AI4="전문학사",IF($AK4<=8,"초급",IF($AK4<12,"중급",IF($AK4<15,"고급",IF($AK4>=15,"특급"))))) -> 특급 | AM4: =IF(ISNUMBER(SEARCH("산업기사",$AT4)),IF($AK4>=13,"특급",IF($AK4>=10,"고급",IF($AK4>=7,"중급","초급"))),IF(ISNUMBER(SEARCH("기사",$AR4)),IF($AK4>=10,"특급",IF($AK4>=7,"고급",IF($AK4>=4,"중급","초급"))),"미해당")) -> 미해당 | AP4: ISTQB | AQ4: 2017.03 | AV4: 컴퓨터활용능력 워드프로세서 | AW4: ISTQB | AX4: 2017.03 | AY4: 아키텍처 | AZ4: 경영지원 | BA4: 기업은행 | BB4: 122-068082-01-018 | BC4: 처 | BD4: 010-9126-0218 | BE4: hk.kang@tbell.co.kr | BF4: 경기도 | BG4: 고양시 | BH4: 덕양구 | BI4: 덕양구 성신로99, 1909 1501호(행신동, 햇빛마을 19단지 공무원 아파트) | BJ4: =IFERROR(VLOOKUP($BG4,[1]프로젝트현황!Y:Z,2,0),"기타") -> 서북권 | BK4: =(IF(BF4="","",BF4&" "))&(IF(BG4="","",BG4&" "))&(IF(BH4="","",BH4&" "))&BI4 -> 경기도 고양시 덕양구 덕양구 성신로99, 1909 1501호(행신동, 햇빛마을 19단지 공무원 아파트) | BL4: 30 | BM4: 30 | BN4: 80000000 | BO4: =BP4*12 -> 80000000 | BP4: =BN4/12 -> 6666666.7 | BQ4: =BP4-BS4 -> 6466666.7 | BR4: 0 | BS4: 200000 | BT4: 0 | BU4: =IF($BN4="","", IFERROR( IF($BN4<'[1]시간외시간 기준표'!$B$2,0, IF($BN4>LOOKUP(9.9E+307,'[1]시간외시간 기준표'!$B$2:$B$999), LOOKUP(9.9E+307,'[1]시간외시간 기준표'!$C$2:$C$999), LOOKUP($BN4,'[1]시간외시간 기준표'!$B$2:$B$999,'[1]시간외시간 기준표'!$C$2:$C$999) ) ),0) ) -> 52 | BV4: =(BQ4+BS4)/209 -> 31897.927 | BW4: 30 | BX4: 30 | BY4: 80000000 | BZ4: =CA4*12 -> 80000000 | CA4: =BY4/12 -> 6666666.7 | CB4: =CA4-CD4 -> 6466666.7 | CC4: 0 | CD4: 200000 | CE4: 0 | CF4: 0 | CG4: =(CB4+CD4)/209 -> 31897.927 | CH4: 30 | CI4: 30 | CJ4: 80000000 | CK4: =CL4*12 -> 80000000 | CL4: =SUM(CM4:CO4) -> 6666666.7 | CM4: =ROUNDUP(CJ4/12*209/(209+CQ4*1.5)/CH4*CI4,-1)-CO4 -> 4654820 | CN4: =ROUNDUP(CJ4/12*(CQ4*1.5)/(209+CQ4*1.5)/CH4*CI4,1) -> 1811846.7 | CO4: 200000 | CP4: 209 | CQ4: =IF(CJ4<26000000,0,IF(CJ4<26500000,4,IF(CJ4<27000000,7,IF(CJ4<27500000,9,IF(CJ4<28000000,11,IF(CJ4<28500000,15,IF(CJ4<29000000,17,IF(CJ4<29500000,20,IF(CJ4<30000000,23,IF(CJ4<30500000,25,IF(CJ4<31000000,27,IF(CJ4<31500000,29,IF(CJ4<32000000,33,IF(CJ4<32500000,37,IF(CJ4<33000000,39,IF(CJ4<33500000,42,IF(CJ4<34000000,45,IF(CJ4<34500000,48,IF(CJ4<35000000,52,52))))))))))))))))))) -> 52 | CR4: =(CM4+CO4)/209 -> 23228.804 | CS4: 60000000 | CT4: =IFERROR(CS4/12,"") -> 5000000 | CU4: =IFERROR(CT4-CV4-CW4,"") -> 3441115 | CV4: =IFERROR(CT4*(CY4*1.5)/(209+(CY4*1.5)),"") -> 1358885 | CW4: 200000 | CX4: 209 | CY4: 52 | CZ4: =SUM(CX4:CY4) -> 261 | DA4: =IFERROR((CU4/209)+(CW4-(9620*209*0.01))/209,"") -> 17325.403 | DB4: =IFERROR((CU4+CW4)/209,"") -> 17421.603 | DC4: 2023 | DG4: =B4 -> 151201
A5: =ROW()-2 -> 3 | B5: 170702 | C5: 강성희 | E5: 선임 | F5: 정규직 | G5: 테스터 | H5: 3실 | I5: GS리테일 1팀 | J5: =+VLOOKUP($I5,[1]프로젝트현황!$I:$N,5,0) -> 서울시 | K5: =+VLOOKUP($I5,[1]프로젝트현황!$I:$N,6,0) -> 영등포구 | L5: 42926 | M5: 42926 | Q5: 830509-2065313 | R5: =LEFT(Q5,6) -> 830509 | S5: =MID($Q5,3,2) -> 05 | T5: =IF(OR(MID($Q5,8,1)="1",MID($Q5,8,1)="3"),"남자",IF(OR(MID($Q5,8,1)="2",MID($Q5,8,1)="4"),"여자","")) -> 여자 | U5: =YEAR(TODAY())-IF(OR(MID($Q5,8,1)="1",MID($Q5,8,1)="2"),19&LEFT($Q5,2),IF(OR(MID($Q5,8,1)="3",MID($Q5,8,1)="4"),20&LEFT($Q5,2),""))+1 -> 44 | V5: 양력 | W5: 한국 | X5: 010-9589-5859 | AB5: TBELL | AD5: =QUOTIENT(SUMPRODUCT(LEFT($AE5:$AF5,FIND("년",$AE5:$AF5)-1)*12+MID($AE5:$AF5,FIND("년",$AE5:$AF5)+1,FIND("개월",$AE5:$AF5)-FIND("년",$AE5:$AF5)-1)),12)&"년"&MOD(SUMPRODUCT(LEFT($AE5:$AF5,FIND("년",$AE5:$AF5)-1)*12+MID($AE5:$AF5,FIND("년",$AE5:$AF5)+1,FIND("개월",$AE5:$AF5)-FIND("년",$AE5:$AF5)-1)),12)&"개월" -> 13년4개월 | AE5: 4년 9개월 | AF5: =DATEDIF($L5,TODAY(),"y")&"년"&DATEDIF($L5,TODAY(),"ym")&"개월" -> 8년7개월 | AG5: 동원대학교 | AH5: 교육서비스문헌정보과 | AI5: 전문학사 | AJ5: 38765 | AK5: =VALUE(LEFT($AD5,FIND("년",$AD5)-1)) -> 13 | AL5: =IF($ABN3="전문학사",IF($AK5<=8,"초급",IF($AK5<12,"중급",IF($AK5<15,"고급",IF($AK5>=15,"특급"))))) -> FALSE | AM5: =IF(ISNUMBER(SEARCH("산업기사",$AT5)),IF($AK5>=13,"특급",IF($AK5>=10,"고급",IF($AK5>=7,"중급","초급"))),IF(ISNUMBER(SEARCH("기사",$AR5)),IF($AK5>=10,"특급",IF($AK5>=7,"고급",IF($AK5>=4,"중급","초급"))),"미해당")) -> 미해당 | AV5: 워드프로세스 2급 컴퓨터활용능력 3급 | AW5: 대한상공회의소 대한상공회의소 | AX5: 1999.11 2001.06 | AY5: IT기획 및 품질관리 | AZ5: 테스팅 엔지니어 | BA5: 기업은행 | BB5: 248-009498-01-029 | BC5: 모 | BD5: 010-2588-0245 | BE5: sh.kang@tbell.co.kr | BF5: 서울시 | BG5: 금천구 | BI5: 시흥대로94길 33-4 3층 (독산동 1058-20) | BJ5: =IFERROR(VLOOKUP($BG5,[1]프로젝트현황!Y:Z,2,0),"기타") -> 서남권 | BK5: =(IF(BF5="","",BF5&" "))&(IF(BG5="","",BG5&" "))&(IF(BH5="","",BH5&" "))&BBN3 -> 서울시 금천구 | BL5: 30 | BM5: 30 | BN5: 34000000 | BO5: =(BP5*12) -> 34000082 | BP5: =SUM(BQ5:BS5) -> 2833340.2 | BQ5: =ROUNDUP(BN5/12*209/(209+BU5*1.5)/BL5*BM5,-1)-BS5 -> 1965150 | BR5: =ROUNDUP(BN5/12*(BU5*1.5)/(209+BU5*1.5)/BL5*BM5,1) -> 668190.2 | BS5: 200000 | BT5: 209 | BU5: =IF($BN5="","", IFERROR( IF($BN5<'[1]시간외시간 기준표'!$B$2,0, IF($BN5>LOOKUP(9.9E+307,'[1]시간외시간 기준표'!$B$2:$B$999), LOOKUP(9.9E+307,'[1]시간외시간 기준표'!$C$2:$C$999), LOOKUP($BN5,'[1]시간외시간 기준표'!$B$2:$B$999,'[1]시간외시간 기준표'!$C$2:$C$999) ) ),0) ) -> 43 | BV5: =(BQ5+BS5)/209 -> 10359.569 | BW5: 30 | BX5: 30 | BY5: 34000000 | BZ5: =(CA5*12) -> 34000064 | CA5: =SUM(CB5:CD5) -> 2833338.7 | CB5: =ROUNDUP(BY5/12*209/(209+CF5*1.5)/BW5*BX5,-1)-CD5 -> 1907360 | CC5: =ROUNDUP(BY5/12*(CF5*1.5)/(209+CF5*1.5)/BW5*BX5,1) -> 725978.7 | CD5: 200000 | CE5: 209 | CF5: =IF(BY5<26000000,0,IF(BY5<26500000,4,IF(BY5<27000000,7,IF(BY5<27500000,9,IF(BY5<28000000,11,IF(BY5<28500000,15,IF(BY5<29000000,17,IF(BY5<29500000,20,IF(BY5<30000000,23,IF(BY5<30500000,25,IF(BY5<31000000,27,IF(BY5<31500000,29,IF(BY5<32000000,33,IF(BY5<32500000,37,IF(BY5<33000000,39,IF(BY5<33500000,42,IF(BY5<34000000,45,IF(BY5<34500000,48,IF(BY5<35000000,52,52))))))))))))))))))) -> 48 | CG5: =(CB5+CD5)/209 -> 10083.062 | CH5: 30 | CI5: 30 | CJ5: 33200000 | CK5: =CL5*12 -> 0 | CL5: =SUM(CM5:CO5) -> 0 | CM5: =ROUNDUP(CJ5/12*209/(209+CQ5*1.5)/CH5*CBN3,-1)-CO5 -> -200000 | CN5: =ROUNDUP(CJ5/12*(CQ5*1.5)/(209+CQ5*1.5)/CH5*CBN3,1) -> 0 | CO5: 200000 | CP5: 209 | CQ5: =IF(CJ5<26000000,0,IF(CJ5<26500000,4,IF(CJ5<27000000,7,IF(CJ5<27500000,9,IF(CJ5<28000000,11,IF(CJ5<28500000,15,IF(CJ5<29000000,17,IF(CJ5<29500000,20,IF(CJ5<30000000,23,IF(CJ5<30500000,25,IF(CJ5<31000000,27,IF(CJ5<31500000,29,IF(CJ5<32000000,33,IF(CJ5<32500000,37,IF(CJ5<33000000,39,IF(CJ5<33500000,42,IF(CJ5<34000000,45,IF(CJ5<34500000,48,IF(CJ5<35000000,52,52))))))))))))))))))) -> 42 | CR5: =(CM5+CO5)/209 -> 0 | CS5: 32000000 | CT5: =IFERROR(CS5/12,"") -> 2666666.7 | CU5: =IFERROR(CBX3-CV5-CW5,"") -> -200000 | CV5: =IFERROR(CBX3*(CY5*1.5)/(209+(CY5*1.5)),"") -> 0 | CW5: 200000 | CX5: 209 | CY5: 43 | CZ5: =SUM(CX5:CY5) -> 252 | DA5: =IFERROR((CU5/209)+(CW5-(9620*209*0.01))/209,"") -> -96.2 | DB5: =IFERROR((CU5+CW5)/209,"") -> 0 | DC5: 2023 | DG5: =B5 -> 170702
A6: =ROW()-2 -> 4 | B6: 170801 | C6: 서동한 | E6: 선임 | F6: 정규직 | G6: 테스터 | H6: 2실 | I6: 삼성카드 1팀 | J6: =+VLOOKUP($I6,[1]프로젝트현황!$I:$N,5,0) -> 서울시 | K6: =+VLOOKUP($I6,[1]프로젝트현황!$I:$N,6,0) -> 중구 | L6: 42948 | M6: 42948 | P6: Seo, Dang Han | Q6: 890218-1054222 | R6: =LEFT(Q6,6) -> 890218 | S6: 3 | T6: =IF(OR(MID($Q6,8,1)="1",MID($Q6,8,1)="3"),"남자",IF(OR(MID($Q6,8,1)="2",MID($Q6,8,1)="4"),"여자","")) -> 남자 | U6: =YEAR(TODAY())-IF(OR(MID($Q6,8,1)="1",MID($Q6,8,1)="2"),19&LEFT($Q6,2),IF(OR(MID($Q6,8,1)="3",MID($Q6,8,1)="4"),20&LEFT($Q6,2),""))+1 -> 38 | V6: 음력 | W6: 한국 | X6: 010-4101-4909 | Z6: 무 | AB6: TBELL | AD6: =QUOTIENT(SUMPRODUCT(LEFT($AE6:$AF6,FIND("년",$AE6:$AF6)-1)*12+MID($AE6:$AF6,FIND("년",$AE6:$AF6)+1,FIND("개월",$AE6:$AF6)-FIND("년",$AE6:$AF6)-1)),12)&"년"&MOD(SUMPRODUCT(LEFT($AE6:$AF6,FIND("년",$AE6:$AF6)-1)*12+MID($AE6:$AF6,FIND("년",$AE6:$AF6)+1,FIND("개월",$AE6:$AF6)-FIND("년",$AE6:$AF6)-1)),12)&"개월" -> 8년8개월 | AE6: 0년2개월 | AF6: =DATEDIF($L6,TODAY(),"y")&"년"&DATEDIF($L6,TODAY(),"ym")&"개월" -> 8년6개월 | AG6: 한신대학교 | AH6: 정보통신학 | AI6: 학사 | AJ6: 41684 | AK6: =VALUE(LEFT($AD6,FIND("년",$AD6)-1)) -> 8 | AL6: =IF($AI6="학사",IF($AK6<=5,"초급",IF($AK6<9,"중급",IF($AK6<12,"고급",IF($AK6>=12,"특급"))))) -> 중급 | AM6: =IF(ISNUMBER(SEARCH("산업기사",$AT6)),IF($AK6>=13,"특급",IF($AK6>=10,"고급",IF($AK6>=7,"중급","초급"))),IF(ISNUMBER(SEARCH("기사",$AR6)),IF($AK6>=10,"특급",IF($AK6>=7,"고급",IF($AK6>=4,"중급","초급"))),"미해당")) -> 미해당 | AV6: 네트워크관리사 2급 자동차운전면허 1종 보통 | AW6: 한국정보통신자격협회 경기지방경찰청 | AX6: 2012.12.11 2012.02.14 | AY6: IT기획 및 품질관리 | AZ6: 테스팅 엔지니어 | BA6: 기업은행 | BB6: 326-119130-01-010 | BC6: 부 | BD6: 010-5287-1237 | BE6: dh.seo@tbell.co.kr | BF6: 경기도 | BG6: 안산시 | BH6: 단원구 | BI6: 단원구 광덕3로 241, 4층 (고잔동 760-2) | BJ6: =IFERROR(VLOOKUP($BG6,[1]프로젝트현황!Y:Z,2,0),"기타") -> 서남권 | BK6: =(IF(BF6="","",BF6&" "))&(IF(BG6="","",BG6&" "))&(IF(BH6="","",BH6&" "))&BI6 -> 경기도 안산시 단원구 단원구 광덕3로 241, 4층 (고잔동 760-2) | BL6: 30 | BM6: 30 | BN6: 34000000 | BO6: =BP6*12 -> 34000082 | BP6: =SUM(BQ6:BS6) -> 2833340.2 | BQ6: =ROUNDUP(BN6/12*209/(209+BU6*1.5)/BL6*BM6,-1)-BS6 -> 1965150 | BR6: =ROUNDUP(BN6/12*(BU6*1.5)/(209+BU6*1.5)/BL6*BM6,1) -> 668190.2 | BS6: 200000 | BT6: 209 | BU6: =IF($BN6="","", IFERROR( IF($BN6<'[1]시간외시간 기준표'!$B$2,0, IF($BN6>LOOKUP(9.9E+307,'[1]시간외시간 기준표'!$B$2:$B$999), LOOKUP(9.9E+307,'[1]시간외시간 기준표'!$C$2:$C$999), LOOKUP($BN6,'[1]시간외시간 기준표'!$B$2:$B$999,'[1]시간외시간 기준표'!$C$2:$C$999) ) ),0) ) -> 43 | BV6: =(BQ6+BS6)/209 -> 10359.569 | BW6: 30 | BX6: 30 | BY6: 34000000 | BZ6: =CA6*12 -> 34000064 | CA6: =SUM(CB6:CD6) -> 2833338.7 | CB6: =ROUNDUP(BY6/12*209/(209+CF6*1.5)/BW6*BX6,-1)-CD6 -> 1907360 | CC6: =ROUNDUP(BY6/12*(CF6*1.5)/(209+CF6*1.5)/BW6*BX6,1) -> 725978.7 | CD6: 200000 | CE6: 209 | CF6: =IF(BY6<26000000,0,IF(BY6<26500000,4,IF(BY6<27000000,7,IF(BY6<27500000,9,IF(BY6<28000000,11,IF(BY6<28500000,15,IF(BY6<29000000,17,IF(BY6<29500000,20,IF(BY6<30000000,23,IF(BY6<30500000,25,IF(BY6<31000000,27,IF(BY6<31500000,29,IF(BY6<32000000,33,IF(BY6<32500000,37,IF(BY6<33000000,39,IF(BY6<33500000,42,IF(BY6<34000000,45,IF(BY6<34500000,48,IF(BY6<35000000,52,52))))))))))))))))))) -> 48 | CG6: =(CB6+CD6)/209 -> 10083.062 | CH6: 30 | CI6: 30 | CJ6: 33200000 | CK6: =CL6*12 -> 33200027 | CL6: =SUM(CM6:CO6) -> 2766668.9 | CM6: =ROUNDUP(CJ6/12*209/(209+CQ6*1.5)/CH6*CI6,-1)-CO6 -> 1925860 | CN6: =ROUNDUP(CJ6/12*(CQ6*1.5)/(209+CQ6*1.5)/CH6*CI6,1) -> 640808.9 | CO6: 200000 | CP6: 209 | CQ6: =IF(CJ6<26000000,0,IF(CJ6<26500000,4,IF(CJ6<27000000,7,IF(CJ6<27500000,9,IF(CJ6<28000000,11,IF(CJ6<28500000,15,IF(CJ6<29000000,17,IF(CJ6<29500000,20,IF(CJ6<30000000,23,IF(CJ6<30500000,25,IF(CJ6<31000000,27,IF(CJ6<31500000,29,IF(CJ6<32000000,33,IF(CJ6<32500000,37,IF(CJ6<33000000,39,IF(CJ6<33500000,42,IF(CJ6<34000000,45,IF(CJ6<34500000,48,IF(CJ6<35000000,52,52))))))))))))))))))) -> 42 | CR6: =(CM6+CO6)/209 -> 10171.579 | CS6: 32000000 | CT6: =IFERROR(CS6/12,"") -> 2666666.7 | CU6: =IFERROR(CT6-CV6-CW6,"") -> 1837781.8 | CV6: =IFERROR(CT6*(CY6*1.5)/(209+(CY6*1.5)),"") -> 628884.83 | CW6: 200000 | CX6: 209 | CY6: 43 | CZ6: =SUM(CX6:CY6) -> 252 | DA6: =IFERROR((CU6/209)+(CW6-(9620*209*0.01))/209,"") -> 9653.9523 | DB6: =IFERROR((CU6+CW6)/209,"") -> 9750.1523 | DC6: 2023 | DG6: =B6 -> 170801
A7: =ROW()-2 -> 5 | B7: 170803 | C7: 조현균 | D7: 팀장 | E7: 책임 | F7: 정규직 | G7: 테스터 | H7: 3실 | I7: GS리테일 1팀 | J7: =+VLOOKUP($I7,[1]프로젝트현황!$I:$N,5,0) -> 서울시 | K7: =+VLOOKUP($I7,[1]프로젝트현황!$I:$N,6,0) -> 영등포구 | L7: 42948 | M7: 42948 | P7: Cho, Hyun Gyun | Q7: 860429-1382113 | R7: =LEFT(Q7,6) -> 860429 | S7: =MID($Q7,3,2) -> 04 | T7: =IF(OR(MID($Q7,8,1)="1",MID($Q7,8,1)="3"),"남자",IF(OR(MID($Q7,8,1)="2",MID($Q7,8,1)="4"),"여자","")) -> 남자 | U7: =YEAR(TODAY())-IF(OR(MID($Q7,8,1)="1",MID($Q7,8,1)="2"),19&LEFT($Q7,2),IF(OR(MID($Q7,8,1)="3",MID($Q7,8,1)="4"),20&LEFT($Q7,2),""))+1 -> 41 | V7: 양력 | W7: 한국 | X7: 010-8903-8016 | AB7: TBELL | AD7: =QUOTIENT(SUMPRODUCT(LEFT($AE7:$AF7,FIND("년",$AE7:$AF7)-1)*12+MID($AE7:$AF7,FIND("년",$AE7:$AF7)+1,FIND("개월",$AE7:$AF7)-FIND("년",$AE7:$AF7)-1)),12)&"년"&MOD(SUMPRODUCT(LEFT($AE7:$AF7,FIND("년",$AE7:$AF7)-1)*12+MID($AE7:$AF7,FIND("년",$AE7:$AF7)+1,FIND("개월",$AE7:$AF7)-FIND("년",$AE7:$AF7)-1)),12)&"개월" -> 16년11개월 | AE7: 8년 5개월 | AF7: =DATEDIF($L7,TODAY(),"y")&"년"&DATEDIF($L7,TODAY(),"ym")&"개월" -> 8년6개월 | AG7: 두원공과대 | AH7: 정보통신미디어계열 | AI7: 전문학사 | AJ7: 39492 | AK7: =VALUE(LEFT($AD7,FIND("년",$AD7)-1)) -> 16 | AL7: =IF($AI7="전문학사",IF($AK7<=8,"초급",IF($AK7<12,"중급",IF($AK7<15,"고급",IF($AK7>=15,"특급"))))) -> 특급 | AM7: =IF(ISNUMBER(SEARCH("산업기사",$AT7)),IF($AK7>=13,"특급",IF($AK7>=10,"고급",IF($AK7>=7,"중급","초급"))),IF(ISNUMBER(SEARCH("기사",$AR7)),IF($AK7>=10,"특급",IF($AK7>=7,"고급",IF($AK7>=4,"중급","초급"))),"미해당")) -> 미해당 | AN7: CSTS | AO7: 44794 | AP7: ISTQB | AQ7: 44035 | AW7: KSTQB 한국정보통신기술협회 | AX7: 2020.07 2021.09.03 | AY7: IT기획 및 품질관리 | AZ7: 테스팅 엔지니어 | BA7: 기업은행 | BB7: 607-022578-01-018 | BC7: 모 | BD7: 010-4931-8016 | BE7: hg.cho@tbell.co.kr | BF7: 경기도 | BG7: 수원시 | BH7: 팔달구 | BI7: 경수대로 534, 102동 401호 (인계동 945, 인계극동스타클래스) | BJ7: =IFERROR(VLOOKUP($BG7,[1]프로젝트현황!Y:Z,2,0),"기타") -> 동남권 | BK7: =(IF(BF7="","",BF7&" "))&(IF(BG7="","",BG7&" "))&(IF(BH7="","",BH7&" "))&BI7 -> 경기도 수원시 팔달구 경수대로 534, 102동 401호 (인계동 945, 인계극동스타클래스) | BL7: 30 | BM7: 30 | BN7: 39000000 | BO7: =BP7*12 -> 39000064 | BP7: =SUM(BQ7:BS7) -> 3250005.3 | BQ7: =ROUNDUP(BN7/12*209/(209+BU7*1.5)/BL7*BM7,-1)-BS7 -> 2166730 | BR7: =ROUNDUP(BN7/12*(BU7*1.5)/(209+BU7*1.5)/BL7*BM7,1) -> 883275.3 | BS7: 200000 | BT7: 209 | BU7: =IF($BN7="","", IFERROR( IF($BN7<'[1]시간외시간 기준표'!$B$2,0, IF($BN7>LOOKUP(9.9E+307,'[1]시간외시간 기준표'!$B$2:$B$999), LOOKUP(9.9E+307,'[1]시간외시간 기준표'!$C$2:$C$999), LOOKUP($BN7,'[1]시간외시간 기준표'!$B$2:$B$999,'[1]시간외시간 기준표'!$C$2:$C$999) ) ),0) ) -> 52 | BV7: =(BQ7+BS7)/209 -> 11324.067 | BW7: 30 | BX7: 30 | BY7: 39000000 | BZ7: =CA7*12 -> 39000064 | CA7: =SUM(CB7:CD7) -> 3250005.3 | CB7: =ROUNDUP(BY7/12*209/(209+CF7*1.5)/BW7*BX7,-1)-CD7 -> 2166730 | CC7: =ROUNDUP(BY7/12*(CF7*1.5)/(209+CF7*1.5)/BW7*BX7,1) -> 883275.3 | CD7: 200000 | CE7: 209 | CF7: =IF(BY7<26000000,0,IF(BY7<26500000,4,IF(BY7<27000000,7,IF(BY7<27500000,9,IF(BY7<28000000,11,IF(BY7<28500000,15,IF(BY7<29000000,17,IF(BY7<29500000,20,IF(BY7<30000000,23,IF(BY7<30500000,25,IF(BY7<31000000,27,IF(BY7<31500000,29,IF(BY7<32000000,33,IF(BY7<32500000,37,IF(BY7<33000000,39,IF(BY7<33500000,42,IF(BY7<34000000,45,IF(BY7<34500000,48,IF(BY7<35000000,52,52))))))))))))))))))) -> 52 | CG7: =(CB7+CD7)/209 -> 11324.067 | CH7: 30 | CI7: 30 | CJ7: 38200000 | CK7: =CL7*12 -> 38200042 | CL7: =SUM(CM7:CO7) -> 3183336.8 | CM7: =ROUNDUP(CJ7/12*209/(209+CQ7*1.5)/CH7*CI7,-1)-CO7 -> 2118180 | CN7: =ROUNDUP(CJ7/12*(CQ7*1.5)/(209+CQ7*1.5)/CH7*CI7,1) -> 865156.8 | CO7: 200000 | CP7: 209 | CQ7: =IF(CJ7<26000000,0,IF(CJ7<26500000,4,IF(CJ7<27000000,7,IF(CJ7<27500000,9,IF(CJ7<28000000,11,IF(CJ7<28500000,15,IF(CJ7<29000000,17,IF(CJ7<29500000,20,IF(CJ7<30000000,23,IF(CJ7<30500000,25,IF(CJ7<31000000,27,IF(CJ7<31500000,29,IF(CJ7<32000000,33,IF(CJ7<32500000,37,IF(CJ7<33000000,39,IF(CJ7<33500000,42,IF(CJ7<34000000,45,IF(CJ7<34500000,48,IF(CJ7<35000000,52,52))))))))))))))))))) -> 52 | CR7: =(CM7+CO7)/209 -> 11091.77 | CS7: 37000000 | CT7: =IFERROR(CS7/12,"") -> 3083333.3 | CU7: =IFERROR(CT7-CV7-CW7,"") -> 2045354.2 | CV7: =IFERROR(CT7*(CY7*1.5)/(209+(CY7*1.5)),"") -> 837979.09 | CW7: 200000 | CX7: 209 | CY7: 52 | CZ7: =SUM(CX7:CY7) -> 261 | DA7: =IFERROR((CU7/209)+(CW7-(9620*209*0.01))/209,"") -> 10647.122 | DB7: =IFERROR((CU7+CW7)/209,"") -> 10743.322 | DC7: 2023 | DG7: =B7 -> 170803
A8: =ROW()-2 -> 6 | B8: 170904 | C8: 조소영 | E8: 선임 | F8: 정규직 | G8: 테스터 | H8: 3실 | I8: GS리테일 6팀 | J8: =+VLOOKUP($I8,[1]프로젝트현황!$I:$N,5,0) -> 서울시 | K8: =+VLOOKUP($I8,[1]프로젝트현황!$I:$N,6,0) -> 영등포구 | L8: 42982 | M8: 42982 | P8: Jo, So Young | Q8: 900424-2163820 | R8: =LEFT(Q8,6) -> 900424 | S8: =MID($Q8,3,2) -> 04 | T8: =IF(OR(MID($Q8,8,1)="1",MID($Q8,8,1)="3"),"남자",IF(OR(MID($Q8,8,1)="2",MID($Q8,8,1)="4"),"여자","")) -> 여자 | U8: =YEAR(TODAY())-IF(OR(MID($Q8,8,1)="1",MID($Q8,8,1)="2"),19&LEFT($Q8,2),IF(OR(MID($Q8,8,1)="3",MID($Q8,8,1)="4"),20&LEFT($Q8,2),""))+1 -> 37 | V8: 양력 | W8: 한국 | X8: 010-9189-7381 | Z8: 무 | AB8: TBELL | AD8: =QUOTIENT(SUMPRODUCT(LEFT($AE8:$AF8,FIND("년",$AE8:$AF8)-1)*12+MID($AE8:$AF8,FIND("년",$AE8:$AF8)+1,FIND("개월",$AE8:$AF8)-FIND("년",$AE8:$AF8)-1)),12)&"년"&MOD(SUMPRODUCT(LEFT($AE8:$AF8,FIND("년",$AE8:$AF8)-1)*12+MID($AE8:$AF8,FIND("년",$AE8:$AF8)+1,FIND("개월",$AE8:$AF8)-FIND("년",$AE8:$AF8)-1)),12)&"개월" -> 13년1개월 | AE8: 4년 8개월 | AF8: =DATEDIF($L8,TODAY(),"y")&"년"&DATEDIF($L8,TODAY(),"ym")&"개월" -> 8년5개월 | AG8: 용인송담대학교 | AH8: 멀티미디어영상과 | AI8: 전문학사 | AJ8: 40585 | AK8: =VALUE(LEFT($AD8,FIND("년",$AD8)-1)) -> 13 | AL8: =IF($AI8="전문학사",IF($AK8<=8,"초급",IF($AK8<12,"중급",IF($AK8<15,"고급",IF($AK8>=15,"특급"))))) -> 고급 | AM8: =IF(ISNUMBER(SEARCH("산업기사",$AT8)),IF($AK8>=13,"특급",IF($AK8>=10,"고급",IF($AK8>=7,"중급","초급"))),IF(ISNUMBER(SEARCH("기사",$AR8)),IF($AK8>=10,"특급",IF($AK8>=7,"고급",IF($AK8>=4,"중급","초급"))),"미해당")) -> 미해당 | AV8: 워드프로세스 MOS Excel 2003 MOS Powerpoint 2003 | AW8: 대한상공회의소 MS MS | AX8: 2001.12.26 2010.09.17 2010.10.01 | AY8: IT기획 및 품질관리 | AZ8: 테스팅 엔지니어 | BA8: 기업은행 | BB8: 065-135562-01-013 | BC8: 모 | BD8: 010-5039-9118 | BE8: sy.jo@tbell.co.kr | BF8: 경기도 | BG8: 수원시 | BH8: 권선구 | BI8: 경수대로 302번길 29, 4동 501호 (권선제2동 1185-1, 권선삼성아파트) | BJ8: =IFERROR(VLOOKUP($BG8,[1]프로젝트현황!Y:Z,2,0),"기타") -> 동남권 | BK8: =(IF(BF8="","",BF8&" "))&(IF(BG8="","",BG8&" "))&(IF(BH8="","",BH8&" "))&BI8 -> 경기도 수원시 권선구 경수대로 302번길 29, 4동 501호 (권선제2동 1185-1, 권선삼성아파트) | BL8: 30 | BM8: 30 | BN8: 36400000 | BO8: =BP8*12 -> 36400084 | BP8: =SUM(BQ8:BS8) -> 3033340.3 | BQ8: =ROUNDUP(BN8/12*209/(209+BU8*1.5)/BL8*BM8,-1)-BS8 -> 2008950 | BR8: =ROUNDUP(BN8/12*(BU8*1.5)/(209+BU8*1.5)/BL8*BM8,1) -> 824390.3 | BS8: 200000 | BT8: 209 | BU8: =IF($BN8="","", IFERROR( IF($BN8<'[1]시간외시간 기준표'!$B$2,0, IF($BN8>LOOKUP(9.9E+307,'[1]시간외시간 기준표'!$B$2:$B$999), LOOKUP(9.9E+307,'[1]시간외시간 기준표'!$C$2:$C$999), LOOKUP($BN8,'[1]시간외시간 기준표'!$B$2:$B$999,'[1]시간외시간 기준표'!$C$2:$C$999) ) ),0) ) -> 52 | BV8: =(BQ8+BS8)/209 -> 10569.139 | BW8: 30 | BX8: 30 | BY8: 36400000 | BZ8: =CA8*12 -> 36400084 | CA8: =SUM(CB8:CD8) -> 3033340.3 | CB8: =ROUNDUP(BY8/12*209/(209+CF8*1.5)/BW8*BX8,-1)-CD8 -> 2008950 | CC8: =ROUNDUP(BY8/12*(CF8*1.5)/(209+CF8*1.5)/BW8*BX8,1) -> 824390.3 | CD8: 200000 | CE8: 209 | CF8: =IF(BY8<26000000,0,IF(BY8<26500000,4,IF(BY8<27000000,7,IF(BY8<27500000,9,IF(BY8<28000000,11,IF(BY8<28500000,15,IF(BY8<29000000,17,IF(BY8<29500000,20,IF(BY8<30000000,23,IF(BY8<30500000,25,IF(BY8<31000000,27,IF(BY8<31500000,29,IF(BY8<32000000,33,IF(BY8<32500000,37,IF(BY8<33000000,39,IF(BY8<33500000,42,IF(BY8<34000000,45,IF(BY8<34500000,48,IF(BY8<35000000,52,52))))))))))))))))))) -> 52 | CG8: =(CB8+CD8)/209 -> 10569.139 | CH8: 30 | CI8: 30 | CJ8: 35600000 | CK8: =CL8*12 -> 35600062 | CL8: =SUM(CM8:CO8) -> 2966671.8 | CM8: =ROUNDUP(CJ8/12*209/(209+CQ8*1.5)/CH8*CI8,-1)-CO8 -> 1960400 | CN8: =ROUNDUP(CJ8/12*(CQ8*1.5)/(209+CQ8*1.5)/CH8*CI8,1) -> 806271.8 | CO8: 200000 | CP8: 209 | CQ8: =IF(CJ8<26000000,0,IF(CJ8<26500000,4,IF(CJ8<27000000,7,IF(CJ8<27500000,9,IF(CJ8<28000000,11,IF(CJ8<28500000,15,IF(CJ8<29000000,17,IF(CJ8<29500000,20,IF(CJ8<30000000,23,IF(CJ8<30500000,25,IF(CJ8<31000000,27,IF(CJ8<31500000,29,IF(CJ8<32000000,33,IF(CJ8<32500000,37,IF(CJ8<33000000,39,IF(CJ8<33500000,42,IF(CJ8<34000000,45,IF(CJ8<34500000,48,IF(CJ8<35000000,52,52))))))))))))))))))) -> 52 | CR8: =(CM8+CO8)/209 -> 10336.842 | CS8: 35000000 | CT8: =IFERROR(CS8/12,"") -> 2916666.7 | CU8: =IFERROR(CT8-CV8-CW8,"") -> 1923983.7 | CV8: =IFERROR(CT8*(CY8*1.5)/(209+(CY8*1.5)),"") -> 792682.93 | CW8: 200000 | CX8: 209 | CY8: 52 | CZ8: =SUM(CX8:CY8) -> 261 | DA8: =IFERROR((CU8/209)+(CW8-(9620*209*0.01))/209,"") -> 10066.402 | DB8: =IFERROR((CU8+CW8)/209,"") -> 10162.602 | DC8: 2023 | DD8: 동결 | DG8: =B8 -> 170904
A9: =ROW()-2 -> 7 | B9: 180501 | C9: 정성우 | D9: 팀장 | E9: 책임 | F9: 정규직 | G9: 테스터 | H9: 2실 | I9: 반티바 1팀 | J9: =+VLOOKUP($I9,[1]프로젝트현황!$I:$N,5,0) -> 경기도 | K9: =+VLOOKUP($I9,[1]프로젝트현황!$I:$N,6,0) -> 성남시 | L9: 43244 | M9: 43244 | P9: Jung, Sung Woo | Q9: 810306-1167610 | R9: =LEFT(Q9,6) -> 810306 | S9: =MID($Q9,3,2) -> 03 | T9: =IF(OR(MID($Q9,8,1)="1",MID($Q9,8,1)="3"),"남자",IF(OR(MID($Q9,8,1)="2",MID($Q9,8,1)="4"),"여자","")) -> 남자 | U9: =YEAR(TODAY())-IF(OR(MID($Q9,8,1)="1",MID($Q9,8,1)="2"),19&LEFT($Q9,2),IF(OR(MID($Q9,8,1)="3",MID($Q9,8,1)="4"),20&LEFT($Q9,2),""))+1 -> 46 | V9: 양력 | W9: 한국 | X9: 010-5547-9612 | AB9: TBELL | AD9: =QUOTIENT(SUMPRODUCT(LEFT($AE9:$AF9,FIND("년",$AE9:$AF9)-1)*12+MID($AE9:$AF9,FIND("년",$AE9:$AF9)+1,FIND("개월",$AE9:$AF9)-FIND("년",$AE9:$AF9)-1)),12)&"년"&MOD(SUMPRODUCT(LEFT($AE9:$AF9,FIND("년",$AE9:$AF9)-1)*12+MID($AE9:$AF9,FIND("년",$AE9:$AF9)+1,FIND("개월",$AE9:$AF9)-FIND("년",$AE9:$AF9)-1)),12)&"개월" -> 17년6개월 | AE9: 9년 10개월 | AF9: =DATEDIF($L9,TODAY(),"y")&"년"&DATEDIF($L9,TODAY(),"ym")&"개월" -> 7년8개월 | AG9: 용인송담대학교 | AH9: 정보통신과 | AI9: 전문학사 | AJ9: 38401 | AK9: =VALUE(LEFT($AD9,FIND("년",$AD9)-1)) -> 17 | AL9: =IF($AI9="전문학사",IF($AK9<=8,"초급",IF($AK9<12,"중급",IF($AK9<15,"고급",IF($AK9>=15,"특급"))))) -> 특급 | AM9: =IF(ISNUMBER(SEARCH("산업기사",$AT9)),IF($AK9>=13,"특급",IF($AK9>=10,"고급",IF($AK9>=7,"중급","초급"))),IF(ISNUMBER(SEARCH("기사",$AR9)),IF($AK9>=10,"특급",IF($AK9>=7,"고급",IF($AK9>=4,"중급","초급"))),"미해당")) -> 미해당 | AV9: 정보기기운용기능사 정보처리기능사 무선통신기능사 워드프로세서 1급 교원자격증(실기교사-통신) 新JLPT N2 | AW9: 한국산업인력공단 한국산업인력공단 한국산업인력공단 대한상공회의소 교원인적자원부 국제교류기금 | AX9: 1999.04 1999.06 1999.07 1999.11 2005.02 2017.08 | AY9: IT기획 및 품질관리 | AZ9: 테스팅 엔지니어 | BA9: 기업은행 | BB9: 013-125229-01-010 | BC9: 모 | BD9: 010-9382-9612 | BE9: sw.jung@tbell.co.kr | BF9: 경기도 | BG9: 성남시 | BH9: 수정구 | BI9: 수정로 251번길 22 신원빌리지 102동 302호 | BJ9: =IFERROR(VLOOKUP($BG9,[1]프로젝트현황!Y:Z,2,0),"기타") -> 동남권 | BK9: =(IF(BF9="","",BF9&" "))&(IF(BG9="","",BG9&" "))&(IF(BH9="","",BH9&" "))&BI9 -> 경기도 성남시 수정구 수정로 251번길 22 신원빌리지 102동 302호 | BL9: 30 | BM9: 30 | BN9: 39600000 | BO9: =BP9*12 -> 39600050 | BP9: =SUM(BQ9:BS9) -> 3300004.2 | BQ9: =ROUNDUP(BN9/12*209/(209+BU9*1.5)/BL9*BM9,-1)-BS9 -> 2203140 | BR9: =ROUNDUP(BN9/12*(BU9*1.5)/(209+BU9*1.5)/BL9*BM9,1) -> 896864.2 | BS9: 200000 | BT9: 209 | BU9: =IF($BN9="","", IFERROR( IF($BN9<'[1]시간외시간 기준표'!$B$2,0, IF($BN9>LOOKUP(9.9E+307,'[1]시간외시간 기준표'!$B$2:$B$999), LOOKUP(9.9E+307,'[1]시간외시간 기준표'!$C$2:$C$999), LOOKUP($BN9,'[1]시간외시간 기준표'!$B$2:$B$999,'[1]시간외시간 기준표'!$C$2:$C$999) ) ),0) ) -> 52 | BV9: =(BQ9+BS9)/209 -> 11498.278 | BW9: 30 | BX9: 30 | BY9: 39600000 | BZ9: =CA9*12 -> 39600050 | CA9: =SUM(CB9:CD9) -> 3300004.2 | CB9: =ROUNDUP(BY9/12*209/(209+CF9*1.5)/BW9*BX9,-1)-CD9 -> 2203140 | CC9: =ROUNDUP(BY9/12*(CF9*1.5)/(209+CF9*1.5)/BW9*BX9,1) -> 896864.2 | CD9: 200000 | CE9: 209 | CF9: =IF(BY9<26000000,0,IF(BY9<26500000,4,IF(BY9<27000000,7,IF(BY9<27500000,9,IF(BY9<28000000,11,IF(BY9<28500000,15,IF(BY9<29000000,17,IF(BY9<29500000,20,IF(BY9<30000000,23,IF(BY9<30500000,25,IF(BY9<31000000,27,IF(BY9<31500000,29,IF(BY9<32000000,33,IF(BY9<32500000,37,IF(BY9<33000000,39,IF(BY9<33500000,42,IF(BY9<34000000,45,IF(BY9<34500000,48,IF(BY9<35000000,52,52))))))))))))))))))) -> 52 | CG9: =(CB9+CD9)/209 -> 11498.278 | CH9: 30 | CI9: 30 | CJ9: 38800000 | CK9: =CL9*12 -> 38800028 | CL9: =SUM(CM9:CO9) -> 3233335.7 | CM9: =ROUNDUP(CJ9/12*209/(209+CQ9*1.5)/CH9*CI9,-1)-CO9 -> 2154590 | CN9: =ROUNDUP(CJ9/12*(CQ9*1.5)/(209+CQ9*1.5)/CH9*CI9,1) -> 878745.7 | CO9: 200000 | CP9: 209 | CQ9: =IF(CJ9<26000000,0,IF(CJ9<26500000,4,IF(CJ9<27000000,7,IF(CJ9<27500000,9,IF(CJ9<28000000,11,IF(CJ9<28500000,15,IF(CJ9<29000000,17,IF(CJ9<29500000,20,IF(CJ9<30000000,23,IF(CJ9<30500000,25,IF(CJ9<31000000,27,IF(CJ9<31500000,29,IF(CJ9<32000000,33,IF(CJ9<32500000,37,IF(CJ9<33000000,39,IF(CJ9<33500000,42,IF(CJ9<34000000,45,IF(CJ9<34500000,48,IF(CJ9<35000000,52,52))))))))))))))))))) -> 52 | CR9: =(CM9+CO9)/209 -> 11265.981 | CS9: 37000000 | CT9: =IFERROR(CS9/12,"") -> 3083333.3 | CU9: =IFERROR(CT9-CV9-CW9,"") -> 2045354.2 | CV9: =IFERROR(CT9*(CY9*1.5)/(209+(CY9*1.5)),"") -> 837979.09 | CW9: 200000 | CX9: 209 | CY9: 52 | CZ9: =SUM(CX9:CY9) -> 261 | DA9: =IFERROR((CU9/209)+(CW9-(9620*209*0.01))/209,"") -> 10647.122 | DB9: =IFERROR((CU9+CW9)/209,"") -> 10743.322 | DC9: 2023 | DG9: =B9 -> 180501
A10: =ROW()-2 -> 8 | B10: 180601 | C10: 전광희 | D10: 팀장 | E10: 선임 | F10: 정규직 | G10: 테스터 | H10: 1실 | I10: LG전자 1팀 | J10: =+VLOOKUP($I10,[1]프로젝트현황!$I:$N,5,0) -> 서울시 | K10: =+VLOOKUP($I10,[1]프로젝트현황!$I:$N,6,0) -> 강서구 | L10: 43262 | M10: 43262 | P10: Jeon, Gwang Hee | Q10: 920409-1187228 | R10: =LEFT(Q10,6) -> 920409 | S10: =MID($Q10,3,2) -> 04 | T10: =IF(OR(MID($Q10,8,1)="1",MID($Q10,8,1)="3"),"남자",IF(OR(MID($Q10,8,1)="2",MID($Q10,8,1)="4"),"여자","")) -> 남자 | U10: =YEAR(TODAY())-IF(OR(MID($Q10,8,1)="1",MID($Q10,8,1)="2"),19&LEFT($Q10,2),IF(OR(MID($Q10,8,1)="3",MID($Q10,8,1)="4"),20&LEFT($Q10,2),""))+1 -> 35 | V10: 양력 | W10: 한국 | X10: 010-4168-4630 | Z10: 무 | AB10: TBELL | AD10: =QUOTIENT(SUMPRODUCT(LEFT($AE10:$AF10,FIND("년",$AE10:$AF10)-1)*12+MID($AE10:$AF10,FIND("년",$AE10:$AF10)+1,FIND("개월",$AE10:$AF10)-FIND("년",$AE10:$AF10)-1)),12)&"년"&MOD(SUMPRODUCT(LEFT($AE10:$AF10,FIND("년",$AE10:$AF10)-1)*12+MID($AE10:$AF10,FIND("년",$AE10:$AF10)+1,FIND("개월",$AE10:$AF10)-FIND("년",$AE10:$AF10)-1)),12)&"개월" -> 9년4개월 | AE10: 1년 8개월 | AF10: =DATEDIF($L10,TODAY(),"y")&"년"&DATEDIF($L10,TODAY(),"ym")&"개월" -> 7년8개월 | AG10: 용인송담대학교 | AH10: 컴퓨터게임과 | AI10: 전문학사 | AJ10: 42412 | AK10: =VALUE(LEFT($AD10,FIND("년",$AD10)-1)) -> 9 | AL10: =IF($AI10="전문학사",IF($AK10<=8,"초급",IF($AK10<12,"중급",IF($AK10<15,"고급",IF($AK10>=15,"특급"))))) -> 중급 | AM10: =IF(ISNUMBER(SEARCH("산업기사",$AT10)),IF($AK10>=13,"특급",IF($AK10>=10,"고급",IF($AK10>=7,"중급","초급"))),IF(ISNUMBER(SEARCH("기사",$AR10)),IF($AK10>=10,"특급",IF($AK10>=7,"고급",IF($AK10>=4,"중급","초급"))),"미해당")) -> 미해당 | AY10: IT기획 및 품질관리 | AZ10: 테스팅 엔지니어 | BA10: 기업은행 | BB10: 534-026781-01-015 | BC10: 모 | BD10: 010-2657-4630 | BE10: gh.jeon@tbell.co.kr | BF10: 서울시 | BG10: 구로구 | BI10: 부일로17길 147 4층 | BJ10: =IFERROR(VLOOKUP($BG10,[1]프로젝트현황!Y:Z,2,0),"기타") -> 서남권 | BK10: =(IF(BF10="","",BF10&" "))&(IF(BG10="","",BG10&" "))&(IF(BH10="","",BH10&" "))&BI10 -> 서울시 구로구 부일로17길 147 4층 | BL10: 30 | BM10: 30 | BN10: 34600000 | BO10: =BP10*12 -> 34600050 | BP10: =SUM(BQ10:BS10) -> 2883337.5 | BQ10: =ROUNDUP(BN10/12*209/(209+BU10*1.5)/BL10*BM10,-1)-BS10 -> 1967690 | BR10: =ROUNDUP(BN10/12*(BU10*1.5)/(209+BU10*1.5)/BL10*BM10,1) -> 715647.5 | BS10: 200000 | BT10: 209 | BU10: =IF($BN10="","", IFERROR( IF($BN10<'[1]시간외시간 기준표'!$B$2,0, IF($BN10>LOOKUP(9.9E+307,'[1]시간외시간 기준표'!$B$2:$B$999), LOOKUP(9.9E+307,'[1]시간외시간 기준표'!$C$2:$C$999), LOOKUP($BN10,'[1]시간외시간 기준표'!$B$2:$B$999,'[1]시간외시간 기준표'!$C$2:$C$999) ) ),0) ) -> 46 | BV10: =(BQ10+BS10)/209 -> 10371.722 | BW10: 30 | BX10: 30 | BY10: 34600000 | BZ10: =CA10*12 -> 34600004 | CA10: =SUM(CB10:CD10) -> 2883333.7 | CB10: =ROUNDUP(BY10/12*209/(209+CF10*1.5)/BW10*BX10,-1)-CD10 -> 1899710 | CC10: =ROUNDUP(BY10/12*(CF10*1.5)/(209+CF10*1.5)/BW10*BX10,1) -> 783623.7 | CD10: 200000 | CE10: 209 | CF10: =IF(BY10<26000000,0,IF(BY10<26500000,4,IF(BY10<27000000,7,IF(BY10<27500000,9,IF(BY10<28000000,11,IF(BY10<28500000,15,IF(BY10<29000000,17,IF(BY10<29500000,20,IF(BY10<30000000,23,IF(BY10<30500000,25,IF(BY10<31000000,27,IF(BY10<31500000,29,IF(BY10<32000000,33,IF(BY10<32500000,37,IF(BY10<33000000,39,IF(BY10<33500000,42,IF(BY10<34000000,45,IF(BY10<34500000,48,IF(BY10<35000000,52,52))))))))))))))))))) -> 52 | CG10: =(CB10+CD10)/209 -> 10046.459 | CH10: 30 | CI10: 30 | CJ10: 33800000 | CK10: =CL10*12 -> 33800077 | CL10: =SUM(CM10:CO10) -> 2816673.1 | CM10: =ROUNDUP(CJ10/12*209/(209+CQ10*1.5)/CH10*CI10,-1)-CO10 -> 1929060 | CN10: =ROUNDUP(CJ10/12*(CQ10*1.5)/(209+CQ10*1.5)/CH10*CI10,1) -> 687613.1 | CO10: 200000 | CP10: 209 | CQ10: =IF(CJ10<26000000,0,IF(CJ10<26500000,4,IF(CJ10<27000000,7,IF(CJ10<27500000,9,IF(CJ10<28000000,11,IF(CJ10<28500000,15,IF(CJ10<29000000,17,IF(CJ10<29500000,20,IF(CJ10<30000000,23,IF(CJ10<30500000,25,IF(CJ10<31000000,27,IF(CJ10<31500000,29,IF(CJ10<32000000,33,IF(CJ10<32500000,37,IF(CJ10<33000000,39,IF(CJ10<33500000,42,IF(CJ10<34000000,45,IF(CJ10<34500000,48,IF(CJ10<35000000,52,52))))))))))))))))))) -> 45 | CR10: =(CM10+CO10)/209 -> 10186.89 | CS10: 32000000 | CT10: =IFERROR(CS10/12,"") -> 2666666.7 | CU10: =IFERROR(CT10-CV10-CW10,"") -> 1837781.8 | CV10: =IFERROR(CT10*(CY10*1.5)/(209+(CY10*1.5)),"") -> 628884.83 | CW10: 200000 | CX10: 209 | CY10: 43 | CZ10: =SUM(CX10:CY10) -> 252 | DA10: =IFERROR((CU10/209)+(CW10-(9620*209*0.01))/209,"") -> 9653.9523 | DB10: =IFERROR((CU10+CW10)/209,"") -> 9750.1523 | DC10: 2023 | DG10: =B10 -> 180601
A11: =ROW()-2 -> 9 | B11: 190102 | C11: 김재완 | E11: 선임 | F11: 정규직 | G11: 테스터 | H11: 2실 | I11: 블루월넛 1팀 | J11: =+VLOOKUP($I11,[1]프로젝트현황!$I:$N,5,0) -> 서울시 | K11: =+VLOOKUP($I11,[1]프로젝트현황!$I:$N,6,0) -> 영등포구 | L11: 43467 | M11: 43467 | P11: Kim, Jae Wan | Q11: 920208-1238814 | R11: =LEFT(Q11,6) -> 920208 | S11: =MID($Q11,3,2) -> 02 | T11: =IF(OR(MID($Q11,8,1)="1",MID($Q11,8,1)="3"),"남자",IF(OR(MID($Q11,8,1)="2",MID($Q11,8,1)="4"),"여자","")) -> 남자 | U11: =YEAR(TODAY())-IF(OR(MID($Q11,8,1)="1",MID($Q11,8,1)="2"),19&LEFT($Q11,2),IF(OR(MID($Q11,8,1)="3",MID($Q11,8,1)="4"),20&LEFT($Q11,2),""))+1 -> 35 | V11: 양력 | W11: 한국 | X11: 010-9001-4697 | Z11: 무 | AB11: TBELL | AD11: =QUOTIENT(SUMPRODUCT(LEFT($AE11:$AF11,FIND("년",$AE11:$AF11)-1)*12+MID($AE11:$AF11,FIND("년",$AE11:$AF11)+1,FIND("개월",$AE11:$AF11)-FIND("년",$AE11:$AF11)-1)),12)&"년"&MOD(SUMPRODUCT(LEFT($AE11:$AF11,FIND("년",$AE11:$AF11)-1)*12+MID($AE11:$AF11,FIND("년",$AE11:$AF11)+1,FIND("개월",$AE11:$AF11)-FIND("년",$AE11:$AF11)-1)),12)&"개월" -> 8년4개월 | AE11: 1년3개월 | AF11: =DATEDIF($L11,TODAY(),"y")&"년"&DATEDIF($L11,TODAY(),"ym")&"개월" -> 7년1개월 | AG11: 청강문화산업대학교 | AH11: E스포츠게임과 | AI11: 전문학사 | AJ11: 42050 | AK11: =VALUE(LEFT($AD11,FIND("년",$AD11)-1)) -> 8 | AL11: =IF($AI11="전문학사",IF($AK11<=8,"초급",IF($AK11<12,"중급",IF($AK11<15,"고급",IF($AK11>=15,"특급"))))) -> 초급 | AM11: =IF(ISNUMBER(SEARCH("산업기사",$AT11)),IF($AK11>=13,"특급",IF($AK11>=10,"고급",IF($AK11>=7,"중급","초급"))),IF(ISNUMBER(SEARCH("기사",$AR11)),IF($AK11>=10,"특급",IF($AK11>=7,"고급",IF($AK11>=4,"중급","초급"))),"미해당")) -> 미해당 | AP11: ISTQB | AQ11: 2017.12 | AW11: ISTQB | AX11: 2017.12.05 | AY11: IT기획 및 품질관리 | AZ11: 테스팅 엔지니어 | BA11: 기업은행 | BB11: 001-623506-01-018 | BC11: 모 | BD11: 010-6322-4697 | BE11: jw.kim@tbell.co.kr | BF11: 경기도 | BG11: 부천시 | BH11: 원미구 | BI11: 부일로 232, 102동 2108호 (상동) | BJ11: =IFERROR(VLOOKUP($BG11,[1]프로젝트현황!Y:Z,2,0),"기타") -> 서남권 | BK11: =(IF(BF11="","",BF11&" "))&(IF(BG11="","",BG11&" "))&(IF(BH11="","",BH11&" "))&BI11 -> 경기도 부천시 원미구 부일로 232, 102동 2108호 (상동) | BL11: 30 | BM11: 30 | BN11: 36600000 | BO11: =BP11*12 -> 36600119 | BP11: =SUM(BQ11:BS11) -> 3050009.9 | BQ11: =ROUNDUP(BN11/12*209/(209+BU11*1.5)/BL11*BM11,-1)-BS11 -> 2021090 | BR11: =ROUNDUP(BN11/12*(BU11*1.5)/(209+BU11*1.5)/BL11*BM11,1) -> 828919.9 | BS11: 200000 | BT11: 209 | BU11: =IF($BN11="","", IFERROR( IF($BN11<'[1]시간외시간 기준표'!$B$2,0, IF($BN11>LOOKUP(9.9E+307,'[1]시간외시간 기준표'!$B$2:$B$999), LOOKUP(9.9E+307,'[1]시간외시간 기준표'!$C$2:$C$999), LOOKUP($BN11,'[1]시간외시간 기준표'!$B$2:$B$999,'[1]시간외시간 기준표'!$C$2:$C$999) ) ),0) ) -> 52 | BV11: =(BQ11+BS11)/209 -> 10627.225 | BW11: 30 | BX11: 30 | BY11: 36600000 | BZ11: =CA11*12 -> 36600119 | CA11: =SUM(CB11:CD11) -> 3050009.9 | CB11: =ROUNDUP(BY11/12*209/(209+CF11*1.5)/BW11*BX11,-1)-CD11 -> 2021090 | CC11: =ROUNDUP(BY11/12*(CF11*1.5)/(209+CF11*1.5)/BW11*BX11,1) -> 828919.9 | CD11: 200000 | CE11: 209 | CF11: =IF(BY11<26000000,0,IF(BY11<26500000,4,IF(BY11<27000000,7,IF(BY11<27500000,9,IF(BY11<28000000,11,IF(BY11<28500000,15,IF(BY11<29000000,17,IF(BY11<29500000,20,IF(BY11<30000000,23,IF(BY11<30500000,25,IF(BY11<31000000,27,IF(BY11<31500000,29,IF(BY11<32000000,33,IF(BY11<32500000,37,IF(BY11<33000000,39,IF(BY11<33500000,42,IF(BY11<34000000,45,IF(BY11<34500000,48,IF(BY11<35000000,52,52))))))))))))))))))) -> 52 | CG11: =(CB11+CD11)/209 -> 10627.225 | CH11: 30 | CI11: 30 | CJ11: 35800000 | CK11: =CL11*12 -> 35800097 | CL11: =SUM(CM11:CO11) -> 2983341.4 | CM11: =ROUNDUP(CJ11/12*209/(209+CQ11*1.5)/CH11*CI11,-1)-CO11 -> 1972540 | CN11: =ROUNDUP(CJ11/12*(CQ11*1.5)/(209+CQ11*1.5)/CH11*CI11,1) -> 810801.4 | CO11: 200000 | CP11: 209 | CQ11: =IF(CJ11<26000000,0,IF(CJ11<26500000,4,IF(CJ11<27000000,7,IF(CJ11<27500000,9,IF(CJ11<28000000,11,IF(CJ11<28500000,15,IF(CJ11<29000000,17,IF(CJ11<29500000,20,IF(CJ11<30000000,23,IF(CJ11<30500000,25,IF(CJ11<31000000,27,IF(CJ11<31500000,29,IF(CJ11<32000000,33,IF(CJ11<32500000,37,IF(CJ11<33000000,39,IF(CJ11<33500000,42,IF(CJ11<34000000,45,IF(CJ11<34500000,48,IF(CJ11<35000000,52,52))))))))))))))))))) -> 52 | CR11: =(CM11+CO11)/209 -> 10394.928 | CS11: 34000000 | CT11: =IFERROR(CS11/12,"") -> 2833333.3 | CU11: =IFERROR(CT11-CV11-CW11,"") -> 1863298.5 | CV11: =IFERROR(CT11*(CY11*1.5)/(209+(CY11*1.5)),"") -> 770034.84 | CW11: 200000 | CX11: 209 | CY11: 52 | CZ11: =SUM(CX11:CY11) -> 261 | DA11: =IFERROR((CU11/209)+(CW11-(9620*209*0.01))/209,"") -> 9776.0416 | DB11: =IFERROR((CU11+CW11)/209,"") -> 9872.2416 | DC11: 2023 | DG11: =B11 -> 190102
A12: =ROW()-2 -> 10 | B12: 190103 | C12: 이정훈 | E12: 선임 | F12: 정규직 | G12: 테스터 | H12: 1실 | I12: 웅진씽크빅 1팀 | J12: =+VLOOKUP($I12,[1]프로젝트현황!$I:$N,5,0) -> 서울시 | K12: =+VLOOKUP($I12,[1]프로젝트현황!$I:$N,6,0) -> 금천구 | L12: 43474 | M12: 43474 | Q12: 910629-1285511 | R12: =LEFT(Q12,6) -> 910629 | S12: =MID($Q12,3,2) -> 06 | T12: =IF(OR(MID($Q12,8,1)="1",MID($Q12,8,1)="3"),"남자",IF(OR(MID($Q12,8,1)="2",MID($Q12,8,1)="4"),"여자","")) -> 남자 | U12: =YEAR(TODAY())-IF(OR(MID($Q12,8,1)="1",MID($Q12,8,1)="2"),19&LEFT($Q12,2),IF(OR(MID($Q12,8,1)="3",MID($Q12,8,1)="4"),20&LEFT($Q12,2),""))+1 -> 36 | V12: 양력 | W12: 한국 | X12: 010-2082-2969 | Z12: 무 | AB12: TBELL | AD12: =QUOTIENT(SUMPRODUCT(LEFT($AE12:$AF12,FIND("년",$AE12:$AF12)-1)*12+MID($AE12:$AF12,FIND("년",$AE12:$AF12)+1,FIND("개월",$AE12:$AF12)-FIND("년",$AE12:$AF12)-1)),12)&"년"&MOD(SUMPRODUCT(LEFT($AE12:$AF12,FIND("년",$AE12:$AF12)-1)*12+MID($AE12:$AF12,FIND("년",$AE12:$AF12)+1,FIND("개월",$AE12:$AF12)-FIND("년",$AE12:$AF12)-1)),12)&"개월" -> 13년6개월 | AE12: 6년 5개월 | AF12: =DATEDIF($L12,TODAY(),"y")&"년"&DATEDIF($L12,TODAY(),"ym")&"개월" -> 7년1개월 | AG12: 태백기계공업고등학교 | AH12: 전자기계과 | AI12: 고졸 | AJ12: 40221 | AK12: =VALUE(LEFT($AD12,FIND("년",$AD12)-1)) -> 13 | AL12: =IF($AI12="고졸",IF($AK12<=11,"초급",IF($AK12<=14,"중급",IF($AK12<=17,"고급",IF($AK12>=18,"특급"))))) -> 중급 | AM12: =IF(ISNUMBER(SEARCH("산업기사",$AT12)),IF($AK12>=13,"특급",IF($AK12>=10,"고급",IF($AK12>=7,"중급","초급"))),IF(ISNUMBER(SEARCH("기사",$AR12)),IF($AK12>=10,"특급",IF($AK12>=7,"고급",IF($AK12>=4,"중급","초급"))),"미해당")) -> 미해당 | AP12: ISTQB | AQ12: 42206 | AW12: ISTQB | AX12: 2015.07.21 | AY12: IT기획 및 품질관리 | AZ12: 테스팅 엔지니어 | BA12: 기업은행 | BB12: 126-087492-01-017 | BC12: 제 | BD12: 010-4170-0045 | BE12: jh.lee2@tbell.co.kr | BF12: 서울시 | BG12: 관악구 | BI12: 행운2길 51 502호 | BJ12: =IFERROR(VLOOKUP($BG12,[1]프로젝트현황!Y:Z,2,0),"기타") -> 서남권 | BK12: =(IF(BF12="","",BF12&" "))&(IF(BG12="","",BG12&" "))&(IF(BH12="","",BH12&" "))&BI12 -> 서울시 관악구 행운2길 51 502호 | BL12: 30 | BM12: 30 | BN12: 38000000 | BO12: =BP12*12 -> 38000006 | BP12: =SUM(BQ12:BS12) -> 3166667.2 | BQ12: =ROUNDUP(BN12/12*209/(209+BU12*1.5)/BL12*BM12,-1)-BS12 -> 2106040 | BR12: =ROUNDUP(BN12/12*(BU12*1.5)/(209+BU12*1.5)/BL12*BM12,1) -> 860627.2 | BS12: 200000 | BT12: 209 | BU12: =IF($BN12="","", IFERROR( IF($BN12<'[1]시간외시간 기준표'!$B$2,0, IF($BN12>LOOKUP(9.9E+307,'[1]시간외시간 기준표'!$B$2:$B$999), LOOKUP(9.9E+307,'[1]시간외시간 기준표'!$C$2:$C$999), LOOKUP($BN12,'[1]시간외시간 기준표'!$B$2:$B$999,'[1]시간외시간 기준표'!$C$2:$C$999) ) ),0) ) -> 52 | BV12: =(BQ12+BS12)/209 -> 11033.684 | BW12: 30 | BX12: 30 | BY12: 38000000 | BZ12: =CA12*12 -> 38000006 | CA12: =SUM(CB12:CD12) -> 3166667.2 | CB12: =ROUNDUP(BY12/12*209/(209+CF12*1.5)/BW12*BX12,-1)-CD12 -> 2106040 | CC12: =ROUNDUP(BY12/12*(CF12*1.5)/(209+CF12*1.5)/BW12*BX12,1) -> 860627.2 | CD12: 200000 | CE12: 209 | CF12: =IF(BY12<26000000,0,IF(BY12<26500000,4,IF(BY12<27000000,7,IF(BY12<27500000,9,IF(BY12<28000000,11,IF(BY12<28500000,15,IF(BY12<29000000,17,IF(BY12<29500000,20,IF(BY12<30000000,23,IF(BY12<30500000,25,IF(BY12<31000000,27,IF(BY12<31500000,29,IF(BY12<32000000,33,IF(BY12<32500000,37,IF(BY12<33000000,39,IF(BY12<33500000,42,IF(BY12<34000000,45,IF(BY12<34500000,48,IF(BY12<35000000,52,52))))))))))))))))))) -> 52 | CG12: =(CB12+CD12)/209 -> 11033.684 | CH12: 30 | CI12: 30 | CJ12: 37200000 | CK12: =CL12*12 -> 37200106 | CL12: =SUM(CM12:CO12) -> 3100008.8 | CM12: =ROUNDUP(CJ12/12*209/(209+CQ12*1.5)/CH12*CI12,-1)-CO12 -> 2057500 | CN12: =ROUNDUP(CJ12/12*(CQ12*1.5)/(209+CQ12*1.5)/CH12*CI12,1) -> 842508.8 | CO12: 200000 | CP12: 209 | CQ12: =IF(CJ12<26000000,0,IF(CJ12<26500000,4,IF(CJ12<27000000,7,IF(CJ12<27500000,9,IF(CJ12<28000000,11,IF(CJ12<28500000,15,IF(CJ12<29000000,17,IF(CJ12<29500000,20,IF(CJ12<30000000,23,IF(CJ12<30500000,25,IF(CJ12<31000000,27,IF(CJ12<31500000,29,IF(CJ12<32000000,33,IF(CJ12<32500000,37,IF(CJ12<33000000,39,IF(CJ12<33500000,42,IF(CJ12<34000000,45,IF(CJ12<34500000,48,IF(CJ12<35000000,52,52))))))))))))))))))) -> 52 | CR12: =(CM12+CO12)/209 -> 10801.435 | CS12: 36000000 | CT12: =IFERROR(CS12/12,"") -> 3000000 | CU12: =IFERROR(CT12-CV12-CW12,"") -> 1984669 | CV12: =IFERROR(CT12*(CY12*1.5)/(209+(CY12*1.5)),"") -> 815331.01 | CW12: 200000 | CX12: 209 | CY12: 52 | CZ12: =SUM(CX12:CY12) -> 261 | DA12: =IFERROR((CU12/209)+(CW12-(9620*209*0.01))/209,"") -> 10356.762 | DB12: =IFERROR((CU12+CW12)/209,"") -> 10452.962 | DC12: 2023 | DG12: =B12 -> 190103
A13: =ROW()-2 -> 11 | B13: 190105 | C13: 김하정 | E13: 선임 | F13: 정규직 | G13: 테스터 | H13: 2실 | I13: 반티바 1팀 | J13: =+VLOOKUP($I13,[1]프로젝트현황!$I:$N,5,0) -> 경기도 | K13: =+VLOOKUP($I13,[1]프로젝트현황!$I:$N,6,0) -> 성남시 | L13: 43479 | M13: 43479 | P13: Kim, Ha Jung | Q13: 911113-2055428 | R13: =LEFT(Q13,6) -> 911113 | S13: =MID($Q13,3,2) -> 11 | T13: =IF(OR(MID($Q13,8,1)="1",MID($Q13,8,1)="3"),"남자",IF(OR(MID($Q13,8,1)="2",MID($Q13,8,1)="4"),"여자","")) -> 여자 | U13: =YEAR(TODAY())-IF(OR(MID($Q13,8,1)="1",MID($Q13,8,1)="2"),19&LEFT($Q13,2),IF(OR(MID($Q13,8,1)="3",MID($Q13,8,1)="4"),20&LEFT($Q13,2),""))+1 -> 36 | V13: 양력 | W13: 한국 | X13: 010-3794-9113 | AB13: TBELL | AD13: =QUOTIENT(SUMPRODUCT(LEFT($AE13:$AF13,FIND("년",$AE13:$AF13)-1)*12+MID($AE13:$AF13,FIND("년",$AE13:$AF13)+1,FIND("개월",$AE13:$AF13)-FIND("년",$AE13:$AF13)-1)),12)&"년"&MOD(SUMPRODUCT(LEFT($AE13:$AF13,FIND("년",$AE13:$AF13)-1)*12+MID($AE13:$AF13,FIND("년",$AE13:$AF13)+1,FIND("개월",$AE13:$AF13)-FIND("년",$AE13:$AF13)-1)),12)&"개월" -> 7년9개월 | AE13: 0년9개월 | AF13: =DATEDIF($L13,TODAY(),"y")&"년"&DATEDIF($L13,TODAY(),"ym")&"개월" -> 7년0개월 | AG13: 덕성여자대학교 | AH13: 컴퓨터학과 | AI13: 학사 | AJ13: 42787 | AK13: =VALUE(LEFT($AD13,FIND("년",$AD13)-1)) -> 7 | AL13: =IF($AI13="학사",IF($AK13<=5,"초급",IF($AK13<9,"중급",IF($AK13<12,"고급",IF($AK13>=12,"특급"))))) -> 중급 | AM13: =IF(ISNUMBER(SEARCH("산업기사",$AT13)),IF($AK13>=13,"특급",IF($AK13>=10,"고급",IF($AK13>=7,"중급","초급"))),IF(ISNUMBER(SEARCH("기사",$AR13)),IF($AK13>=10,"특급",IF($AK13>=7,"고급",IF($AK13>=4,"중급","초급"))),"미해당")) -> 미해당 | AV13: ICDL starter | AW13: ICDL Korea | AX13: 2012.11 | AY13: IT기획 및 품질관리 | AZ13: 테스팅 엔지니어 | BA13: 기업은행 | BB13: 589-024251-01-012 | BC13: 모 | BD13: 010-8872-1841 | BE13: hj.kim@tbell.co.kr | BF13: 서울시 | BG13: 서초구 | BI13: 청계산로9길 1-12, 601동 309호(신원동, 서초포레스타) | BJ13: =IFERROR(VLOOKUP($BG13,[1]프로젝트현황!Y:Z,2,0),"기타") -> 동남권 | BK13: =(IF(BF13="","",BF13&" "))&(IF(BG13="","",BG13&" "))&(IF(BH13="","",BH13&" "))&BI13 -> 서울시 서초구 청계산로9길 1-12, 601동 309호(신원동, 서초포레스타) | BL13: 30 | BM13: 30 | BN13: 30000000 | BO13: =BP13*12 -> 30000109 | BP13: =SUM(BQ13:BS13) -> 2500009.1 | BQ13: =ROUNDUP(BN13/12*209/(209+BU13*1.5)/BL13*BM13,-1)-BS13 -> 1959100 | BR13: =ROUNDUP(BN13/12*(BU13*1.5)/(209+BU13*1.5)/BL13*BM13,1) -> 340909.1 | BS13: 200000 | BT13: 209 | BU13: =IF($BN13="","", IFERROR( IF($BN13<'[1]시간외시간 기준표'!$B$2,0, IF($BN13>LOOKUP(9.9E+307,'[1]시간외시간 기준표'!$B$2:$B$999), LOOKUP(9.9E+307,'[1]시간외시간 기준표'!$C$2:$C$999), LOOKUP($BN13,'[1]시간외시간 기준표'!$B$2:$B$999,'[1]시간외시간 기준표'!$C$2:$C$999) ) ),0) ) -> 22 | BV13: =(BQ13+BS13)/209 -> 10330.622 | BW13: 30 | BX13: 30 | BY13: 30000000 | BZ13: =CA13*12 -> 30000055 | CA13: =SUM(CB13:CD13) -> 2500004.6 | CB13: =ROUNDUP(BY13/12*209/(209+CF13*1.5)/BW13*BX13,-1)-CD13 -> 1919680 | CC13: =ROUNDUP(BY13/12*(CF13*1.5)/(209+CF13*1.5)/BW13*BX13,1) -> 380324.6 | CD13: 200000 | CE13: 209 | CF13: =IF(BY13<26000000,0,IF(BY13<26500000,4,IF(BY13<27000000,7,IF(BY13<27500000,9,IF(BY13<28000000,11,IF(BY13<28500000,15,IF(BY13<29000000,17,IF(BY13<29500000,20,IF(BY13<30000000,23,IF(BY13<30500000,25,IF(BY13<31000000,27,IF(BY13<31500000,29,IF(BY13<32000000,33,IF(BY13<32500000,37,IF(BY13<33000000,39,IF(BY13<33500000,42,IF(BY13<34000000,45,IF(BY13<34500000,48,IF(BY13<35000000,52,52))))))))))))))))))) -> 25 | CG13: =(CB13+CD13)/209 -> 10142.01 | CH13: 30 | CI13: 30 | CJ13: 29200000 | CK13: =CL13*12 -> 29200073 | CL13: =SUM(CM13:CO13) -> 2433339.4 | CM13: =ROUNDUP(CJ13/12*209/(209+CQ13*1.5)/CH13*CI13,-1)-CO13 -> 1927900 | CN13: =ROUNDUP(CJ13/12*(CQ13*1.5)/(209+CQ13*1.5)/CH13*CI13,1) -> 305439.4 | CO13: 200000 | CP13: 209 | CQ13: =IF(CJ13<26000000,0,IF(CJ13<26500000,4,IF(CJ13<27000000,7,IF(CJ13<27500000,9,IF(CJ13<28000000,11,IF(CJ13<28500000,15,IF(CJ13<29000000,17,IF(CJ13<29500000,20,IF(CJ13<30000000,23,IF(CJ13<30500000,25,IF(CJ13<31000000,27,IF(CJ13<31500000,29,IF(CJ13<32000000,33,IF(CJ13<32500000,37,IF(CJ13<33000000,39,IF(CJ13<33500000,42,IF(CJ13<34000000,45,IF(CJ13<34500000,48,IF(CJ13<35000000,52,52))))))))))))))))))) -> 20 | CR13: =(CM13+CO13)/209 -> 10181.34 | CS13: 28000000 | CT13: =IFERROR(CS13/12,"") -> 2333333.3 | CU13: =IFERROR(CT13-CV13-CW13,"") -> 1840446.3 | CV13: =IFERROR(CT13*(CY13*1.5)/(209+(CY13*1.5)),"") -> 292887.03 | CW13: 200000 | CX13: 209 | CY13: 20 | CZ13: =SUM(CX13:CY13) -> 229 | DA13: =IFERROR((CU13/209)+(CW13-(9620*209*0.01))/209,"") -> 9666.701 | DB13: =IFERROR((CU13+CW13)/209,"") -> 9762.901 | DC13: 2023 | DG13: =B13 -> 190105
A14: =ROW()-2 -> 12 | B14: 190107 | C14: 김예림 | D14: 파트장 | E14: 선임 | F14: 정규직 | G14: 지원관리 | H14: 경영전략실 | I14: 경영지원팀 | J14: =+VLOOKUP($I14,[1]프로젝트현황!$I:$N,5,0) -> 서울시 | K14: =+VLOOKUP($I14,[1]프로젝트현황!$I:$N,6,0) -> 강남구 | L14: 43495 | M14: 43495 | P14: Kim, Ye Rim | Q14: 961116-2066116 | R14: =LEFT(Q14,6) -> 961116 | S14: =MID($Q14,3,2) -> 11 | T14: =IF(OR(MID($Q14,8,1)="1",MID($Q14,8,1)="3"),"남자",IF(OR(MID($Q14,8,1)="2",MID($Q14,8,1)="4"),"여자","")) -> 여자 | U14: =YEAR(TODAY())-IF(OR(MID($Q14,8,1)="1",MID($Q14,8,1)="2"),19&LEFT($Q14,2),IF(OR(MID($Q14,8,1)="3",MID($Q14,8,1)="4"),20&LEFT($Q14,2),""))+1 -> 31 | V14: 양력 | W14: 한국 | X14: 010-2356-9458 | AB14: TBELL | AD14: =QUOTIENT(SUMPRODUCT(LEFT($AE14:$AF14,FIND("년",$AE14:$AF14)-1)*12+MID($AE14:$AF14,FIND("년",$AE14:$AF14)+1,FIND("개월",$AE14:$AF14)-FIND("년",$AE14:$AF14)-1)),12)&"년"&MOD(SUMPRODUCT(LEFT($AE14:$AF14,FIND("년",$AE14:$AF14)-1)*12+MID($AE14:$AF14,FIND("년",$AE14:$AF14)+1,FIND("개월",$AE14:$AF14)-FIND("년",$AE14:$AF14)-1)),12)&"개월" -> 9년0개월 | AE14: 2년0개월 | AF14: =DATEDIF($L14,TODAY(),"y")&"년"&DATEDIF($L14,TODAY(),"ym")&"개월" -> 7년0개월 | AG14: 명지전문대학교 | AH14: 부동산경영과 | AI14: 전문학사 | AJ14: 43154 | AK14: =VALUE(LEFT($AD14,FIND("년",$AD14)-1)) -> 9 | AL14: =IF($AI14="전문학사",IF($AK14<=8,"초급",IF($AK14<12,"중급",IF($AK14<15,"고급",IF($AK14>=15,"특급"))))) -> 중급 | AM14: =IF(ISNUMBER(SEARCH("산업기사",$AT14)),IF($AK14>=13,"특급",IF($AK14>=10,"고급",IF($AK14>=7,"중급","초급"))),IF(ISNUMBER(SEARCH("기사",$AR14)),IF($AK14>=10,"특급",IF($AK14>=7,"고급",IF($AK14>=4,"중급","초급"))),"미해당")) -> 미해당 | AY14: 경영관리 | AZ14: 경영관리 | BA14: 기업은행 | BB14: 988-008943-01-017 | BC14: 모 | BD14: 010-8243-8002 | BE14: yr.kim@tbell.co.kr | BF14: 서울시 | BG14: 강서구 | BI14: 등촌동 641-12, 802호 | BJ14: =IFERROR(VLOOKUP($BG14,[1]프로젝트현황!Y:Z,2,0),"기타") -> 서남권 | BK14: =(IF(BF14="","",BF14&" "))&(IF(BG14="","",BG14&" "))&(IF(BH14="","",BH14&" "))&BI14 -> 서울시 강서구 등촌동 641-12, 802호 | BL14: 30 | BM14: 30 | BN14: 35200000 | BO14: =BP14*12 -> 35200055 | BP14: =SUM(BQ14:BS14) -> 2933337.9 | BQ14: =ROUNDUP(BN14/12*209/(209+BU14*1.5)/BL14*BM14,-1)-BS14 -> 1958690 | BR14: =ROUNDUP(BN14/12*(BU14*1.5)/(209+BU14*1.5)/BL14*BM14,1) -> 774647.9 | BS14: 200000 | BT14: 209 | BU14: =IF($BN14="","", IFERROR( IF($BN14<'[1]시간외시간 기준표'!$B$2,0, IF($BN14>LOOKUP(9.9E+307,'[1]시간외시간 기준표'!$B$2:$B$999), LOOKUP(9.9E+307,'[1]시간외시간 기준표'!$C$2:$C$999), LOOKUP($BN14,'[1]시간외시간 기준표'!$B$2:$B$999,'[1]시간외시간 기준표'!$C$2:$C$999) ) ),0) ) -> 50 | BV14: =(BQ14+BS14)/209 -> 10328.66 | BW14: 30 | BX14: 30 | BY14: 35200000 | BZ14: =CA14*12 -> 35200111 | CA14: =SUM(CB14:CD14) -> 2933342.6 | CB14: =ROUNDUP(BY14/12*209/(209+CF14*1.5)/BW14*BX14,-1)-CD14 -> 1936130 | CC14: =ROUNDUP(BY14/12*(CF14*1.5)/(209+CF14*1.5)/BW14*BX14,1) -> 797212.6 | CD14: 200000 | CE14: 209 | CF14: =IF(BY14<26000000,0,IF(BY14<26500000,4,IF(BY14<27000000,7,IF(BY14<27500000,9,IF(BY14<28000000,11,IF(BY14<28500000,15,IF(BY14<29000000,17,IF(BY14<29500000,20,IF(BY14<30000000,23,IF(BY14<30500000,25,IF(BY14<31000000,27,IF(BY14<31500000,29,IF(BY14<32000000,33,IF(BY14<32500000,37,IF(BY14<33000000,39,IF(BY14<33500000,42,IF(BY14<34000000,45,IF(BY14<34500000,48,IF(BY14<35000000,52,52))))))))))))))))))) -> 52 | CG14: =(CB14+CD14)/209 -> 10220.718 | CH14: 30 | CI14: 30 | CJ14: 35200000 | CK14: =CL14*12 -> 35200111 | CL14: =SUM(CM14:CO14) -> 2933342.6 | CM14: =ROUNDUP(CJ14/12*209/(209+CQ14*1.5)/CH14*CI14,-1)-CO14 -> 1936130 | CN14: =ROUNDUP(CJ14/12*(CQ14*1.5)/(209+CQ14*1.5)/CH14*CI14,1) -> 797212.6 | CO14: 200000 | CP14: 209 | CQ14: =IF(CJ14<26000000,0,IF(CJ14<26500000,4,IF(CJ14<27000000,7,IF(CJ14<27500000,9,IF(CJ14<28000000,11,IF(CJ14<28500000,15,IF(CJ14<29000000,17,IF(CJ14<29500000,20,IF(CJ14<30000000,23,IF(CJ14<30500000,25,IF(CJ14<31000000,27,IF(CJ14<31500000,29,IF(CJ14<32000000,33,IF(CJ14<32500000,37,IF(CJ14<33000000,39,IF(CJ14<33500000,42,IF(CJ14<34000000,45,IF(CJ14<34500000,48,IF(CJ14<35000000,52,52))))))))))))))))))) -> 52 | CR14: =(CM14+CO14)/209 -> 10220.718 | CS14: 34000000 | CT14: =IFERROR(CS14/12,"") -> 2833333.3 | CU14: =IFERROR(CT14-CV14-CW14,"") -> 1863298.5 | CV14: =IFERROR(CT14*(CY14*1.5)/(209+(CY14*1.5)),"") -> 770034.84 | CW14: 200000 | CX14: 209 | CY14: 52 | CZ14: =SUM(CX14:CY14) -> 261 | DA14: =IFERROR((CU14/209)+(CW14-(9620*209*0.01))/209,"") -> 9776.0416 | DB14: =IFERROR((CU14+CW14)/209,"") -> 9872.2416 | DC14: 2023 | DG14: =B14 -> 190107
A15: =ROW()-2 -> 13 | B15: 190301 | C15: 최현준 | E15: 책임 | F15: 정규직 | G15: 테스터 | H15: 3실 | I15: GS리테일 1팀 | J15: =+VLOOKUP($I15,[1]프로젝트현황!$I:$N,5,0) -> 서울시 | K15: =+VLOOKUP($I15,[1]프로젝트현황!$I:$N,6,0) -> 영등포구 | L15: 43529 | M15: 43529 | P15: Choi, Hyun Jun | Q15: 870110-1011923 | R15: =LEFT(Q15,6) -> 870110 | S15: =MID($Q15,3,2) -> 01 | T15: =IF(OR(MID($Q15,8,1)="1",MID($Q15,8,1)="3"),"남자",IF(OR(MID($Q15,8,1)="2",MID($Q15,8,1)="4"),"여자","")) -> 남자 | U15: =YEAR(TODAY())-IF(OR(MID($Q15,8,1)="1",MID($Q15,8,1)="2"),19&LEFT($Q15,2),IF(OR(MID($Q15,8,1)="3",MID($Q15,8,1)="4"),20&LEFT($Q15,2),""))+1 -> 40 | V15: 양력 | W15: 한국 | X15: 010-5491-0110 | AB15: TBELL | AD15: =QUOTIENT(SUMPRODUCT(LEFT($AE15:$AF15,FIND("년",$AE15:$AF15)-1)*12+MID($AE15:$AF15,FIND("년",$AE15:$AF15)+1,FIND("개월",$AE15:$AF15)-FIND("년",$AE15:$AF15)-1)),12)&"년"&MOD(SUMPRODUCT(LEFT($AE15:$AF15,FIND("년",$AE15:$AF15)-1)*12+MID($AE15:$AF15,FIND("년",$AE15:$AF15)+1,FIND("개월",$AE15:$AF15)-FIND("년",$AE15:$AF15)-1)),12)&"개월" -> 15년11개월 | AE15: 9년0개월 | AF15: =DATEDIF($L15,TODAY(),"y")&"년"&DATEDIF($L15,TODAY(),"ym")&"개월" -> 6년11개월 | AG15: 신구대학교 | AH15: 컴퓨터 멀티미디어과 | AI15: 전문학사 | AJ15: 40218 | AK15: =VALUE(LEFT($AD15,FIND("년",$AD15)-1)) -> 15 | AL15: =IF($AI15="전문학사",IF($AK15<=8,"초급",IF($AK15<12,"중급",IF($AK15<15,"고급",IF($AK15>=15,"특급"))))) -> 특급 | AM15: =IF(ISNUMBER(SEARCH("산업기사",$AT15)),IF($AK15>=13,"특급",IF($AK15>=10,"고급",IF($AK15>=7,"중급","초급"))),IF(ISNUMBER(SEARCH("기사",$AR15)),IF($AK15>=10,"특급",IF($AK15>=7,"고급",IF($AK15>=4,"중급","초급"))),"미해당")) -> 미해당 | AP15: ISTQB | AQ15: 42787 | AV15: 컴퓨활용능력3급 정보기기기능사 워드프로세스1급 | AW15: 대한상공회의소 한국산업인력공단 대한상공회의소 ISTQB | AX15: 2003.03 2004.03 2004.11 2017.11 | AY15: IT기획 및 품질관리 | AZ15: 테스팅 엔지니어 | BA15: 기업은행 | BB15: 131-088072-01-017 | BC15: 모 | BD15: 010-2320-8062 | BE15: hj.choi@tbell.co.kr | BF15: 서울시 | BG15: 구로구 | BI15: 고척로 49, 202동 1402호 (오류동 338, 동부골든아파트) | BJ15: =IFERROR(VLOOKUP($BG15,[1]프로젝트현황!Y:Z,2,0),"기타") -> 서남권 | BK15: =(IF(BF15="","",BF15&" "))&(IF(BG15="","",BG15&" "))&(IF(BH15="","",BH15&" "))&BI15 -> 서울시 구로구 고척로 49, 202동 1402호 (오류동 338, 동부골든아파트) | BL15: 30 | BM15: 30 | BN15: 35100000 | BO15: =BP15*12 -> 35100092 | BP15: =SUM(BQ15:BS15) -> 2925007.7 | BQ15: =ROUNDUP(BN15/12*209/(209+BU15*1.5)/BL15*BM15,-1)-BS15 -> 1963990 | BR15: =ROUNDUP(BN15/12*(BU15*1.5)/(209+BU15*1.5)/BL15*BM15,1) -> 761017.7 | BS15: 200000 | BT15: 209 | BU15: =IF($BN15="","", IFERROR( IF($BN15<'[1]시간외시간 기준표'!$B$2,0, IF($BN15>LOOKUP(9.9E+307,'[1]시간외시간 기준표'!$B$2:$B$999), LOOKUP(9.9E+307,'[1]시간외시간 기준표'!$C$2:$C$999), LOOKUP($BN15,'[1]시간외시간 기준표'!$B$2:$B$999,'[1]시간외시간 기준표'!$C$2:$C$999) ) ),0) ) -> 49 | BV15: =(BQ15+BS15)/209 -> 10354.019 | BW15: 30 | BX15: 30 | BY15: 35100000 | BZ15: =CA15*12 -> 35100094 | CA15: =SUM(CB15:CD15) -> 2925007.8 | CB15: =ROUNDUP(BY15/12*209/(209+CF15*1.5)/BW15*BX15,-1)-CD15 -> 1930060 | CC15: =ROUNDUP(BY15/12*(CF15*1.5)/(209+CF15*1.5)/BW15*BX15,1) -> 794947.8 | CD15: 200000 | CE15: 209 | CF15: =IF(BY15<26000000,0,IF(BY15<26500000,4,IF(BY15<27000000,7,IF(BY15<27500000,9,IF(BY15<28000000,11,IF(BY15<28500000,15,IF(BY15<29000000,17,IF(BY15<29500000,20,IF(BY15<30000000,23,IF(BY15<30500000,25,IF(BY15<31000000,27,IF(BY15<31500000,29,IF(BY15<32000000,33,IF(BY15<32500000,37,IF(BY15<33000000,39,IF(BY15<33500000,42,IF(BY15<34000000,45,IF(BY15<34500000,48,IF(BY15<35000000,52,52))))))))))))))))))) -> 52 | CG15: =(CB15+CD15)/209 -> 10191.675 | CH15: 30 | CI15: 30 | CJ15: 35100000 | CK15: =CL15*12 -> 35100094 | CL15: =SUM(CM15:CO15) -> 2925007.8 | CM15: =ROUNDUP(CJ15/12*209/(209+CQ15*1.5)/CH15*CI15,-1)-CO15 -> 1930060 | CN15: =ROUNDUP(CJ15/12*(CQ15*1.5)/(209+CQ15*1.5)/CH15*CI15,1) -> 794947.8 | CO15: 200000 | CP15: 209 | CQ15: =IF(CJ15<26000000,0,IF(CJ15<26500000,4,IF(CJ15<27000000,7,IF(CJ15<27500000,9,IF(CJ15<28000000,11,IF(CJ15<28500000,15,IF(CJ15<29000000,17,IF(CJ15<29500000,20,IF(CJ15<30000000,23,IF(CJ15<30500000,25,IF(CJ15<31000000,27,IF(CJ15<31500000,29,IF(CJ15<32000000,33,IF(CJ15<32500000,37,IF(CJ15<33000000,39,IF(CJ15<33500000,42,IF(CJ15<34000000,45,IF(CJ15<34500000,48,IF(CJ15<35000000,52,52))))))))))))))))))) -> 52 | CR15: =(CM15+CO15)/209 -> 10191.675 | CS15: 34500000 | CT15: =IFERROR(CS15/12,"") -> 2875000 | CU15: =IFERROR(CT15-CV15-CW15,"") -> 1893641.1 | CV15: =IFERROR(CT15*(CY15*1.5)/(209+(CY15*1.5)),"") -> 781358.89 | CW15: 200000 | CX15: 209 | CY15: 52 | CZ15: =SUM(CX15:CY15) -> 261 | DA15: =IFERROR((CU15/209)+(CW15-(9620*209*0.01))/209,"") -> 9921.2216 | DB15: =IFERROR((CU15+CW15)/209,"") -> 10017.422 | DC15: 2023 | DG15: =B15 -> 190301
