Workbook
Name 범위: '[2]1-1. 개인별 급여분석'!$B$5:$R$43
Name 성명: '[2]1-1. 개인별 급여분석'!$B$5:$B$39
Name 포함단어시작셀: #REF!

Sheet 인사기본정보
B1: 1 | C1: 2 | D1: 11 | E1: 12 | F1: 13 | G1: 14 | H1: 15 | I1: 16 | J1: 17 | K1: 18 | L1: 19 | M1: 20 | N1: 21 | O1: 22 | P1: 23 | Q1: 24 | R1: 25 | S1: 26 | T1: 27 | U1: 28 | V1: 29 | W1: 30 | X1: 31 | Y1: 32 | Z1: 33 | AA1: 34 | AB1: 35 | AC1: 36 | AD1: 37 | AE1: 38 | AF1: 39 | AG1: 40 | AH1: 41 | AI1: 42 | AJ1: 43 | AK1: 44 | AL1: 45 | AM1: 46 | AN1: 47 | AO1: 48 | AP1: 49 | AQ1: 50 | AR1: 51 | AS1: 52 | AT1: 53 | AU1: 54 | AV1: 55 | AW1: 56 | AX1: 57 | AY1: 58 | AZ1: 59 | BA1: 60 | BB1: 61 | BC1: 62
A2: 순번 | B2: 사번 | C2: 성명 | D2: 최초입사일 | E2: 정규전환일 | F2: 적치적용일 | G2: 퇴직일자 | H2: 영문명 | I2: 주민번호 | J2: 생년월일 | K2: 생일월 | L2: 성별 | M2: 나이 | N2: 양력/음력 | O2: 국적 | P2: 전화번호 | Q2: 재직구분 | R2: 결혼유무 | S2: 결혼기념일 | T2: 법인 | U2: 한자명 | V2: 총업무경력 | W2: 전SW경력 | X2: 재직기간 | Y2: 최종학교 | Z2: 전공 | AA2: 최종학력 | AB2: 졸업일 | AC2: 지우면안돼 | AD2: 등급(경력+학력) | AE2: 등급(자격증) | AF2: CSTS | AG2: 취득일 | AH2: ISTQB | AI2: 취득일2 | AJ2: 정보처리기사 | AK2: 취득일3 | AL2: 정보처리산업기사 | AM2: 취득일4 | AN2: 기타 | AO2: 발행기관 | AP2: 취득년월 | AQ2: 분야 | AR2: 직무2 | AS2: 은행 | AT2: 계좌번호 | AU2: 본인과의 관계 | AV2: 비상연락처 | AW2: 그룹웨어 이메일 | AX2: 주요시도 | AY2: 자치시구 | AZ2: 상세주소 | BA2: 상세주소3 | BB2: 거주지역 | BC2: 상세주소4
A3: =ROW()-2 -> 1 | B3: 150501 | C3: 김종균 | D3: 42142 | E3: 42142 | I3: 831124-1113419 | J3: =LEFT(I3,6) -> 831124 | K3: =MID($I3,3,2) -> 11 | L3: =IF(OR(MID($I3,8,1)="1",MID($I3,8,1)="3"),"남자",IF(OR(MID($I3,8,1)="2",MID($I3,8,1)="4"),"여자","")) -> 남자 | M3: =YEAR(TODAY())-IF(OR(MID($I3,8,1)="1",MID($I3,8,1)="2"),19&LEFT($I3,2),IF(OR(MID($I3,8,1)="3",MID($I3,8,1)="4"),20&LEFT($I3,2),""))+1 -> 44 | N3: 양력 | O3: 한국 | P3: 010-5749-8009 | T3: TBELL | V3: {=QUOTIENT(SUMPRODUCT(LEFT($W3:$X3,FIND("년",$W3:$X3)-1)*12+MID($W3:$X3,FIND("년",$W3:$X3)+1,FIND("개월",$W3:$X3)-FIND("년",$W3:$X3)-1)),12)&"년"&MOD(SUMPRODUCT(LEFT($W3:$X3,FIND("년",$W3:$X3)-1)*12+MID($W3:$X3,FIND("년",$W3:$X3)+1,FIND("개월",$W3:$X3)-FIND("년",$W3:$X3)-1)),12)&"개월"} -> 10년8개월 | W3: 0년0개월 | X3: =DATEDIF($D3,TODAY(),"y")&"년"&DATEDIF($D3,TODAY(),"ym")&"개월" -> 10년8개월 | AA3: 전문학사 | AC3: =VALUE(LEFT($V3,FIND("년",$V3)-1)) -> 10 | AD3: 특급 | AE3: =IF(ISNUMBER(SEARCH("산업기사",$AL3)),IF($AC3>=13,"특급",IF($AC3>=10,"고급",IF($AC3>=7,"중급","초급"))),IF(ISNUMBER(SEARCH("기사",$AJ3)),IF($AC3>=10,"특급",IF($AC3>=7,"고급",IF($AC3>=4,"중급","초급"))),"미해당")) -> 미해당 | AQ3: 정보기술컨설팅 | AU3: 처 | AV3: 010-5749-8009 | AW3: jg.kim@tbell.co.kr | AX3: 서울시 | AY3: 서대문구 | BA3: 세무서8길 30 홍제역 효성해링턴플레이스 113동 1802호 | BB3: =IFERROR(VLOOKUP($AY3,[1]프로젝트현황!Y:Z,2,0),"기타") -> 서북권 | BC3: =(IF(AX3="","",AX3&" "))&(IF(AY3="","",AY3&" "))&(IF(AZ3="","",AZ3&" "))&BA3 -> 서울시 서대문구 세무서8길 30 홍제역 효성해링턴플레이스 113동 1802호
A4: =ROW()-2 -> 2 | B4: 151201 | C4: 강현규 | D4: 42345 | E4: 42345 | F4: 43220 | H4: KANG, HyeonKyu | I4: 821030-1012027 | J4: =LEFT(I4,6) -> 821030 | K4: =MID($I4,3,2) -> 10 | L4: =IF(OR(MID($I4,8,1)="1",MID($I4,8,1)="3"),"남자",IF(OR(MID($I4,8,1)="2",MID($I4,8,1)="4"),"여자","")) -> 남자 | M4: =YEAR(TODAY())-IF(OR(MID($I4,8,1)="1",MID($I4,8,1)="2"),19&LEFT($I4,2),IF(OR(MID($I4,8,1)="3",MID($I4,8,1)="4"),20&LEFT($I4,2),""))+1 -> 45 | N4: 양력 | O4: 한국 | P4: 010-6388-7664 | R4: 유 | S4: 45267 | T4: TBELL | V4: =QUOTIENT(SUMPRODUCT(LEFT($W4:$X4,FIND("년",$W4:$X4)-1)*12+MID($W4:$X4,FIND("년",$W4:$X4)+1,FIND("개월",$W4:$X4)-FIND("년",$W4:$X4)-1)),12)&"년"&MOD(SUMPRODUCT(LEFT($W4:$X4,FIND("년",$W4:$X4)-1)*12+MID($W4:$X4,FIND("년",$W4:$X4)+1,FIND("개월",$W4:$X4)-FIND("년",$W4:$X4)-1)),12)&"개월" -> 21년0개월 | W4: 10년 10개월 | X4: =DATEDIF($D4,TODAY(),"y")&"년"&DATEDIF($D4,TODAY(),"ym")&"개월" -> 10년2개월 | Y4: 동국대학교전산원 | Z4: 멀티미디어 | AA4: 전문학사 | AB4: 37672 | AC4: =VALUE(LEFT($V4,FIND("년",$V4)-1)) -> 21 | AD4: =IF($AA4="전문학사",IF($AC4<=8,"초급",IF($AC4<12,"중급",IF($AC4<15,"고급",IF($AC4>=15,"특급"))))) -> 특급 | AE4: =IF(ISNUMBER(SEARCH("산업기사",$AL4)),IF($AC4>=13,"특급",IF($AC4>=10,"고급",IF($AC4>=7,"중급","초급"))),IF(ISNUMBER(SEARCH("기사",$AJ4)),IF($AC4>=10,"특급",IF($AC4>=7,"고급",IF($AC4>=4,"중급","초급"))),"미해당")) -> 미해당 | AH4: ISTQB | AI4: 2017.03 | AN4: 컴퓨터활용능력 워드프로세서 | AO4: ISTQB | AP4: 2017.03 | AQ4: 아키텍처 | AR4: 경영지원 | AS4: 기업은행 | AT4: 122-068082-01-018 | AU4: 처 | AV4: 010-9126-0218 | AW4: hk.kang@tbell.co.kr | AX4: 경기도 | AY4: 고양시 | AZ4: 덕양구 | BA4: 덕양구 성신로99, 1909 1501호(행신동, 햇빛마을 19단지 공무원 아파트) | BB4: =IFERROR(VLOOKUP($AY4,[1]프로젝트현황!Y:Z,2,0),"기타") -> 서북권 | BC4: =(IF(AX4="","",AX4&" "))&(IF(AY4="","",AY4&" "))&(IF(AZ4="","",AZ4&" "))&BA4 -> 경기도 고양시 덕양구 덕양구 성신로99, 1909 1501호(행신동, 햇빛마을 19단지 공무원 아파트)
A5: =ROW()-2 -> 3 | B5: 170702 | C5: 강성희 | D5: 42926 | E5: 42926 | I5: 830509-2065313 | J5: =LEFT(I5,6) -> 830509 | K5: =MID($I5,3,2) -> 05 | L5: =IF(OR(MID($I5,8,1)="1",MID($I5,8,1)="3"),"남자",IF(OR(MID($I5,8,1)="2",MID($I5,8,1)="4"),"여자","")) -> 여자 | M5: =YEAR(TODAY())-IF(OR(MID($I5,8,1)="1",MID($I5,8,1)="2"),19&LEFT($I5,2),IF(OR(MID($I5,8,1)="3",MID($I5,8,1)="4"),20&LEFT($I5,2),""))+1 -> 44 | N5: 양력 | O5: 한국 | P5: 010-9589-5859 | T5: TBELL | V5: =QUOTIENT(SUMPRODUCT(LEFT($W5:$X5,FIND("년",$W5:$X5)-1)*12+MID($W5:$X5,FIND("년",$W5:$X5)+1,FIND("개월",$W5:$X5)-FIND("년",$W5:$X5)-1)),12)&"년"&MOD(SUMPRODUCT(LEFT($W5:$X5,FIND("년",$W5:$X5)-1)*12+MID($W5:$X5,FIND("년",$W5:$X5)+1,FIND("개월",$W5:$X5)-FIND("년",$W5:$X5)-1)),12)&"개월" -> 13년4개월 | W5: 4년 9개월 | X5: =DATEDIF($D5,TODAY(),"y")&"년"&DATEDIF($D5,TODAY(),"ym")&"개월" -> 8년7개월 | Y5: 동원대학교 | Z5: 교육서비스문헌정보과 | AA5: 전문학사 | AB5: 38765 | AC5: =VALUE(LEFT($V5,FIND("년",$V5)-1)) -> 13 | AD5: =IF($ZE3="전문학사",IF($AC5<=8,"초급",IF($AC5<12,"중급",IF($AC5<15,"고급",IF($AC5>=15,"특급"))))) -> FALSE | AE5: =IF(ISNUMBER(SEARCH("산업기사",$AL5)),IF($AC5>=13,"특급",IF($AC5>=10,"고급",IF($AC5>=7,"중급","초급"))),IF(ISNUMBER(SEARCH("기사",$AJ5)),IF($AC5>=10,"특급",IF($AC5>=7,"고급",IF($AC5>=4,"중급","초급"))),"미해당")) -> 미해당 | AN5: 워드프로세스 2급 컴퓨터활용능력 3급 | AO5: 대한상공회의소 대한상공회의소 | AP5: 1999.11 2001.06 | AQ5: IT기획 및 품질관리 | AR5: 테스팅 엔지니어 | AS5: 기업은행 | AT5: 248-009498-01-029 | AU5: 모 | AV5: 010-2588-0245 | AW5: sh.kang@tbell.co.kr | AX5: 서울시 | AY5: 금천구 | BA5: 시흥대로94길 33-4 3층 (독산동 1058-20) | BB5: =IFERROR(VLOOKUP($AY5,[1]프로젝트현황!Y:Z,2,0),"기타") -> 서남권 | BC5: =(IF(AX5="","",AX5&" "))&(IF(AY5="","",AY5&" "))&(IF(AZ5="","",AZ5&" "))&AZE3 -> 서울시 금천구
A6: =ROW()-2 -> 4 | B6: 170801 | C6: 서동한 | D6: 42948 | E6: 42948 | H6: Seo, Dang Han | I6: 890218-1054222 | J6: =LEFT(I6,6) -> 890218 | K6: 3 | L6: =IF(OR(MID($I6,8,1)="1",MID($I6,8,1)="3"),"남자",IF(OR(MID($I6,8,1)="2",MID($I6,8,1)="4"),"여자","")) -> 남자 | M6: =YEAR(TODAY())-IF(OR(MID($I6,8,1)="1",MID($I6,8,1)="2"),19&LEFT($I6,2),IF(OR(MID($I6,8,1)="3",MID($I6,8,1)="4"),20&LEFT($I6,2),""))+1 -> 38 | N6: 음력 | O6: 한국 | P6: 010-4101-4909 | R6: 무 | T6: TBELL | V6: =QUOTIENT(SUMPRODUCT(LEFT($W6:$X6,FIND("년",$W6:$X6)-1)*12+MID($W6:$X6,FIND("년",$W6:$X6)+1,FIND("개월",$W6:$X6)-FIND("년",$W6:$X6)-1)),12)&"년"&MOD(SUMPRODUCT(LEFT($W6:$X6,FIND("년",$W6:$X6)-1)*12+MID($W6:$X6,FIND("년",$W6:$X6)+1,FIND("개월",$W6:$X6)-FIND("년",$W6:$X6)-1)),12)&"개월" -> 8년8개월 | W6: 0년2개월 | X6: =DATEDIF($D6,TODAY(),"y")&"년"&DATEDIF($D6,TODAY(),"ym")&"개월" -> 8년6개월 | Y6: 한신대학교 | Z6: 정보통신학 | AA6: 학사 | AB6: 41684 | AC6: =VALUE(LEFT($V6,FIND("년",$V6)-1)) -> 8 | AD6: =IF($AA6="학사",IF($AC6<=5,"초급",IF($AC6<9,"중급",IF($AC6<12,"고급",IF($AC6>=12,"특급"))))) -> 중급 | AE6: =IF(ISNUMBER(SEARCH("산업기사",$AL6)),IF($AC6>=13,"특급",IF($AC6>=10,"고급",IF($AC6>=7,"중급","초급"))),IF(ISNUMBER(SEARCH("기사",$AJ6)),IF($AC6>=10,"특급",IF($AC6>=7,"고급",IF($AC6>=4,"중급","초급"))),"미해당")) -> 미해당 | AN6: 네트워크관리사 2급 자동차운전면허 1종 보통 | AO6: 한국정보통신자격협회 경기지방경찰청 | AP6: 2012.12.11 2012.02.14 | AQ6: IT기획 및 품질관리 | AR6: 테스팅 엔지니어 | AS6: 기업은행 | AT6: 326-119130-01-010 | AU6: 부 | AV6: 010-5287-1237 | AW6: dh.seo@tbell.co.kr | AX6: 경기도 | AY6: 안산시 | AZ6: 단원구 | BA6: 단원구 광덕3로 241, 4층 (고잔동 760-2) | BB6: =IFERROR(VLOOKUP($AY6,[1]프로젝트현황!Y:Z,2,0),"기타") -> 서남권 | BC6: =(IF(AX6="","",AX6&" "))&(IF(AY6="","",AY6&" "))&(IF(AZ6="","",AZ6&" "))&BA6 -> 경기도 안산시 단원구 단원구 광덕3로 241, 4층 (고잔동 760-2)
A7: =ROW()-2 -> 5 | B7: 170803 | C7: 조현균 | D7: 42948 | E7: 42948 | H7: Cho, Hyun Gyun | I7: 860429-1382113 | J7: =LEFT(I7,6) -> 860429 | K7: =MID($I7,3,2) -> 04 | L7: =IF(OR(MID($I7,8,1)="1",MID($I7,8,1)="3"),"남자",IF(OR(MID($I7,8,1)="2",MID($I7,8,1)="4"),"여자","")) -> 남자 | M7: =YEAR(TODAY())-IF(OR(MID($I7,8,1)="1",MID($I7,8,1)="2"),19&LEFT($I7,2),IF(OR(MID($I7,8,1)="3",MID($I7,8,1)="4"),20&LEFT($I7,2),""))+1 -> 41 | N7: 양력 | O7: 한국 | P7: 010-8903-8016 | T7: TBELL | V7: =QUOTIENT(SUMPRODUCT(LEFT($W7:$X7,FIND("년",$W7:$X7)-1)*12+MID($W7:$X7,FIND("년",$W7:$X7)+1,FIND("개월",$W7:$X7)-FIND("년",$W7:$X7)-1)),12)&"년"&MOD(SUMPRODUCT(LEFT($W7:$X7,FIND("년",$W7:$X7)-1)*12+MID($W7:$X7,FIND("년",$W7:$X7)+1,FIND("개월",$W7:$X7)-FIND("년",$W7:$X7)-1)),12)&"개월" -> 16년11개월 | W7: 8년 5개월 | X7: =DATEDIF($D7,TODAY(),"y")&"년"&DATEDIF($D7,TODAY(),"ym")&"개월" -> 8년6개월 | Y7: 두원공과대 | Z7: 정보통신미디어계열 | AA7: 전문학사 | AB7: 39492 | AC7: =VALUE(LEFT($V7,FIND("년",$V7)-1)) -> 16 | AD7: =IF($AA7="전문학사",IF($AC7<=8,"초급",IF($AC7<12,"중급",IF($AC7<15,"고급",IF($AC7>=15,"특급"))))) -> 특급 | AE7: =IF(ISNUMBER(SEARCH("산업기사",$AL7)),IF($AC7>=13,"특급",IF($AC7>=10,"고급",IF($AC7>=7,"중급","초급"))),IF(ISNUMBER(SEARCH("기사",$AJ7)),IF($AC7>=10,"특급",IF($AC7>=7,"고급",IF($AC7>=4,"중급","초급"))),"미해당")) -> 미해당 | AF7: CSTS | AG7: 44794 | AH7: ISTQB | AI7: 44035 | AO7: KSTQB 한국정보통신기술협회 | AP7: 2020.07 2021.09.03 | AQ7: IT기획 및 품질관리 | AR7: 테스팅 엔지니어 | AS7: 기업은행 | AT7: 607-022578-01-018 | AU7: 모 | AV7: 010-4931-8016 | AW7: hg.cho@tbell.co.kr | AX7: 경기도 | AY7: 수원시 | AZ7: 팔달구 | BA7: 경수대로 534, 102동 401호 (인계동 945, 인계극동스타클래스) | BB7: =IFERROR(VLOOKUP($AY7,[1]프로젝트현황!Y:Z,2,0),"기타") -> 동남권 | BC7: =(IF(AX7="","",AX7&" "))&(IF(AY7="","",AY7&" "))&(IF(AZ7="","",AZ7&" "))&BA7 -> 경기도 수원시 팔달구 경수대로 534, 102동 401호 (인계동 945, 인계극동스타클래스)
A8: =ROW()-2 -> 6 | B8: 170904 | C8: 조소영 | D8: 42982 | E8: 42982 | H8: Jo, So Young | I8: 900424-2163820 | J8: =LEFT(I8,6) -> 900424 | K8: =MID($I8,3,2) -> 04 | L8: =IF(OR(MID($I8,8,1)="1",MID($I8,8,1)="3"),"남자",IF(OR(MID($I8,8,1)="2",MID($I8,8,1)="4"),"여자","")) -> 여자 | M8: =YEAR(TODAY())-IF(OR(MID($I8,8,1)="1",MID($I8,8,1)="2"),19&LEFT($I8,2),IF(OR(MID($I8,8,1)="3",MID($I8,8,1)="4"),20&LEFT($I8,2),""))+1 -> 37 | N8: 양력 | O8: 한국 | P8: 010-9189-7381 | R8: 무 | T8: TBELL | V8: =QUOTIENT(SUMPRODUCT(LEFT($W8:$X8,FIND("년",$W8:$X8)-1)*12+MID($W8:$X8,FIND("년",$W8:$X8)+1,FIND("개월",$W8:$X8)-FIND("년",$W8:$X8)-1)),12)&"년"&MOD(SUMPRODUCT(LEFT($W8:$X8,FIND("년",$W8:$X8)-1)*12+MID($W8:$X8,FIND("년",$W8:$X8)+1,FIND("개월",$W8:$X8)-FIND("년",$W8:$X8)-1)),12)&"개월" -> 13년1개월 | W8: 4년 8개월 | X8: =DATEDIF($D8,TODAY(),"y")&"년"&DATEDIF($D8,TODAY(),"ym")&"개월" -> 8년5개월 | Y8: 용인송담대학교 | Z8: 멀티미디어영상과 | AA8: 전문학사 | AB8: 40585 | AC8: =VALUE(LEFT($V8,FIND("년",$V8)-1)) -> 13 | AD8: =IF($AA8="전문학사",IF($AC8<=8,"초급",IF($AC8<12,"중급",IF($AC8<15,"고급",IF($AC8>=15,"특급"))))) -> 고급 | AE8: =IF(ISNUMBER(SEARCH("산업기사",$AL8)),IF($AC8>=13,"특급",IF($AC8>=10,"고급",IF($AC8>=7,"중급","초급"))),IF(ISNUMBER(SEARCH("기사",$AJ8)),IF($AC8>=10,"특급",IF($AC8>=7,"고급",IF($AC8>=4,"중급","초급"))),"미해당")) -> 미해당 | AN8: 워드프로세스 MOS Excel 2003 MOS Powerpoint 2003 | AO8: 대한상공회의소 MS MS | AP8: 2001.12.26 2010.09.17 2010.10.01 | AQ8: IT기획 및 품질관리 | AR8: 테스팅 엔지니어 | AS8: 기업은행 | AT8: 065-135562-01-013 | AU8: 모 | AV8: 010-5039-9118 | AW8: sy.jo@tbell.co.kr | AX8: 경기도 | AY8: 수원시 | AZ8: 권선구 | BA8: 경수대로 302번길 29, 4동 501호 (권선제2동 1185-1, 권선삼성아파트) | BB8: =IFERROR(VLOOKUP($AY8,[1]프로젝트현황!Y:Z,2,0),"기타") -> 동남권 | BC8: =(IF(AX8="","",AX8&" "))&(IF(AY8="","",AY8&" "))&(IF(AZ8="","",AZ8&" "))&BA8 -> 경기도 수원시 권선구 경수대로 302번길 29, 4동 501호 (권선제2동 1185-1, 권선삼성아파트)
A9: =ROW()-2 -> 7 | B9: 180501 | C9: 정성우 | D9: 43244 | E9: 43244 | H9: Jung, Sung Woo | I9: 810306-1167610 | J9: =LEFT(I9,6) -> 810306 | K9: =MID($I9,3,2) -> 03 | L9: =IF(OR(MID($I9,8,1)="1",MID($I9,8,1)="3"),"남자",IF(OR(MID($I9,8,1)="2",MID($I9,8,1)="4"),"여자","")) -> 남자 | M9: =YEAR(TODAY())-IF(OR(MID($I9,8,1)="1",MID($I9,8,1)="2"),19&LEFT($I9,2),IF(OR(MID($I9,8,1)="3",MID($I9,8,1)="4"),20&LEFT($I9,2),""))+1 -> 46 | N9: 양력 | O9: 한국 | P9: 010-5547-9612 | T9: TBELL | V9: =QUOTIENT(SUMPRODUCT(LEFT($W9:$X9,FIND("년",$W9:$X9)-1)*12+MID($W9:$X9,FIND("년",$W9:$X9)+1,FIND("개월",$W9:$X9)-FIND("년",$W9:$X9)-1)),12)&"년"&MOD(SUMPRODUCT(LEFT($W9:$X9,FIND("년",$W9:$X9)-1)*12+MID($W9:$X9,FIND("년",$W9:$X9)+1,FIND("개월",$W9:$X9)-FIND("년",$W9:$X9)-1)),12)&"개월" -> 17년6개월 | W9: 9년 10개월 | X9: =DATEDIF($D9,TODAY(),"y")&"년"&DATEDIF($D9,TODAY(),"ym")&"개월" -> 7년8개월 | Y9: 용인송담대학교 | Z9: 정보통신과 | AA9: 전문학사 | AB9: 38401 | AC9: =VALUE(LEFT($V9,FIND("년",$V9)-1)) -> 17 | AD9: =IF($AA9="전문학사",IF($AC9<=8,"초급",IF($AC9<12,"중급",IF($AC9<15,"고급",IF($AC9>=15,"특급"))))) -> 특급 | AE9: =IF(ISNUMBER(SEARCH("산업기사",$AL9)),IF($AC9>=13,"특급",IF($AC9>=10,"고급",IF($AC9>=7,"중급","초급"))),IF(ISNUMBER(SEARCH("기사",$AJ9)),IF($AC9>=10,"특급",IF($AC9>=7,"고급",IF($AC9>=4,"중급","초급"))),"미해당")) -> 미해당 | AN9: 정보기기운용기능사 정보처리기능사 무선통신기능사 워드프로세서 1급 교원자격증(실기교사-통신) 新JLPT N2 | AO9: 한국산업인력공단 한국산업인력공단 한국산업인력공단 대한상공회의소 교원인적자원부 국제교류기금 | AP9: 1999.04 1999.06 1999.07 1999.11 2005.02 2017.08 | AQ9: IT기획 및 품질관리 | AR9: 테스팅 엔지니어 | AS9: 기업은행 | AT9: 013-125229-01-010 | AU9: 모 | AV9: 010-9382-9612 | AW9: sw.jung@tbell.co.kr | AX9: 경기도 | AY9: 성남시 | AZ9: 수정구 | BA9: 수정로 251번길 22 신원빌리지 102동 302호 | BB9: =IFERROR(VLOOKUP($AY9,[1]프로젝트현황!Y:Z,2,0),"기타") -> 동남권 | BC9: =(IF(AX9="","",AX9&" "))&(IF(AY9="","",AY9&" "))&(IF(AZ9="","",AZ9&" "))&BA9 -> 경기도 성남시 수정구 수정로 251번길 22 신원빌리지 102동 302호
A10: =ROW()-2 -> 8 | B10: 180601 | C10: 전광희 | D10: 43262 | E10: 43262 | H10: Jeon, Gwang Hee | I10: 920409-1187228 | J10: =LEFT(I10,6) -> 920409 | K10: =MID($I10,3,2) -> 04 | L10: =IF(OR(MID($I10,8,1)="1",MID($I10,8,1)="3"),"남자",IF(OR(MID($I10,8,1)="2",MID($I10,8,1)="4"),"여자","")) -> 남자 | M10: =YEAR(TODAY())-IF(OR(MID($I10,8,1)="1",MID($I10,8,1)="2"),19&LEFT($I10,2),IF(OR(MID($I10,8,1)="3",MID($I10,8,1)="4"),20&LEFT($I10,2),""))+1 -> 35 | N10: 양력 | O10: 한국 | P10: 010-4168-4630 | R10: 무 | T10: TBELL | V10: =QUOTIENT(SUMPRODUCT(LEFT($W10:$X10,FIND("년",$W10:$X10)-1)*12+MID($W10:$X10,FIND("년",$W10:$X10)+1,FIND("개월",$W10:$X10)-FIND("년",$W10:$X10)-1)),12)&"년"&MOD(SUMPRODUCT(LEFT($W10:$X10,FIND("년",$W10:$X10)-1)*12+MID($W10:$X10,FIND("년",$W10:$X10)+1,FIND("개월",$W10:$X10)-FIND("년",$W10:$X10)-1)),12)&"개월" -> 9년3개월 | W10: 1년 8개월 | X10: =DATEDIF($D10,TODAY(),"y")&"년"&DATEDIF($D10,TODAY(),"ym")&"개월" -> 7년7개월 | Y10: 용인송담대학교 | Z10: 컴퓨터게임과 | AA10: 전문학사 | AB10: 42412 | AC10: =VALUE(LEFT($V10,FIND("년",$V10)-1)) -> 9 | AD10: =IF($AA10="전문학사",IF($AC10<=8,"초급",IF($AC10<12,"중급",IF($AC10<15,"고급",IF($AC10>=15,"특급"))))) -> 중급 | AE10: =IF(ISNUMBER(SEARCH("산업기사",$AL10)),IF($AC10>=13,"특급",IF($AC10>=10,"고급",IF($AC10>=7,"중급","초급"))),IF(ISNUMBER(SEARCH("기사",$AJ10)),IF($AC10>=10,"특급",IF($AC10>=7,"고급",IF($AC10>=4,"중급","초급"))),"미해당")) -> 미해당 | AQ10: IT기획 및 품질관리 | AR10: 테스팅 엔지니어 | AS10: 기업은행 | AT10: 534-026781-01-015 | AU10: 모 | AV10: 010-2657-4630 | AW10: gh.jeon@tbell.co.kr | AX10: 서울시 | AY10: 구로구 | BA10: 부일로17길 147 4층 | BB10: =IFERROR(VLOOKUP($AY10,[1]프로젝트현황!Y:Z,2,0),"기타") -> 서남권 | BC10: =(IF(AX10="","",AX10&" "))&(IF(AY10="","",AY10&" "))&(IF(AZ10="","",AZ10&" "))&BA10 -> 서울시 구로구 부일로17길 147 4층
A11: =ROW()-2 -> 9 | B11: 190102 | C11: 김재완 | D11: 43467 | E11: 43467 | H11: Kim, Jae Wan | I11: 920208-1238814 | J11: =LEFT(I11,6) -> 920208 | K11: =MID($I11,3,2) -> 02 | L11: =IF(OR(MID($I11,8,1)="1",MID($I11,8,1)="3"),"남자",IF(OR(MID($I11,8,1)="2",MID($I11,8,1)="4"),"여자","")) -> 남자 | M11: =YEAR(TODAY())-IF(OR(MID($I11,8,1)="1",MID($I11,8,1)="2"),19&LEFT($I11,2),IF(OR(MID($I11,8,1)="3",MID($I11,8,1)="4"),20&LEFT($I11,2),""))+1 -> 35 | N11: 양력 | O11: 한국 | P11: 010-9001-4697 | R11: 무 | T11: TBELL | V11: =QUOTIENT(SUMPRODUCT(LEFT($W11:$X11,FIND("년",$W11:$X11)-1)*12+MID($W11:$X11,FIND("년",$W11:$X11)+1,FIND("개월",$W11:$X11)-FIND("년",$W11:$X11)-1)),12)&"년"&MOD(SUMPRODUCT(LEFT($W11:$X11,FIND("년",$W11:$X11)-1)*12+MID($W11:$X11,FIND("년",$W11:$X11)+1,FIND("개월",$W11:$X11)-FIND("년",$W11:$X11)-1)),12)&"개월" -> 8년4개월 | W11: 1년3개월 | X11: =DATEDIF($D11,TODAY(),"y")&"년"&DATEDIF($D11,TODAY(),"ym")&"개월" -> 7년1개월 | Y11: 청강문화산업대학교 | Z11: E스포츠게임과 | AA11: 전문학사 | AB11: 42050 | AC11: =VALUE(LEFT($V11,FIND("년",$V11)-1)) -> 8 | AD11: =IF($AA11="전문학사",IF($AC11<=8,"초급",IF($AC11<12,"중급",IF($AC11<15,"고급",IF($AC11>=15,"특급"))))) -> 초급 | AE11: =IF(ISNUMBER(SEARCH("산업기사",$AL11)),IF($AC11>=13,"특급",IF($AC11>=10,"고급",IF($AC11>=7,"중급","초급"))),IF(ISNUMBER(SEARCH("기사",$AJ11)),IF($AC11>=10,"특급",IF($AC11>=7,"고급",IF($AC11>=4,"중급","초급"))),"미해당")) -> 미해당 | AH11: ISTQB | AI11: 2017.12 | AO11: ISTQB | AP11: 2017.12.05 | AQ11: IT기획 및 품질관리 | AR11: 테스팅 엔지니어 | AS11: 기업은행 | AT11: 001-623506-01-018 | AU11: 모 | AV11: 010-6322-4697 | AW11: jw.kim@tbell.co.kr | AX11: 경기도 | AY11: 부천시 | AZ11: 원미구 | BA11: 부일로 232, 102동 2108호 (상동) | BB11: =IFERROR(VLOOKUP($AY11,[1]프로젝트현황!Y:Z,2,0),"기타") -> 서남권 | BC11: =(IF(AX11="","",AX11&" "))&(IF(AY11="","",AY11&" "))&(IF(AZ11="","",AZ11&" "))&BA11 -> 경기도 부천시 원미구 부일로 232, 102동 2108호 (상동)
A12: =ROW()-2 -> 10 | B12: 190103 | C12: 이정훈 | D12: 43474 | E12: 43474 | I12: 910629-1285511 | J12: =LEFT(I12,6) -> 910629 | K12: =MID($I12,3,2) -> 06 | L12: =IF(OR(MID($I12,8,1)="1",MID($I12,8,1)="3"),"남자",IF(OR(MID($I12,8,1)="2",MID($I12,8,1)="4"),"여자","")) -> 남자 | M12: =YEAR(TODAY())-IF(OR(MID($I12,8,1)="1",MID($I12,8,1)="2"),19&LEFT($I12,2),IF(OR(MID($I12,8,1)="3",MID($I12,8,1)="4"),20&LEFT($I12,2),""))+1 -> 36 | N12: 양력 | O12: 한국 | P12: 010-2082-2969 | R12: 무 | T12: TBELL | V12: =QUOTIENT(SUMPRODUCT(LEFT($W12:$X12,FIND("년",$W12:$X12)-1)*12+MID($W12:$X12,FIND("년",$W12:$X12)+1,FIND("개월",$W12:$X12)-FIND("년",$W12:$X12)-1)),12)&"년"&MOD(SUMPRODUCT(LEFT($W12:$X12,FIND("년",$W12:$X12)-1)*12+MID($W12:$X12,FIND("년",$W12:$X12)+1,FIND("개월",$W12:$X12)-FIND("년",$W12:$X12)-1)),12)&"개월" -> 13년6개월 | W12: 6년 5개월 | X12: =DATEDIF($D12,TODAY(),"y")&"년"&DATEDIF($D12,TODAY(),"ym")&"개월" -> 7년1개월 | Y12: 태백기계공업고등학교 | Z12: 전자기계과 | AA12: 고졸 | AB12: 40221 | AC12: =VALUE(LEFT($V12,FIND("년",$V12)-1)) -> 13 | AD12: =IF($AA12="고졸",IF($AC12<=11,"초급",IF($AC12<=14,"중급",IF($AC12<=17,"고급",IF($AC12>=18,"특급"))))) -> 중급 | AE12: =IF(ISNUMBER(SEARCH("산업기사",$AL12)),IF($AC12>=13,"특급",IF($AC12>=10,"고급",IF($AC12>=7,"중급","초급"))),IF(ISNUMBER(SEARCH("기사",$AJ12)),IF($AC12>=10,"특급",IF($AC12>=7,"고급",IF($AC12>=4,"중급","초급"))),"미해당")) -> 미해당 | AH12: ISTQB | AI12: 42206 | AO12: ISTQB | AP12: 2015.07.21 | AQ12: IT기획 및 품질관리 | AR12: 테스팅 엔지니어 | AS12: 기업은행 | AT12: 126-087492-01-017 | AU12: 제 | AV12: 010-4170-0045 | AW12: jh.lee2@tbell.co.kr | AX12: 서울시 | AY12: 관악구 | BA12: 행운2길 51 502호 | BB12: =IFERROR(VLOOKUP($AY12,[1]프로젝트현황!Y:Z,2,0),"기타") -> 서남권 | BC12: =(IF(AX12="","",AX12&" "))&(IF(AY12="","",AY12&" "))&(IF(AZ12="","",AZ12&" "))&BA12 -> 서울시 관악구 행운2길 51 502호
A13: =ROW()-2 -> 11 | B13: 190105 | C13: 김하정 | D13: 43479 | E13: 43479 | H13: Kim, Ha Jung | I13: 911113-2055428 | J13: =LEFT(I13,6) -> 911113 | K13: =MID($I13,3,2) -> 11 | L13: =IF(OR(MID($I13,8,1)="1",MID($I13,8,1)="3"),"남자",IF(OR(MID($I13,8,1)="2",MID($I13,8,1)="4"),"여자","")) -> 여자 | M13: =YEAR(TODAY())-IF(OR(MID($I13,8,1)="1",MID($I13,8,1)="2"),19&LEFT($I13,2),IF(OR(MID($I13,8,1)="3",MID($I13,8,1)="4"),20&LEFT($I13,2),""))+1 -> 36 | N13: 양력 | O13: 한국 | P13: 010-3794-9113 | T13: TBELL | V13: =QUOTIENT(SUMPRODUCT(LEFT($W13:$X13,FIND("년",$W13:$X13)-1)*12+MID($W13:$X13,FIND("년",$W13:$X13)+1,FIND("개월",$W13:$X13)-FIND("년",$W13:$X13)-1)),12)&"년"&MOD(SUMPRODUCT(LEFT($W13:$X13,FIND("년",$W13:$X13)-1)*12+MID($W13:$X13,FIND("년",$W13:$X13)+1,FIND("개월",$W13:$X13)-FIND("년",$W13:$X13)-1)),12)&"개월" -> 7년9개월 | W13: 0년9개월 | X13: =DATEDIF($D13,TODAY(),"y")&"년"&DATEDIF($D13,TODAY(),"ym")&"개월" -> 7년0개월 | Y13: 덕성여자대학교 | Z13: 컴퓨터학과 | AA13: 학사 | AB13: 42787 | AC13: =VALUE(LEFT($V13,FIND("년",$V13)-1)) -> 7 | AD13: =IF($AA13="학사",IF($AC13<=5,"초급",IF($AC13<9,"중급",IF($AC13<12,"고급",IF($AC13>=12,"특급"))))) -> 중급 | AE13: =IF(ISNUMBER(SEARCH("산업기사",$AL13)),IF($AC13>=13,"특급",IF($AC13>=10,"고급",IF($AC13>=7,"중급","초급"))),IF(ISNUMBER(SEARCH("기사",$AJ13)),IF($AC13>=10,"특급",IF($AC13>=7,"고급",IF($AC13>=4,"중급","초급"))),"미해당")) -> 미해당 | AN13: ICDL starter | AO13: ICDL Korea | AP13: 2012.11 | AQ13: IT기획 및 품질관리 | AR13: 테스팅 엔지니어 | AS13: 기업은행 | AT13: 589-024251-01-012 | AU13: 모 | AV13: 010-8872-1841 | AW13: hj.kim@tbell.co.kr | AX13: 서울시 | AY13: 서초구 | BA13: 청계산로9길 1-12, 601동 309호(신원동, 서초포레스타) | BB13: =IFERROR(VLOOKUP($AY13,[1]프로젝트현황!Y:Z,2,0),"기타") -> 동남권 | BC13: =(IF(AX13="","",AX13&" "))&(IF(AY13="","",AY13&" "))&(IF(AZ13="","",AZ13&" "))&BA13 -> 서울시 서초구 청계산로9길 1-12, 601동 309호(신원동, 서초포레스타)
A14: =ROW()-2 -> 12 | B14: 190107 | C14: 김예림 | D14: 43495 | E14: 43495 | H14: Kim, Ye Rim | I14: 961116-2066116 | J14: =LEFT(I14,6) -> 961116 | K14: =MID($I14,3,2) -> 11 | L14: =IF(OR(MID($I14,8,1)="1",MID($I14,8,1)="3"),"남자",IF(OR(MID($I14,8,1)="2",MID($I14,8,1)="4"),"여자","")) -> 여자 | M14: =YEAR(TODAY())-IF(OR(MID($I14,8,1)="1",MID($I14,8,1)="2"),19&LEFT($I14,2),IF(OR(MID($I14,8,1)="3",MID($I14,8,1)="4"),20&LEFT($I14,2),""))+1 -> 31 | N14: 양력 | O14: 한국 | P14: 010-2356-9458 | T14: TBELL | V14: =QUOTIENT(SUMPRODUCT(LEFT($W14:$X14,FIND("년",$W14:$X14)-1)*12+MID($W14:$X14,FIND("년",$W14:$X14)+1,FIND("개월",$W14:$X14)-FIND("년",$W14:$X14)-1)),12)&"년"&MOD(SUMPRODUCT(LEFT($W14:$X14,FIND("년",$W14:$X14)-1)*12+MID($W14:$X14,FIND("년",$W14:$X14)+1,FIND("개월",$W14:$X14)-FIND("년",$W14:$X14)-1)),12)&"개월" -> 9년0개월 | W14: 2년0개월 | X14: =DATEDIF($D14,TODAY(),"y")&"년"&DATEDIF($D14,TODAY(),"ym")&"개월" -> 7년0개월 | Y14: 명지전문대학교 | Z14: 부동산경영과 | AA14: 전문학사 | AB14: 43154 | AC14: =VALUE(LEFT($V14,FIND("년",$V14)-1)) -> 9 | AD14: =IF($AA14="전문학사",IF($AC14<=8,"초급",IF($AC14<12,"중급",IF($AC14<15,"고급",IF($AC14>=15,"특급"))))) -> 중급 | AE14: =IF(ISNUMBER(SEARCH("산업기사",$AL14)),IF($AC14>=13,"특급",IF($AC14>=10,"고급",IF($AC14>=7,"중급","초급"))),IF(ISNUMBER(SEARCH("기사",$AJ14)),IF($AC14>=10,"특급",IF($AC14>=7,"고급",IF($AC14>=4,"중급","초급"))),"미해당")) -> 미해당 | AQ14: 경영관리 | AR14: 경영관리 | AS14: 기업은행 | AT14: 988-008943-01-017 | AU14: 모 | AV14: 010-8243-8002 | AW14: yr.kim@tbell.co.kr | AX14: 서울시 | AY14: 강서구 | BA14: 등촌동 641-12, 802호 | BB14: =IFERROR(VLOOKUP($AY14,[1]프로젝트현황!Y:Z,2,0),"기타") -> 서남권 | BC14: =(IF(AX14="","",AX14&" "))&(IF(AY14="","",AY14&" "))&(IF(AZ14="","",AZ14&" "))&BA14 -> 서울시 강서구 등촌동 641-12, 802호
A15: =ROW()-2 -> 13 | B15: 190301 | C15: 최현준 | D15: 43529 | E15: 43529 | H15: Choi, Hyun Jun | I15: 870110-1011923 | J15: =LEFT(I15,6) -> 870110 | K15: =MID($I15,3,2) -> 01 | L15: =IF(OR(MID($I15,8,1)="1",MID($I15,8,1)="3"),"남자",IF(OR(MID($I15,8,1)="2",MID($I15,8,1)="4"),"여자","")) -> 남자 | M15: =YEAR(TODAY())-IF(OR(MID($I15,8,1)="1",MID($I15,8,1)="2"),19&LEFT($I15,2),IF(OR(MID($I15,8,1)="3",MID($I15,8,1)="4"),20&LEFT($I15,2),""))+1 -> 40 | N15: 양력 | O15: 한국 | P15: 010-5491-0110 | T15: TBELL | V15: =QUOTIENT(SUMPRODUCT(LEFT($W15:$X15,FIND("년",$W15:$X15)-1)*12+MID($W15:$X15,FIND("년",$W15:$X15)+1,FIND("개월",$W15:$X15)-FIND("년",$W15:$X15)-1)),12)&"년"&MOD(SUMPRODUCT(LEFT($W15:$X15,FIND("년",$W15:$X15)-1)*12+MID($W15:$X15,FIND("년",$W15:$X15)+1,FIND("개월",$W15:$X15)-FIND("년",$W15:$X15)-1)),12)&"개월" -> 15년11개월 | W15: 9년0개월 | X15: =DATEDIF($D15,TODAY(),"y")&"년"&DATEDIF($D15,TODAY(),"ym")&"개월" -> 6년11개월 | Y15: 신구대학교 | Z15: 컴퓨터 멀티미디어과 | AA15: 전문학사 | AB15: 40218 | AC15: =VALUE(LEFT($V15,FIND("년",$V15)-1)) -> 15 | AD15: =IF($AA15="전문학사",IF($AC15<=8,"초급",IF($AC15<12,"중급",IF($AC15<15,"고급",IF($AC15>=15,"특급"))))) -> 특급 | AE15: =IF(ISNUMBER(SEARCH("산업기사",$AL15)),IF($AC15>=13,"특급",IF($AC15>=10,"고급",IF($AC15>=7,"중급","초급"))),IF(ISNUMBER(SEARCH("기사",$AJ15)),IF($AC15>=10,"특급",IF($AC15>=7,"고급",IF($AC15>=4,"중급","초급"))),"미해당")) -> 미해당 | AH15: ISTQB | AI15: 42787 | AN15: 컴퓨활용능력3급 정보기기기능사 워드프로세스1급 | AO15: 대한상공회의소 한국산업인력공단 대한상공회의소 ISTQB | AP15: 2003.03 2004.03 2004.11 2017.11 | AQ15: IT기획 및 품질관리 | AR15: 테스팅 엔지니어 | AS15: 기업은행 | AT15: 131-088072-01-017 | AU15: 모 | AV15: 010-2320-8062 | AW15: hj.choi@tbell.co.kr | AX15: 서울시 | AY15: 구로구 | BA15: 고척로 49, 202동 1402호 (오류동 338, 동부골든아파트) | BB15: =IFERROR(VLOOKUP($AY15,[1]프로젝트현황!Y:Z,2,0),"기타") -> 서남권 | BC15: =(IF(AX15="","",AX15&" "))&(IF(AY15="","",AY15&" "))&(IF(AZ15="","",AZ15&" "))&BA15 -> 서울시 구로구 고척로 49, 202동 1402호 (오류동 338, 동부골든아파트)
A16: =ROW()-2 -> 14 | B16: 190601 | C16: 조현정 | D16: 43619 | E16: 43619 | H16: Cho, Hyun Jung | I16: 730903-2041416 | J16: =LEFT(I16,6) -> 730903 | K16: =MID($I16,3,2) -> 09 | L16: =IF(OR(MID($I16,8,1)="1",MID($I16,8,1)="3"),"남자",IF(OR(MID($I16,8,1)="2",MID($I16,8,1)="4"),"여자","")) -> 여자 | M16: =YEAR(TODAY())-IF(OR(MID($I16,8,1)="1",MID($I16,8,1)="2"),19&LEFT($I16,2),IF(OR(MID($I16,8,1)="3",MID($I16,8,1)="4"),20&LEFT($I16,2),""))+1 -> 54 | N16: 양력 | O16: 한국 | P16: 010-4346-2311 | R16: 유 | S16: 45156 | T16: TBELL | V16: =QUOTIENT(SUMPRODUCT(LEFT($W16:$X16,FIND("년",$W16:$X16)-1)*12+MID($W16:$X16,FIND("년",$W16:$X16)+1,FIND("개월",$W16:$X16)-FIND("년",$W16:$X16)-1)),12)&"년"&MOD(SUMPRODUCT(LEFT($W16:$X16,FIND("년",$W16:$X16)-1)*12+MID($W16:$X16,FIND("년",$W16:$X16)+1,FIND("개월",$W16:$X16)-FIND("년",$W16:$X16)-1)),12)&"개월" -> 28년3개월 | W16: 21년 7개월 | X16: =DATEDIF($D16,TODAY(),"y")&"년"&DATEDIF($D16,TODAY(),"ym")&"개월" -> 6년8개월 | Y16: 유한전문대학교 | Z16: 전자계산과 | AA16: 전문학사 | AB16: 34733 | AC16: =VALUE(LEFT($V16,FIND("년",$V16)-1)) -> 28 | AD16: =IF($AA16="전문학사",IF($AC16<=8,"초급",IF($AC16<12,"중급",IF($AC16<15,"고급",IF($AC16>=15,"특급"))))) -> 특급 | AE16: =IF(ISNUMBER(SEARCH("산업기사",$AL16)),IF($AC16>=13,"특급",IF($AC16>=10,"고급",IF($AC16>=7,"중급","초급"))),IF(ISNUMBER(SEARCH("기사",$AJ16)),IF($AC16>=10,"특급",IF($AC16>=7,"고급",IF($AC16>=4,"중급","초급"))),"미해당")) -> 특급 | AJ16: 정보처리기사 | AK16: 34621 | AN16: SuccessFactors | AO16: 한국정보통신기술협회 한국산업인력공단 SAP | AP16: 1995 2016 | AQ16: IT기획 및 품질관리 | AR16: 테스팅 엔지니어 | AS16: 하나은행 | AT16: 160-910357-92807 | AU16: 처 | AV16: 010-3637-2439 | AW16: hj.cho@tbell.co.kr | AX16: 서울시 | AY16: 서대문구 | BA16: 문화촌길 6-24, 103동 510호(홍제동, 문화촌현대아파트) | BB16: =IFERROR(VLOOKUP($AY16,[1]프로젝트현황!Y:Z,2,0),"기타") -> 서북권 | BC16: =(IF(AX16="","",AX16&" "))&(IF(AY16="","",AY16&" "))&(IF(AZ16="","",AZ16&" "))&BA16 -> 서울시 서대문구 문화촌길 6-24, 103동 510호(홍제동, 문화촌현대아파트)
A17: =ROW()-2 -> 15 | B17: 190903 | C17: 이건혁 | D17: 43731 | E17: 43731 | F17: 45352 | H17: Lee, Gun Heyk | I17: 920215-1058330 | J17: =LEFT(I17,6) -> 920215 | K17: =MID($I17,3,2) -> 02 | L17: =IF(OR(MID($I17,8,1)="1",MID($I17,8,1)="3"),"남자",IF(OR(MID($I17,8,1)="2",MID($I17,8,1)="4"),"여자","")) -> 남자 | M17: =YEAR(TODAY())-IF(OR(MID($I17,8,1)="1",MID($I17,8,1)="2"),19&LEFT($I17,2),IF(OR(MID($I17,8,1)="3",MID($I17,8,1)="4"),20&LEFT($I17,2),""))+1 -> 35 | N17: 양력 | O17: 한국 | P17: 010-3795-0907 | R17: 무 | T17: TBELL | V17: =QUOTIENT(SUMPRODUCT(LEFT($W17:$X17,FIND("년",$W17:$X17)-1)*12+MID($W17:$X17,FIND("년",$W17:$X17)+1,FIND("개월",$W17:$X17)-FIND("년",$W17:$X17)-1)),12)&"년"&MOD(SUMPRODUCT(LEFT($W17:$X17,FIND("년",$W17:$X17)-1)*12+MID($W17:$X17,FIND("년",$W17:$X17)+1,FIND("개월",$W17:$X17)-FIND("년",$W17:$X17)-1)),12)&"개월" -> 7년4개월 | W17: 1년 0개월 | X17: =DATEDIF($D17,TODAY(),"y")&"년"&DATEDIF($D17,TODAY(),"ym")&"개월" -> 6년4개월 | Y17: 청강문화산업대학교 | Z17: E스포츠게임과 | AA17: 전문학사 | AB17: 42048 | AC17: =VALUE(LEFT($V17,FIND("년",$V17)-1)) -> 7 | AD17: =IF($AA17="전문학사",IF($AC17<=8,"초급",IF($AC17<12,"중급",IF($AC17<15,"고급",IF($AC17>=15,"특급"))))) -> 초급 | AE17: =IF(ISNUMBER(SEARCH("산업기사",$AL17)),IF($AC17>=13,"특급",IF($AC17>=10,"고급",IF($AC17>=7,"중급","초급"))),IF(ISNUMBER(SEARCH("기사",$AJ17)),IF($AC17>=10,"특급",IF($AC17>=7,"고급",IF($AC17>=4,"중급","초급"))),"미해당")) -> 미해당 | AH17: ISTQB | AI17: 2023.02 | AQ17: IT기획 및 품질관리 | AR17: 테스팅 엔지니어 | AS17: 기업은행 | AT17: 085-055231-01-011 | AU17: 모 | AV17: 010-5694-2308 | AW17: gh.lee@tbell.co.kr | AX17: 경기도 | AY17: 안양시 | AZ17: 동안구 | BA17: 관악대로263번길 67-8, 가동 101호(비산동, 화도맨션) | BB17: =IFERROR(VLOOKUP($AY17,[1]프로젝트현황!Y:Z,2,0),"기타") -> 서남권 | BC17: =(IF(AX17="","",AX17&" "))&(IF(AY17="","",AY17&" "))&(IF(AZ17="","",AZ17&" "))&BA17 -> 경기도 안양시 동안구 관악대로263번길 67-8, 가동 101호(비산동, 화도맨션)
A18: =ROW()-2 -> 16 | B18: 200901 | C18: 홍영실 | D18: 44075 | E18: 44075 | H18: Hong, Yeong Sil | I18: 990903-2233619 | J18: =LEFT(I18,6) -> 990903 | K18: =MID($I18,3,2) -> 09 | L18: =IF(OR(MID($I18,8,1)="1",MID($I18,8,1)="3"),"남자",IF(OR(MID($I18,8,1)="2",MID($I18,8,1)="4"),"여자","")) -> 여자 | M18: =YEAR(TODAY())-IF(OR(MID($I18,8,1)="1",MID($I18,8,1)="2"),19&LEFT($I18,2),IF(OR(MID($I18,8,1)="3",MID($I18,8,1)="4"),20&LEFT($I18,2),""))+1 -> 28 | N18: 양력 | O18: 한국 | P18: 010-9306-6493 | T18: TBELL | V18: =QUOTIENT(SUMPRODUCT(LEFT($W18:$X18,FIND("년",$W18:$X18)-1)*12+MID($W18:$X18,FIND("년",$W18:$X18)+1,FIND("개월",$W18:$X18)-FIND("년",$W18:$X18)-1)),12)&"년"&MOD(SUMPRODUCT(LEFT($W18:$X18,FIND("년",$W18:$X18)-1)*12+MID($W18:$X18,FIND("년",$W18:$X18)+1,FIND("개월",$W18:$X18)-FIND("년",$W18:$X18)-1)),12)&"개월" -> 5년5개월 | W18: 0년0개월 | X18: =DATEDIF($D18,TODAY(),"y")&"년"&DATEDIF($D18,TODAY(),"ym")&"개월" -> 5년5개월 | Y18: 인하공업전문대학교 | Z18: 컴퓨터시스템과 | AA18: 전문학사 | AB18: 44232 | AC18: =VALUE(LEFT($V18,FIND("년",$V18)-1)) -> 5 | AD18: =IF($AA18="전문학사",IF($AC18<=8,"초급",IF($AC18<12,"중급",IF($AC18<15,"고급",IF($AC18>=15,"특급"))))) -> 초급 | AE18: =IF(ISNUMBER(SEARCH("산업기사",$AL18)),IF($AC18>=13,"특급",IF($AC18>=10,"고급",IF($AC18>=7,"중급","초급"))),IF(ISNUMBER(SEARCH("기사",$AJ18)),IF($AC18>=10,"특급",IF($AC18>=7,"고급",IF($AC18>=4,"중급","초급"))),"미해당")) -> 미해당 | AQ18: IT기획 및 품질관리 | AR18: 테스팅 엔지니어 | AS18: 기업은행 | AT18: 508-038161-01-026 | AU18: 모 | AV18: 010-4742-6499 | AW18: ys.hong@tbell.co.kr | AX18: 경기도 | AY18: 파주시 | BA18: 파평면 배머리길 811-15 | BB18: =IFERROR(VLOOKUP($AY18,[1]프로젝트현황!Y:Z,2,0),"기타") -> 서북권 | BC18: =(IF(AX18="","",AX18&" "))&(IF(AY18="","",AY18&" "))&(IF(AZ18="","",AZ18&" "))&BA18 -> 경기도 파주시 파평면 배머리길 811-15
A19: =ROW()-2 -> 17 | B19: 201003 | C19: 임상욱 | D19: 44116 | E19: 44116 | H19: Lim Sang Wook | I19: 931106-1184719 | J19: =LEFT(I19,6) -> 931106 | K19: =MID($I19,3,2) -> 11 | L19: =IF(OR(MID($I19,8,1)="1",MID($I19,8,1)="3"),"남자",IF(OR(MID($I19,8,1)="2",MID($I19,8,1)="4"),"여자","")) -> 남자 | M19: =YEAR(TODAY())-IF(OR(MID($I19,8,1)="1",MID($I19,8,1)="2"),19&LEFT($I19,2),IF(OR(MID($I19,8,1)="3",MID($I19,8,1)="4"),20&LEFT($I19,2),""))+1 -> 34 | N19: 양력 | O19: 한국 | P19: 010-4059-3674 | T19: TBELL | V19: =QUOTIENT(SUMPRODUCT(LEFT($W19:$X19,FIND("년",$W19:$X19)-1)*12+MID($W19:$X19,FIND("년",$W19:$X19)+1,FIND("개월",$W19:$X19)-FIND("년",$W19:$X19)-1)),12)&"년"&MOD(SUMPRODUCT(LEFT($W19:$X19,FIND("년",$W19:$X19)-1)*12+MID($W19:$X19,FIND("년",$W19:$X19)+1,FIND("개월",$W19:$X19)-FIND("년",$W19:$X19)-1)),12)&"개월" -> 8년3개월 | W19: 3년0개월 | X19: =DATEDIF($D19,TODAY(),"y")&"년"&DATEDIF($D19,TODAY(),"ym")&"개월" -> 5년3개월 | Y19: 신구대학교 | Z19: 모바일IT전공 | AA19: 전문학사 | AB19: 42769 | AC19: =VALUE(LEFT($V19,FIND("년",$V19)-1)) -> 8 | AD19: =IF($AA19="전문학사",IF($AC19<=8,"초급",IF($AC19<12,"중급",IF($AC19<15,"고급",IF($AC19>=15,"특급"))))) -> 초급 | AE19: =IF(ISNUMBER(SEARCH("산업기사",$AL19)),IF($AC19>=13,"특급",IF($AC19>=10,"고급",IF($AC19>=7,"중급","초급"))),IF(ISNUMBER(SEARCH("기사",$AJ19)),IF($AC19>=10,"특급",IF($AC19>=7,"고급",IF($AC19>=4,"중급","초급"))),"미해당")) -> 미해당 | AQ19: IT기획 및 품질관리 | AR19: 테스팅 엔지니어 | AS19: 기업은행 | AT19: 242-124483-01-015 | AU19: 모 | AV19: 010-4158-3674 | AW19: sw.lim@tbell.co.kr | AX19: 경기도 | AY19: 광주시 | BA19: 송정로 59-26, 2층 | BB19: =IFERROR(VLOOKUP($AY19,[1]프로젝트현황!Y:Z,2,0),"기타") -> 동남권 | BC19: =(IF(AX19="","",AX19&" "))&(IF(AY19="","",AY19&" "))&(IF(AZ19="","",AZ19&" "))&BA19 -> 경기도 광주시 송정로 59-26, 2층
A20: =ROW()-2 -> 18 | B20: 210301 | C20: 조우성 | D20: 44257 | E20: 44257 | H20: Cho Woo Sung | I20: 950306-1388224 | J20: =LEFT(I20,6) -> 950306 | K20: =MID($I20,3,2) -> 03 | L20: =IF(OR(MID($I20,8,1)="1",MID($I20,8,1)="3"),"남자",IF(OR(MID($I20,8,1)="2",MID($I20,8,1)="4"),"여자","")) -> 남자 | M20: =YEAR(TODAY())-IF(OR(MID($I20,8,1)="1",MID($I20,8,1)="2"),19&LEFT($I20,2),IF(OR(MID($I20,8,1)="3",MID($I20,8,1)="4"),20&LEFT($I20,2),""))+1 -> 32 | N20: 양력 | O20: 한국 | P20: 010-7215-4947 | T20: TBELL | U20: 曹 佑 誠 | V20: =QUOTIENT(SUMPRODUCT(LEFT($W20:$X20,FIND("년",$W20:$X20)-1)*12+MID($W20:$X20,FIND("년",$W20:$X20)+1,FIND("개월",$W20:$X20)-FIND("년",$W20:$X20)-1)),12)&"년"&MOD(SUMPRODUCT(LEFT($W20:$X20,FIND("년",$W20:$X20)-1)*12+MID($W20:$X20,FIND("년",$W20:$X20)+1,FIND("개월",$W20:$X20)-FIND("년",$W20:$X20)-1)),12)&"개월" -> 6년8개월 | W20: 1년 9개월 | X20: =DATEDIF($D20,TODAY(),"y")&"년"&DATEDIF($D20,TODAY(),"ym")&"개월" -> 4년11개월 | Y20: 안산대학교 | Z20: 인터넷정보과 | AA20: 전문학사 | AB20: 43511 | AC20: =VALUE(LEFT($V20,FIND("년",$V20)-1)) -> 6 | AD20: =IF($AA20="전문학사",IF($AC20<=8,"초급",IF($AC20<12,"중급",IF($AC20<15,"고급",IF($AC20>=15,"특급"))))) -> 초급 | AE20: =IF(ISNUMBER(SEARCH("산업기사",$AL20)),IF($AC20>=13,"특급",IF($AC20>=10,"고급",IF($AC20>=7,"중급","초급"))),IF(ISNUMBER(SEARCH("기사",$AJ20)),IF($AC20>=10,"특급",IF($AC20>=7,"고급",IF($AC20>=4,"중급","초급"))),"미해당")) -> 미해당 | AQ20: IT기획 및 품질관리 | AR20: 테스팅 엔지니어 | AS20: 기업은행 | AT20: 345-148269-01-013 | AU20: 모 | AV20: 010-5450-4947 | AW20: ws.cho@tbell.co.kr | AX20: 경기도 | AY20: 수원시 | AZ20: 권선구 | BA20: 세류동 97-20 201호 | BB20: =IFERROR(VLOOKUP($AY20,[1]프로젝트현황!Y:Z,2,0),"기타") -> 동남권 | BC20: =(IF(AX20="","",AX20&" "))&(IF(AY20="","",AY20&" "))&(IF(AZ20="","",AZ20&" "))&BA20 -> 경기도 수원시 권선구 세류동 97-20 201호
A21: =ROW()-2 -> 19 | B21: 210303 | C21: 김대현 | D21: 44273 | E21: 44273 | H21: Kim Dae Hyun | I21: 810323-1055111 | J21: =LEFT(I21,6) -> 810323 | K21: =MID($I21,3,2) -> 03 | L21: =IF(OR(MID($I21,8,1)="1",MID($I21,8,1)="3"),"남자",IF(OR(MID($I21,8,1)="2",MID($I21,8,1)="4"),"여자","")) -> 남자 | M21: =YEAR(TODAY())-IF(OR(MID($I21,8,1)="1",MID($I21,8,1)="2"),19&LEFT($I21,2),IF(OR(MID($I21,8,1)="3",MID($I21,8,1)="4"),20&LEFT($I21,2),""))+1 -> 46 | N21: 양력 | O21: 한국 | P21: 010-3021-9812 | T21: TBELL | U21: 金 大 鉉 | V21: =QUOTIENT(SUMPRODUCT(LEFT($W21:$X21,FIND("년",$W21:$X21)-1)*12+MID($W21:$X21,FIND("년",$W21:$X21)+1,FIND("개월",$W21:$X21)-FIND("년",$W21:$X21)-1)),12)&"년"&MOD(SUMPRODUCT(LEFT($W21:$X21,FIND("년",$W21:$X21)-1)*12+MID($W21:$X21,FIND("년",$W21:$X21)+1,FIND("개월",$W21:$X21)-FIND("년",$W21:$X21)-1)),12)&"개월" -> 16년1개월 | W21: 11년 3개월 | X21: =DATEDIF($D21,TODAY(),"y")&"년"&DATEDIF($D21,TODAY(),"ym")&"개월" -> 4년10개월 | Y21: 선문대학교 | Z21: 러시어학과 | AA21: 학사 | AB21: 39493 | AC21: =VALUE(LEFT($V21,FIND("년",$V21)-1)) -> 16 | AD21: =IF($AA21="학사",IF($AC21<=5,"초급",IF($AC21<9,"중급",IF($AC21<12,"고급",IF($AC21>=12,"특급"))))) -> 특급 | AE21: =IF(ISNUMBER(SEARCH("산업기사",$AL21)),IF($AC21>=13,"특급",IF($AC21>=10,"고급",IF($AC21>=7,"중급","초급"))),IF(ISNUMBER(SEARCH("기사",$AJ21)),IF($AC21>=10,"특급",IF($AC21>=7,"고급",IF($AC21>=4,"중급","초급"))),"미해당")) -> 미해당 | AQ21: IT기획 및 품질관리 | AR21: 테스팅 엔지니어 | AS21: 기업은행 | AT21: 389-122625-01-017 | AU21: 모 | AV21: 010-4337-9812 | AW21: dh.kim@tbell.co.kr | AX21: 경기도 | AY21: 성남시 | AZ21: 분당구 | BA21: 분당로 190 101동 102호(분당동, 샛별마을) | BB21: =IFERROR(VLOOKUP($AY21,[1]프로젝트현황!Y:Z,2,0),"기타") -> 동남권 | BC21: =(IF(AX21="","",AX21&" "))&(IF(AY21="","",AY21&" "))&(IF(AZ21="","",AZ21&" "))&BA21 -> 경기도 성남시 분당구 분당로 190 101동 102호(분당동, 샛별마을)
A22: =ROW()-2 -> 20 | B22: 210401 | C22: 이혜진 | D22: 44287 | E22: 44287 | H22: Lee Hae Jin | I22: 740122-2235035 | J22: =LEFT(I22,6) -> 740122 | K22: =MID($I22,3,2) -> 01 | L22: =IF(OR(MID($I22,8,1)="1",MID($I22,8,1)="3"),"남자",IF(OR(MID($I22,8,1)="2",MID($I22,8,1)="4"),"여자","")) -> 여자 | M22: =YEAR(TODAY())-IF(OR(MID($I22,8,1)="1",MID($I22,8,1)="2"),19&LEFT($I22,2),IF(OR(MID($I22,8,1)="3",MID($I22,8,1)="4"),20&LEFT($I22,2),""))+1 -> 53 | N22: 양력 | O22: 한국 | P22: 010-6218-3405 | R22: 유 | S22: 45047 | T22: TBELL | U22: 李 惠 眞 | V22: =QUOTIENT(SUMPRODUCT(LEFT($W22:$X22,FIND("년",$W22:$X22)-1)*12+MID($W22:$X22,FIND("년",$W22:$X22)+1,FIND("개월",$W22:$X22)-FIND("년",$W22:$X22)-1)),12)&"년"&MOD(SUMPRODUCT(LEFT($W22:$X22,FIND("년",$W22:$X22)-1)*12+MID($W22:$X22,FIND("년",$W22:$X22)+1,FIND("개월",$W22:$X22)-FIND("년",$W22:$X22)-1)),12)&"개월" -> 27년7개월 | W22: 22년 9개월 | X22: =DATEDIF($D22,TODAY(),"y")&"년"&DATEDIF($D22,TODAY(),"ym")&"개월" -> 4년10개월 | Y22: 고려대학교 | Z22: 소프트웨어공학과 | AA22: 석사 | AB22: 41145 | AC22: =VALUE(LEFT($V22,FIND("년",$V22)-1)) -> 27 | AD22: =IF($AA22="석사",IF($AC22<=2,"초급",IF($AC22<6,"중급",IF($AC22<9,"고급",IF($AC22>=9,"특급"))))) -> 특급 | AE22: =IF(ISNUMBER(SEARCH("산업기사",$AL22)),IF($AC22>=13,"특급",IF($AC22>=10,"고급",IF($AC22>=7,"중급","초급"))),IF(ISNUMBER(SEARCH("기사",$AJ22)),IF($AC22>=10,"특급",IF($AC22>=7,"고급",IF($AC22>=4,"중급","초급"))),"미해당")) -> 특급 | AH22: ISTQB | AI22: 44443 | AJ22: 정보처리기사 | AK22: 39237 | AN22: 컴퓨터그래픽스운용기능사 | AO22: 한국산업인력공단 한국산업인력공단 KSTQB | AP22: 2007.06 2000.08 2021.09.04 | AQ22: IT기획 및 품질관리 | AR22: 테스팅 엔지니어 | AS22: 기업은행 | AT22: 064-054748-02-017 | AU22: 배우자 | AV22: 010-4595-3461 | AW22: hj.lee@tbell.co.kr | AX22: 경기도 | AY22: 성남시 | AZ22: 분당구 | BA22: 서판교로29 918동 1804호 | BB22: =IFERROR(VLOOKUP($AY22,[1]프로젝트현황!Y:Z,2,0),"기타") -> 동남권 | BC22: =(IF(AX22="","",AX22&" "))&(IF(AY22="","",AY22&" "))&(IF(AZ22="","",AZ22&" "))&BA22 -> 경기도 성남시 분당구 서판교로29 918동 1804호
A23: =ROW()-2 -> 21 | B23: 210403 | C23: 이수민 | D23: 44306 | E23: 44306 | H23: Lee Su Min | I23: 971214-2032011 | J23: =LEFT(I23,6) -> 971214 | K23: =MID($I23,3,2) -> 12 | L23: =IF(OR(MID($I23,8,1)="1",MID($I23,8,1)="3"),"남자",IF(OR(MID($I23,8,1)="2",MID($I23,8,1)="4"),"여자","")) -> 여자 | M23: =YEAR(TODAY())-IF(OR(MID($I23,8,1)="1",MID($I23,8,1)="2"),19&LEFT($I23,2),IF(OR(MID($I23,8,1)="3",MID($I23,8,1)="4"),20&LEFT($I23,2),""))+1 -> 30 | N23: 양력 | O23: 한국 | P23: 010-7626-1531 | T23: TBELL | U23: 李 秀 民 | V23: =QUOTIENT(SUMPRODUCT(LEFT($W23:$X23,FIND("년",$W23:$X23)-1)*12+MID($W23:$X23,FIND("년",$W23:$X23)+1,FIND("개월",$W23:$X23)-FIND("년",$W23:$X23)-1)),12)&"년"&MOD(SUMPRODUCT(LEFT($W23:$X23,FIND("년",$W23:$X23)-1)*12+MID($W23:$X23,FIND("년",$W23:$X23)+1,FIND("개월",$W23:$X23)-FIND("년",$W23:$X23)-1)),12)&"개월" -> 8년7개월 | W23: 3년 10개월 | X23: =DATEDIF($D23,TODAY(),"y")&"년"&DATEDIF($D23,TODAY(),"ym")&"개월" -> 4년9개월 | Y23: 수원정보과학고등학교 | Z23: IT산업디자인과 | AA23: 고졸 | AB23: 42404 | AC23: =VALUE(LEFT($V23,FIND("년",$V23)-1)) -> 8 | AD23: =IF($AA23="고졸",IF($AC23<=11,"초급",IF($AC23<=14,"중급",IF($AC23<=17,"고급",IF($AC23>=18,"특급"))))) -> 초급 | AE23: =IF(ISNUMBER(SEARCH("산업기사",$AL23)),IF($AC23>=13,"특급",IF($AC23>=10,"고급",IF($AC23>=7,"중급","초급"))),IF(ISNUMBER(SEARCH("기사",$AJ23)),IF($AC23>=10,"특급",IF($AC23>=7,"고급",IF($AC23>=4,"중급","초급"))),"미해당")) -> 미해당 | AQ23: IT기획 및 품질관리 | AR23: 테스팅 엔지니어 | AS23: 기업은행 | AT23: 111-205461-01-014 | AU23: 모 | AV23: 010-2222-1531 | AW23: sumin.lee@tbell.co.kr | AX23: 경기도 | AY23: 수원시 | AZ23: 팔달구 | BA23: 월드컵로369번길 13, 202호 (우만동, 보은맨션) | BB23: =IFERROR(VLOOKUP($AY23,[1]프로젝트현황!Y:Z,2,0),"기타") -> 동남권 | BC23: =(IF(AX23="","",AX23&" "))&(IF(AY23="","",AY23&" "))&(IF(AZ23="","",AZ23&" "))&BA23 -> 경기도 수원시 팔달구 월드컵로369번길 13, 202호 (우만동, 보은맨션)
A24: =ROW()-2 -> 22 | B24: 210503 | C24: 이철호 | D24: 44337 | E24: 44470 | H24: Lee Chul Ho | I24: 741221-1808712 | J24: =LEFT(I24,6) -> 741221 | K24: =MID($I24,3,2) -> 12 | L24: =IF(OR(MID($I24,8,1)="1",MID($I24,8,1)="3"),"남자",IF(OR(MID($I24,8,1)="2",MID($I24,8,1)="4"),"여자","")) -> 남자 | M24: =YEAR(TODAY())-IF(OR(MID($I24,8,1)="1",MID($I24,8,1)="2"),19&LEFT($I24,2),IF(OR(MID($I24,8,1)="3",MID($I24,8,1)="4"),20&LEFT($I24,2),""))+1 -> 53 | N24: 양력 | O24: 한국 | P24: 010-2278-9935 | R24: 무 | T24: TBELL | U24: 李 哲 豪 | V24: =QUOTIENT(SUMPRODUCT(LEFT($W24:$X24,FIND("년",$W24:$X24)-1)*12+MID($W24:$X24,FIND("년",$W24:$X24)+1,FIND("개월",$W24:$X24)-FIND("년",$W24:$X24)-1)),12)&"년"&MOD(SUMPRODUCT(LEFT($W24:$X24,FIND("년",$W24:$X24)-1)*12+MID($W24:$X24,FIND("년",$W24:$X24)+1,FIND("개월",$W24:$X24)-FIND("년",$W24:$X24)-1)),12)&"개월" -> 20년9개월 | W24: 16년 1개월 | X24: =DATEDIF($D24,TODAY(),"y")&"년"&DATEDIF($D24,TODAY(),"ym")&"개월" -> 4년8개월 | Y24: 장훈고등학교 | AA24: 고졸 | AB24: 34013 | AC24: =VALUE(LEFT($V24,FIND("년",$V24)-1)) -> 20 | AD24: =IF($AA24="고졸",IF($AC24<=11,"초급",IF($AC24<=14,"중급",IF($AC24<=17,"고급",IF($AC24>=18,"특급"))))) -> 특급 | AE24: =IF(ISNUMBER(SEARCH("산업기사",$AL24)),IF($AC24>=13,"특급",IF($AC24>=10,"고급",IF($AC24>=7,"중급","초급"))),IF(ISNUMBER(SEARCH("기사",$AJ24)),IF($AC24>=10,"특급",IF($AC24>=7,"고급",IF($AC24>=4,"중급","초급"))),"미해당")) -> 미해당 | AN24: 정보처리기능사 2급 | AO24: 한국산업인력공단 | AP24: 1991.1 | AQ24: IT기획 및 품질관리 | AR24: 테스팅 엔지니어 | AS24: 기업은행 | AT24: 076-097767-01-013 | AU24: 모 | AV24: 010-2431-9935 | AW24: ch.lee@tbell.co.kr | AX24: 서울시 | AY24: 영등포구 | BA24: 도신로 64가길 1 1층 | BB24: =IFERROR(VLOOKUP($AY24,[1]프로젝트현황!Y:Z,2,0),"기타") -> 서남권 | BC24: =(IF(AX24="","",AX24&" "))&(IF(AY24="","",AY24&" "))&(IF(AZ24="","",AZ24&" "))&BA24 -> 서울시 영등포구 도신로 64가길 1 1층
A25: =ROW()-2 -> 23 | B25: 210504 | C25: 이원택 | D25: 44347 | E25: 44347 | H25: Lee Won Taek | I25: 970415-1065515 | J25: =LEFT(I25,6) -> 970415 | K25: =MID($I25,3,2) -> 04 | L25: =IF(OR(MID($I25,8,1)="1",MID($I25,8,1)="3"),"남자",IF(OR(MID($I25,8,1)="2",MID($I25,8,1)="4"),"여자","")) -> 남자 | M25: =YEAR(TODAY())-IF(OR(MID($I25,8,1)="1",MID($I25,8,1)="2"),19&LEFT($I25,2),IF(OR(MID($I25,8,1)="3",MID($I25,8,1)="4"),20&LEFT($I25,2),""))+1 -> 30 | N25: 양력 | O25: 한국 | P25: 010-8936-5320 | R25: 무 | T25: TBELL | U25: 李 元 垞 | V25: =QUOTIENT(SUMPRODUCT(LEFT($W25:$X25,FIND("년",$W25:$X25)-1)*12+MID($W25:$X25,FIND("년",$W25:$X25)+1,FIND("개월",$W25:$X25)-FIND("년",$W25:$X25)-1)),12)&"년"&MOD(SUMPRODUCT(LEFT($W25:$X25,FIND("년",$W25:$X25)-1)*12+MID($W25:$X25,FIND("년",$W25:$X25)+1,FIND("개월",$W25:$X25)-FIND("년",$W25:$X25)-1)),12)&"개월" -> 4년8개월 | W25: 0년 0개월 | X25: =DATEDIF($D25,TODAY(),"y")&"년"&DATEDIF($D25,TODAY(),"ym")&"개월" -> 4년8개월 | Y25: 대림대학교 | Z25: 모바일인터넷과 | AA25: 전문학사 | AB25: 44243 | AC25: =VALUE(LEFT($V25,FIND("년",$V25)-1)) -> 4 | AD25: =IF($AA25="전문학사",IF($AC25<=8,"초급",IF($AC25<12,"중급",IF($AC25<15,"고급",IF($AC25>=15,"특급"))))) -> 초급 | AE25: =IF(ISNUMBER(SEARCH("산업기사",$AL25)),IF($AC25>=13,"특급",IF($AC25>=10,"고급",IF($AC25>=7,"중급","초급"))),IF(ISNUMBER(SEARCH("기사",$AJ25)),IF($AC25>=10,"특급",IF($AC25>=7,"고급",IF($AC25>=4,"중급","초급"))),"미해당")) -> 미해당 | AQ25: IT기획 및 품질관리 | AR25: 테스팅 엔지니어 | AS25: 기업은행 | AT25: 074-104301-01-010 | AU25: 모 | AV25: 010-8543-4320 | AW25: wt.lee@tbell.co.kr | AX25: 서울시 | AY25: 관악구 | BA25: 남부순환로 1430 신림푸르지오 114동 704호 | BB25: =IFERROR(VLOOKUP($AY25,[1]프로젝트현황!Y:Z,2,0),"기타") -> 서남권 | BC25: =(IF(AX25="","",AX25&" "))&(IF(AY25="","",AY25&" "))&(IF(AZ25="","",AZ25&" "))&BA25 -> 서울시 관악구 남부순환로 1430 신림푸르지오 114동 704호
A26: =ROW()-2 -> 24 | B26: 210703 | C26: 이유라 | D26: 44378 | E26: 44378 | H26: Lee, Yura | I26: 920917-2126213 | J26: =LEFT(I26,6) -> 920917 | K26: =MID($I26,3,2) -> 09 | L26: =IF(OR(MID($I26,8,1)="1",MID($I26,8,1)="3"),"남자",IF(OR(MID($I26,8,1)="2",MID($I26,8,1)="4"),"여자","")) -> 여자 | M26: =YEAR(TODAY())-IF(OR(MID($I26,8,1)="1",MID($I26,8,1)="2"),19&LEFT($I26,2),IF(OR(MID($I26,8,1)="3",MID($I26,8,1)="4"),20&LEFT($I26,2),""))+1 -> 35 | N26: 양력 | O26: 한국 | P26: 010-8828-0917 | R26: 유 | S26: 45072 | T26: TBELL | U26: 李 柔 羅 | V26: =QUOTIENT(SUMPRODUCT(LEFT($W26:$X26,FIND("년",$W26:$X26)-1)*12+MID($W26:$X26,FIND("년",$W26:$X26)+1,FIND("개월",$W26:$X26)-FIND("년",$W26:$X26)-1)),12)&"년"&MOD(SUMPRODUCT(LEFT($W26:$X26,FIND("년",$W26:$X26)-1)*12+MID($W26:$X26,FIND("년",$W26:$X26)+1,FIND("개월",$W26:$X26)-FIND("년",$W26:$X26)-1)),12)&"개월" -> 4년7개월 | W26: 0년 0개월 | X26: =DATEDIF($D26,TODAY(),"y")&"년"&DATEDIF($D26,TODAY(),"ym")&"개월" -> 4년7개월 | Y26: 연세대학교 | Z26: 독어독문학 | AA26: 학사 | AB26: 42429 | AC26: =VALUE(LEFT($V26,FIND("년",$V26)-1)) -> 4 | AD26: =IF($AA26="학사",IF($AC26<=5,"초급",IF($AC26<9,"중급",IF($AC26<12,"고급",IF($AC26>=12,"특급"))))) -> 초급 | AE26: =IF(ISNUMBER(SEARCH("산업기사",$AL26)),IF($AC26>=13,"특급",IF($AC26>=10,"고급",IF($AC26>=7,"중급","초급"))),IF(ISNUMBER(SEARCH("기사",$AJ26)),IF($AC26>=10,"특급",IF($AC26>=7,"고급",IF($AC26>=4,"중급","초급"))),"미해당")) -> 미해당 | AQ26: 응용SW개발 | AR26: AI 데이터 가공 및 검수 | AS26: 기업은행 | AT26: 194-133344-01-013 | AU26: 배우자 | AV26: 010-4873-2725 | AW26: yr.lee@tbell.co.kr | AX26: 서울시 | AY26: 영등포구 | BA26: 양평로30길 38, 103-1301 | BB26: =IFERROR(VLOOKUP($AY26,[1]프로젝트현황!Y:Z,2,0),"기타") -> 서남권 | BC26: =(IF(AX26="","",AX26&" "))&(IF(AY26="","",AY26&" "))&(IF(AZ26="","",AZ26&" "))&BA26 -> 서울시 영등포구 양평로30길 38, 103-1301
A27: =ROW()-2 -> 25 | B27: 210901 | C27: 신명욱 | D27: 44466 | E27: 44466 | H27: SHIN, Myungwook | I27: 880915-1155216 | J27: =LEFT(I27,6) -> 880915 | K27: =MID($I27,3,2) -> 09 | L27: =IF(OR(MID($I27,8,1)="1",MID($I27,8,1)="3"),"남자",IF(OR(MID($I27,8,1)="2",MID($I27,8,1)="4"),"여자","")) -> 남자 | M27: =YEAR(TODAY())-IF(OR(MID($I27,8,1)="1",MID($I27,8,1)="2"),19&LEFT($I27,2),IF(OR(MID($I27,8,1)="3",MID($I27,8,1)="4"),20&LEFT($I27,2),""))+1 -> 39 | N27: 양력 | O27: 한국 | P27: 010-8987-0894 | T27: TBELL | U27: 申 明 昱 | V27: =QUOTIENT(SUMPRODUCT(LEFT($W27:$X27,FIND("년",$W27:$X27)-1)*12+MID($W27:$X27,FIND("년",$W27:$X27)+1,FIND("개월",$W27:$X27)-FIND("년",$W27:$X27)-1)),12)&"년"&MOD(SUMPRODUCT(LEFT($W27:$X27,FIND("년",$W27:$X27)-1)*12+MID($W27:$X27,FIND("년",$W27:$X27)+1,FIND("개월",$W27:$X27)-FIND("년",$W27:$X27)-1)),12)&"개월" -> 8년9개월 | W27: 4년 5개월 | X27: =DATEDIF($D27,TODAY(),"y")&"년"&DATEDIF($D27,TODAY(),"ym")&"개월" -> 4년4개월 | Y27: 부광고등학교 | AA27: 고졸 | AB27: 39127 | AC27: =VALUE(LEFT($V27,FIND("년",$V27)-1)) -> 8 | AD27: =IF($AA27="고졸",IF($AC27<=11,"초급",IF($AC27<=14,"중급",IF($AC27<=17,"고급",IF($AC27>=18,"특급"))))) -> 초급 | AE27: =IF(ISNUMBER(SEARCH("산업기사",$AL27)),IF($AC27>=13,"특급",IF($AC27>=10,"고급",IF($AC27>=7,"중급","초급"))),IF(ISNUMBER(SEARCH("기사",$AJ27)),IF($AC27>=10,"특급",IF($AC27>=7,"고급",IF($AC27>=4,"중급","초급"))),"미해당")) -> 미해당 | AH27: ISTQB | AI27: 43301 | AO27: KSTQB | AP27: 2018.07.20 | AQ27: IT기획 및 품질관리 | AR27: 테스팅 엔지니어 | AS27: 기업은행 | AT27: 592-036328-01-011 | AU27: 형 | AV27: 010-9980-0914 | AW27: mu.shin@tbell.co.kr | AX27: 인천시 | AY27: 부평구 | BA27: 경원대로 1269, 117동 503호 (신곡동, 현대아파트) | BB27: =IFERROR(VLOOKUP($AY27,[1]프로젝트현황!Y:Z,2,0),"기타") -> 서남권 | BC27: =(IF(AX27="","",AX27&" "))&(IF(AY27="","",AY27&" "))&(IF(AZ27="","",AZ27&" "))&BA27 -> 인천시 부평구 경원대로 1269, 117동 503호 (신곡동, 현대아파트)
A28: =ROW()-2 -> 26 | B28: 220103 | C28: 이영선 | D28: 44578 | E28: 44578 | H28: LEE, YeongSun | I28: 950519-2249637 | J28: =LEFT(I28,6) -> 950519 | K28: =MID($I28,3,2) -> 05 | L28: =IF(OR(MID($I28,8,1)="1",MID($I28,8,1)="3"),"남자",IF(OR(MID($I28,8,1)="2",MID($I28,8,1)="4"),"여자","")) -> 여자 | M28: =YEAR(TODAY())-IF(OR(MID($I28,8,1)="1",MID($I28,8,1)="2"),19&LEFT($I28,2),IF(OR(MID($I28,8,1)="3",MID($I28,8,1)="4"),20&LEFT($I28,2),""))+1 -> 32 | N28: 양력 | O28: 한국 | P28: 010-6635-6908 | T28: TBELL | U28: 李 永 善 | V28: =QUOTIENT(SUMPRODUCT(LEFT($W28:$X28,FIND("년",$W28:$X28)-1)*12+MID($W28:$X28,FIND("년",$W28:$X28)+1,FIND("개월",$W28:$X28)-FIND("년",$W28:$X28)-1)),12)&"년"&MOD(SUMPRODUCT(LEFT($W28:$X28,FIND("년",$W28:$X28)-1)*12+MID($W28:$X28,FIND("년",$W28:$X28)+1,FIND("개월",$W28:$X28)-FIND("년",$W28:$X28)-1)),12)&"개월" -> 5년4개월 | W28: 1년 4개월 | X28: =DATEDIF($D28,TODAY(),"y")&"년"&DATEDIF($D28,TODAY(),"ym")&"개월" -> 4년0개월 | Y28: 한경대학교 | Z28: 컴퓨터공학과 | AA28: 학사 | AB28: 43882 | AC28: =VALUE(LEFT($V28,FIND("년",$V28)-1)) -> 5 | AD28: =IF($AA28="학사",IF($AC28<=5,"초급",IF($AC28<9,"중급",IF($AC28<12,"고급",IF($AC28>=12,"특급"))))) -> 초급 | AE28: =IF(ISNUMBER(SEARCH("산업기사",$AL28)),IF($AC28>=13,"특급",IF($AC28>=10,"고급",IF($AC28>=7,"중급","초급"))),IF(ISNUMBER(SEARCH("기사",$AJ28)),IF($AC28>=10,"특급",IF($AC28>=7,"고급",IF($AC28>=4,"중급","초급"))),"미해당")) -> 중급 | AH28: ISTQB | AI28: 44665 | AJ28: 정보처리기사 | AK28: 43791 | AO28: 한국산업인력공단 KSTQB | AP28: 2019.11.22 2022.04.14 | AQ28: IT기획 및 품질관리 | AR28: 테스팅 엔지니어 | AS28: 기업은행 | AT28: 468-081043-01-012 | AU28: 모 | AV28: 010-4072-6630 | AW28: ys.lee@tbell.co.kr | AX28: 경기도 | AY28: 화성시 | BA28: 병점노을1로 14, 101동 703호 | BB28: =IFERROR(VLOOKUP($AY28,[1]프로젝트현황!Y:Z,2,0),"기타") -> 서남권 | BC28: =(IF(AX28="","",AX28&" "))&(IF(AY28="","",AY28&" "))&(IF(AZ28="","",AZ28&" "))&BA28 -> 경기도 화성시 병점노을1로 14, 101동 703호
A29: =ROW()-2 -> 27 | B29: 220104 | C29: 양혜원 | D29: 44578 | E29: 44578 | H29: Yang, HyeWon | I29: 820319-2452712 | J29: =LEFT(I29,6) -> 820319 | K29: =MID($I29,3,2) -> 03 | L29: =IF(OR(MID($I29,8,1)="1",MID($I29,8,1)="3"),"남자",IF(OR(MID($I29,8,1)="2",MID($I29,8,1)="4"),"여자","")) -> 여자 | M29: =YEAR(TODAY())-IF(OR(MID($I29,8,1)="1",MID($I29,8,1)="2"),19&LEFT($I29,2),IF(OR(MID($I29,8,1)="3",MID($I29,8,1)="4"),20&LEFT($I29,2),""))+1 -> 45 | N29: 양력 | O29: 한국 | P29: 010-4028-1471 | T29: TBELL | V29: =QUOTIENT(SUMPRODUCT(LEFT($W29:$X29,FIND("년",$W29:$X29)-1)*12+MID($W29:$X29,FIND("년",$W29:$X29)+1,FIND("개월",$W29:$X29)-FIND("년",$W29:$X29)-1)),12)&"년"&MOD(SUMPRODUCT(LEFT($W29:$X29,FIND("년",$W29:$X29)-1)*12+MID($W29:$X29,FIND("년",$W29:$X29)+1,FIND("개월",$W29:$X29)-FIND("년",$W29:$X29)-1)),12)&"개월" -> 7년6개월 | W29: 3년 6개월 | X29: =DATEDIF($D29,TODAY(),"y")&"년"&DATEDIF($D29,TODAY(),"ym")&"개월" -> 4년0개월 | Y29: 배재대학교 | Z29: 일본학과일본학 | AA29: 학사 | AB29: 39135 | AC29: =VALUE(LEFT($V29,FIND("년",$V29)-1)) -> 7 | AD29: =IF($AA29="학사",IF($AC29<=5,"초급",IF($AC29<9,"중급",IF($AC29<12,"고급",IF($AC29>=12,"특급"))))) -> 중급 | AE29: =IF(ISNUMBER(SEARCH("산업기사",$AL29)),IF($AC29>=13,"특급",IF($AC29>=10,"고급",IF($AC29>=7,"중급","초급"))),IF(ISNUMBER(SEARCH("기사",$AJ29)),IF($AC29>=10,"특급",IF($AC29>=7,"고급",IF($AC29>=4,"중급","초급"))),"미해당")) -> 미해당 | AH29: ISTQB | AI29: 44443 | AN29: 워드프로세서 2급 JLPT 1급 | AO29: 대한상공회의소 국제교류기금 KSTQB | AP29: 2009.01 2007.02 2021.09.04 | AQ29: IT기획 및 품질관리 | AR29: 테스팅 엔지니어 | AS29: 기업은행 | AT29: 051-118083-01-019 | AU29: 자매 | AV29: 010-9526-1479 | AW29: hyewon.yang@tbell.co.kr | AX29: 서울시 | AY29: 성동구 | BA29: 마조로7길 15(행당동) | BB29: =IFERROR(VLOOKUP($AY29,[1]프로젝트현황!Y:Z,2,0),"기타") -> 동북권 | BC29: =(IF(AX29="","",AX29&" "))&(IF(AY29="","",AY29&" "))&(IF(AZ29="","",AZ29&" "))&BA29 -> 서울시 성동구 마조로7길 15(행당동)
A30: =ROW()-2 -> 28 | B30: 220404 | C30: 송재현 | D30: 44669 | E30: 44669 | H30: Song, Jae Hyeon | I30: 951109-1025913 | J30: =LEFT(I30,6) -> 951109 | K30: =MID($I30,3,2) -> 11 | L30: =IF(OR(MID($I30,8,1)="1",MID($I30,8,1)="3"),"남자",IF(OR(MID($I30,8,1)="2",MID($I30,8,1)="4"),"여자","")) -> 남자 | M30: =YEAR(TODAY())-IF(OR(MID($I30,8,1)="1",MID($I30,8,1)="2"),19&LEFT($I30,2),IF(OR(MID($I30,8,1)="3",MID($I30,8,1)="4"),20&LEFT($I30,2),""))+1 -> 32 | N30: 양력 | O30: 한국 | P30: 010-3910-6506 | T30: TBELL | U30: 宋宰弦 | V30: =QUOTIENT(SUMPRODUCT(LEFT($W30:$X30,FIND("년",$W30:$X30)-1)*12+MID($W30:$X30,FIND("년",$W30:$X30)+1,FIND("개월",$W30:$X30)-FIND("년",$W30:$X30)-1)),12)&"년"&MOD(SUMPRODUCT(LEFT($W30:$X30,FIND("년",$W30:$X30)-1)*12+MID($W30:$X30,FIND("년",$W30:$X30)+1,FIND("개월",$W30:$X30)-FIND("년",$W30:$X30)-1)),12)&"개월" -> 3년9개월 | W30: 0년 0개월 | X30: =DATEDIF($D30,TODAY(),"y")&"년"&DATEDIF($D30,TODAY(),"ym")&"개월" -> 3년9개월 | Y30: 서일대학교 | Z30: 컴퓨터응용전자과 | AA30: 전문학사 | AB30: 43872 | AC30: =VALUE(LEFT($V30,FIND("년",$V30)-1)) -> 3 | AD30: =IF($AA30="전문학사",IF($AC30<=8,"초급",IF($AC30<12,"중급",IF($AC30<15,"고급",IF($AC30>=15,"특급"))))) -> 초급 | AE30: =IF(ISNUMBER(SEARCH("산업기사",$AL30)),IF($AC30>=13,"특급",IF($AC30>=10,"고급",IF($AC30>=7,"중급","초급"))),IF(ISNUMBER(SEARCH("기사",$AJ30)),IF($AC30>=10,"특급",IF($AC30>=7,"고급",IF($AC30>=4,"중급","초급"))),"미해당")) -> 미해당 | AQ30: IT기획 및 품질관리 | AR30: 테스팅 엔지니어 | AS30: 기업은행 | AT30: 005-112710-01-012 | AU30: 모 | AV30: 010-6554-6506 | AW30: jh.song@tbell.co.kr | AX30: 서울시 | AY30: 강북구 | BA30: 삼양로27길 19, 215동 401호 (미아동,삼성래미안트리베라아파트) | BB30: =IFERROR(VLOOKUP($AY30,[1]프로젝트현황!Y:Z,2,0),"기타") -> 동북권 | BC30: =(IF(AX30="","",AX30&" "))&(IF(AY30="","",AY30&" "))&(IF(AZ30="","",AZ30&" "))&BA30 -> 서울시 강북구 삼양로27길 19, 215동 401호 (미아동,삼성래미안트리베라아파트)
A31: =ROW()-2 -> 29 | B31: 220501 | C31: 김준하 | D31: 44683 | E31: 44683 | H31: KIM, Junha | I31: 000206-3403929 | J31: =LEFT(I31,6) -> 000206 | K31: =MID($I31,3,2) -> 02 | L31: =IF(OR(MID($I31,8,1)="1",MID($I31,8,1)="3"),"남자",IF(OR(MID($I31,8,1)="2",MID($I31,8,1)="4"),"여자","")) -> 남자 | M31: =YEAR(TODAY())-IF(OR(MID($I31,8,1)="1",MID($I31,8,1)="2"),19&LEFT($I31,2),IF(OR(MID($I31,8,1)="3",MID($I31,8,1)="4"),20&LEFT($I31,2),""))+1 -> 27 | N31: 양력 | O31: 한국 | P31: 010-8559-7560 | T31: TBELL | U31: 金俊夏 | V31: =QUOTIENT(SUMPRODUCT(LEFT($W31:$X31,FIND("년",$W31:$X31)-1)*12+MID($W31:$X31,FIND("년",$W31:$X31)+1,FIND("개월",$W31:$X31)-FIND("년",$W31:$X31)-1)),12)&"년"&MOD(SUMPRODUCT(LEFT($W31:$X31,FIND("년",$W31:$X31)-1)*12+MID($W31:$X31,FIND("년",$W31:$X31)+1,FIND("개월",$W31:$X31)-FIND("년",$W31:$X31)-1)),12)&"개월" -> 3년9개월 | W31: 0년 0개월 | X31: =DATEDIF($D31,TODAY(),"y")&"년"&DATEDIF($D31,TODAY(),"ym")&"개월" -> 3년9개월 | Y31: 세종대학교(휴학) | Z31: 컴퓨터공학 | AA31: 학사 | AB31: 44622 | AC31: =VALUE(LEFT($V31,FIND("년",$V31)-1)) -> 3 | AD31: =IF($AA31="학사",IF($AC31<=5,"초급",IF($AC31<9,"중급",IF($AC31<12,"고급",IF($AC31>=12,"특급"))))) -> 초급 | AE31: =IF(ISNUMBER(SEARCH("산업기사",$AL31)),IF($AC31>=13,"특급",IF($AC31>=10,"고급",IF($AC31>=7,"중급","초급"))),IF(ISNUMBER(SEARCH("기사",$AJ31)),IF($AC31>=10,"특급",IF($AC31>=7,"고급",IF($AC31>=4,"중급","초급"))),"미해당")) -> 미해당 | AN31: 정보처리기능사 | AO31: 한국산업인력공단 | AP31: 2018.07.18 | AQ31: IT기획 및 품질관리 | AR31: 테스팅 엔지니어 | AS31: 기업은행 | AT31: 977-039689-01-013 | AU31: 모 | AV31: 010-6293-5956 | AW31: junha.kim@tbell.co.kr | AX31: 서울시 | AY31: 관악구 | BA31: 남부순환로 1527 (신림동) 502호 | BB31: =IFERROR(VLOOKUP($AY31,[1]프로젝트현황!Y:Z,2,0),"기타") -> 서남권 | BC31: =(IF(AX31="","",AX31&" "))&(IF(AY31="","",AY31&" "))&(IF(AZ31="","",AZ31&" "))&BA31 -> 서울시 관악구 남부순환로 1527 (신림동) 502호
A32: =ROW()-2 -> 30 | B32: 220602 | C32: 최세욱 | D32: 44719 | E32: 44719 | H32: CHOI, Sewook | I32: 920626-1005711 | J32: =LEFT(I32,6) -> 920626 | K32: =MID($I32,3,2) -> 06 | L32: =IF(OR(MID($I32,8,1)="1",MID($I32,8,1)="3"),"남자",IF(OR(MID($I32,8,1)="2",MID($I32,8,1)="4"),"여자","")) -> 남자 | M32: =YEAR(TODAY())-IF(OR(MID($I32,8,1)="1",MID($I32,8,1)="2"),19&LEFT($I32,2),IF(OR(MID($I32,8,1)="3",MID($I32,8,1)="4"),20&LEFT($I32,2),""))+1 -> 35 | N32: 양력 | O32: 한국 | P32: 010-6223-5999 | R32: 무 | T32: TBELL | U32: 崔世煜 | V32: =QUOTIENT(SUMPRODUCT(LEFT($W32:$X32,FIND("년",$W32:$X32)-1)*12+MID($W32:$X32,FIND("년",$W32:$X32)+1,FIND("개월",$W32:$X32)-FIND("년",$W32:$X32)-1)),12)&"년"&MOD(SUMPRODUCT(LEFT($W32:$X32,FIND("년",$W32:$X32)-1)*12+MID($W32:$X32,FIND("년",$W32:$X32)+1,FIND("개월",$W32:$X32)-FIND("년",$W32:$X32)-1)),12)&"개월" -> 3년8개월 | W32: 0년 0개월 | X32: =DATEDIF($D32,TODAY(),"y")&"년"&DATEDIF($D32,TODAY(),"ym")&"개월" -> 3년8개월 | Y32: 건국대학교사범대학부속고등학교 | Z32: 문과 | AA32: 고졸 | AB32: 40583 | AC32: =VALUE(LEFT($V32,FIND("년",$V32)-1)) -> 3 | AD32: =IF($AA32="고졸",IF($AC32<=11,"초급",IF($AC32<=14,"중급",IF($AC32<=17,"고급",IF($AC32>=18,"특급"))))) -> 초급 | AE32: =IF(ISNUMBER(SEARCH("산업기사",$AL32)),IF($AC32>=13,"특급",IF($AC32>=10,"고급",IF($AC32>=7,"중급","초급"))),IF(ISNUMBER(SEARCH("기사",$AJ32)),IF($AC32>=10,"특급",IF($AC32>=7,"고급",IF($AC32>=4,"중급","초급"))),"미해당")) -> 미해당 | AH32: ISTQB | AI32: 44728 | AO32: KSTQB | AP32: 2022.06.16 | AQ32: IT기획 및 품질관리 | AR32: 테스팅 엔지니어 | AS32: 기업은행 | AT32: 478-077654-02-014 | AU32: 모 | AV32: 010-8982-6702 | AW32: sw.choi@tbell.co.kr | AX32: 서울시 | AY32: 광진구 | BA32: 뚝섬로45길 40 (자양동) | BB32: =IFERROR(VLOOKUP($AY32,[1]프로젝트현황!Y:Z,2,0),"기타") -> 동북권 | BC32: =(IF(AX32="","",AX32&" "))&(IF(AY32="","",AY32&" "))&(IF(AZ32="","",AZ32&" "))&BA32 -> 서울시 광진구 뚝섬로45길 40 (자양동)
A33: =ROW()-2 -> 31 | B33: 220603 | C33: 신진철 | D33: 44719 | E33: 44719 | G33: 46038 | H33: SHIN, Jincheol | I33: 930923-1065825 | J33: =LEFT(I33,6) -> 930923 | K33: =MID($I33,3,2) -> 09 | L33: =IF(OR(MID($I33,8,1)="1",MID($I33,8,1)="3"),"남자",IF(OR(MID($I33,8,1)="2",MID($I33,8,1)="4"),"여자","")) -> 남자 | M33: =YEAR(TODAY())-IF(OR(MID($I33,8,1)="1",MID($I33,8,1)="2"),19&LEFT($I33,2),IF(OR(MID($I33,8,1)="3",MID($I33,8,1)="4"),20&LEFT($I33,2),""))+1 -> 34 | N33: 양력 | O33: 한국 | P33: 010-2802-2493 | T33: TBELL | U33: 申進澈 | V33: =QUOTIENT(SUMPRODUCT(LEFT($W33:$X33,FIND("년",$W33:$X33)-1)*12+MID($W33:$X33,FIND("년",$W33:$X33)+1,FIND("개월",$W33:$X33)-FIND("년",$W33:$X33)-1)),12)&"년"&MOD(SUMPRODUCT(LEFT($W33:$X33,FIND("년",$W33:$X33)-1)*12+MID($W33:$X33,FIND("년",$W33:$X33)+1,FIND("개월",$W33:$X33)-FIND("년",$W33:$X33)-1)),12)&"개월" -> 3년8개월 | W33: 0년 0개월 | X33: =DATEDIF($D33,TODAY(),"y")&"년"&DATEDIF($D33,TODAY(),"ym")&"개월" -> 3년8개월 | Y33: 대일고등학교 | Z33: 문과 | AA33: 고졸 | AB33: 40948 | AC33: =VALUE(LEFT($V33,FIND("년",$V33)-1)) -> 3 | AD33: =IF($AA33="고졸",IF($AC33<=11,"초급",IF($AC33<=14,"중급",IF($AC33<=17,"고급",IF($AC33>=18,"특급"))))) -> 초급 | AE33: =IF(ISNUMBER(SEARCH("산업기사",$AL33)),IF($AC33>=13,"특급",IF($AC33>=10,"고급",IF($AC33>=7,"중급","초급"))),IF(ISNUMBER(SEARCH("기사",$AJ33)),IF($AC33>=10,"특급",IF($AC33>=7,"고급",IF($AC33>=4,"중급","초급"))),"미해당")) -> 미해당 | AQ33: IT기획 및 품질관리 | AR33: 테스팅 엔지니어 | AS33: 기업은행 | AT33: 308-075006-01-011 | AU33: 부 | AV33: 010-5382-2493 | AW33: jc.shin@tbell.co.kr | AX33: 서울시 | AY33: 양천구 | BA33: 목동중앙북로22길 14-16 (목동) | BB33: =IFERROR(VLOOKUP($AY33,[1]프로젝트현황!Y:Z,2,0),"기타") -> 서남권 | BC33: =(IF(AX33="","",AX33&" "))&(IF(AY33="","",AY33&" "))&(IF(AZ33="","",AZ33&" "))&BA33 -> 서울시 양천구 목동중앙북로22길 14-16 (목동)
A34: =ROW()-2 -> 32 | B34: 220604 | C34: 김예경 | D34: 44732 | E34: 44732 | H34: KIM, Yekyeong | I34: 010420-4187419 | J34: =LEFT(I34,6) -> 010420 | K34: =MID($I34,3,2) -> 04 | L34: =IF(OR(MID($I34,8,1)="1",MID($I34,8,1)="3"),"남자",IF(OR(MID($I34,8,1)="2",MID($I34,8,1)="4"),"여자","")) -> 여자 | M34: =YEAR(TODAY())-IF(OR(MID($I34,8,1)="1",MID($I34,8,1)="2"),19&LEFT($I34,2),IF(OR(MID($I34,8,1)="3",MID($I34,8,1)="4"),20&LEFT($I34,2),""))+1 -> 26 | N34: 양력 | O34: 한국 | P34: 010-8854-1381 | R34: 무 | T34: TBELL | U34: 金禮京 | V34: =QUOTIENT(SUMPRODUCT(LEFT($W34:$X34,FIND("년",$W34:$X34)-1)*12+MID($W34:$X34,FIND("년",$W34:$X34)+1,FIND("개월",$W34:$X34)-FIND("년",$W34:$X34)-1)),12)&"년"&MOD(SUMPRODUCT(LEFT($W34:$X34,FIND("년",$W34:$X34)-1)*12+MID($W34:$X34,FIND("년",$W34:$X34)+1,FIND("개월",$W34:$X34)-FIND("년",$W34:$X34)-1)),12)&"개월" -> 4년7개월 | W34: 1년 0개월 | X34: =DATEDIF($D34,TODAY(),"y")&"년"&DATEDIF($D34,TODAY(),"ym")&"개월" -> 3년7개월 | Y34: 대림대학교 | Z34: 융합소프트웨어과 | AA34: 전문학사 | AB34: 44607 | AC34: =VALUE(LEFT($V34,FIND("년",$V34)-1)) -> 4 | AD34: =IF($AA34="전문학사",IF($AC34<=8,"초급",IF($AC34<12,"중급",IF($AC34<15,"고급",IF($AC34>=15,"특급"))))) -> 초급 | AE34: =IF(ISNUMBER(SEARCH("산업기사",$AL34)),IF($AC34>=13,"특급",IF($AC34>=10,"고급",IF($AC34>=7,"중급","초급"))),IF(ISNUMBER(SEARCH("기사",$AJ34)),IF($AC34>=10,"특급",IF($AC34>=7,"고급",IF($AC34>=4,"중급","초급"))),"미해당")) -> 미해당 | AQ34: IT기획 및 품질관리 | AR34: 테스팅 엔지니어 | AS34: 기업은행 | AT34: 167-153649-01-011 | AU34: 모 | AV34: 010-9262-1381 | AW34: yk.kim@tbell.co.kr | AX34: 경기도 | AY34: 광명시 | BA34: 광명로927번길 6-10, 302호(광명동, 보륭빌라) | BB34: =IFERROR(VLOOKUP($AY34,[1]프로젝트현황!Y:Z,2,0),"기타") -> 서남권 | BC34: =(IF(AX34="","",AX34&" "))&(IF(AY34="","",AY34&" "))&(IF(AZ34="","",AZ34&" "))&BA34 -> 경기도 광명시 광명로927번길 6-10, 302호(광명동, 보륭빌라)
A35: =ROW()-2 -> 33 | B35: 220702 | C35: 이동연 | D35: 44746 | E35: 44774 | H35: LEE, DongYeon | I35: 990317-1064119 | J35: =LEFT(I35,6) -> 990317 | K35: =MID($I35,3,2) -> 03 | L35: =IF(OR(MID($I35,8,1)="1",MID($I35,8,1)="3"),"남자",IF(OR(MID($I35,8,1)="2",MID($I35,8,1)="4"),"여자","")) -> 남자 | M35: =YEAR(TODAY())-IF(OR(MID($I35,8,1)="1",MID($I35,8,1)="2"),19&LEFT($I35,2),IF(OR(MID($I35,8,1)="3",MID($I35,8,1)="4"),20&LEFT($I35,2),""))+1 -> 28 | N35: 양력 | O35: 한국 | P35: 010-2021-9871 | T35: TBELL | U35: 李同淵 | V35: =QUOTIENT(SUMPRODUCT(LEFT($W35:$X35,FIND("년",$W35:$X35)-1)*12+MID($W35:$X35,FIND("년",$W35:$X35)+1,FIND("개월",$W35:$X35)-FIND("년",$W35:$X35)-1)),12)&"년"&MOD(SUMPRODUCT(LEFT($W35:$X35,FIND("년",$W35:$X35)-1)*12+MID($W35:$X35,FIND("년",$W35:$X35)+1,FIND("개월",$W35:$X35)-FIND("년",$W35:$X35)-1)),12)&"개월" -> 3년7개월 | W35: 0년 0개월 | X35: =DATEDIF($D35,TODAY(),"y")&"년"&DATEDIF($D35,TODAY(),"ym")&"개월" -> 3년7개월 | Y35: 인하공업전문대학교 | Z35: 컴퓨터시스템과 | AA35: 전문학사 | AB35: 44967 | AC35: =VALUE(LEFT($V35,FIND("년",$V35)-1)) -> 3 | AD35: =IF($AA35="전문학사",IF($AC35<=8,"초급",IF($AC35<12,"중급",IF($AC35<15,"고급",IF($AC35>=15,"특급"))))) -> 초급 | AE35: =IF(ISNUMBER(SEARCH("산업기사",$AL35)),IF($AC35>=13,"특급",IF($AC35>=10,"고급",IF($AC35>=7,"중급","초급"))),IF(ISNUMBER(SEARCH("기사",$AJ35)),IF($AC35>=10,"특급",IF($AC35>=7,"고급",IF($AC35>=4,"중급","초급"))),"미해당")) -> 미해당 | AH35: ISTQB | AI35: 45267 | AQ35: IT기획 및 품질관리 | AR35: 테스팅 엔지니어 | AS35: 기업은행 | AT35: 555-041722-01-011 | AU35: 모 | AV35: 010-3480-9870 | AW35: dongyeon.lee@tbell.co.kr | AX35: 경기도 | AY35: 김포시 | BA35: 전원로 28, 110동 1302호 (운양동,전원마을) | BB35: =IFERROR(VLOOKUP($AY35,[1]프로젝트현황!Y:Z,2,0),"기타") -> 서남권 | BC35: =(IF(AX35="","",AX35&" "))&(IF(AY35="","",AY35&" "))&(IF(AZ35="","",AZ35&" "))&BA35 -> 경기도 김포시 전원로 28, 110동 1302호 (운양동,전원마을)
